Workbook

Sheet HOME
B1: YEAR 11 FANTASY LEAGUE
B2: GAMEWEEK 1
B4: GAMEWEEK 1: Biology and English
B5: GAMEWEEK 1
B7: CURRENT GAMEWEEK: | C7: 1
B9: HOW TO PLAY
B10: 1. Go to PICK YOUR TEAM and click your name.
B11: 2. Pick 5 players from the dropdowns.
B12: 3. Pick 1 captain using the GOLD CAPTAIN BOX.
B13: 4. Stay under the £50m budget.
B14: 5. Enter your own test % on TEST RESULTS after each test.
B17: HOW POINTS WORK
B18: Your score is compared to the CLASS AVERAGE. Average = 5 points. Every small step above = +1. Every step below = −1.
B20: Well above average | D20: High points
B21: Slightly above | D21: 6–7 points
B22: Exactly average | D22: 5 points
B23: Slightly below | D23: 3–4 points
B24: Well below | D24: 0–1 points
B27: HOW PRICES WORK
B28: Prices move based on your 3-WEEK FORM vs the class average. Cheap players rise faster. Expensive players rise slower.
B30: No changes first 2 weeks | E30: Settling in
B31: Week 3 onward | E31: Prices move based on form
B32: Beating average consistently | E32: Price rises up to +£0.5m/week
B33: Below average consistently | E33: Price falls up to -£0.5m/week
B34: Bounds | E34: £7.0m to £13.0m
B36: SETTINGS and RULES sheets have more detail. Ask Mr C if anything is unclear.

Sheet RULES
B1: RULES & HOW TO PLAY
B4: BUDGET | C4: £50.0m per manager. Pick exactly 5 players.
B6: CAPTAIN | C6: Pick 1 captain using the GOLD box on your team sheet. Captain scores 2× points.
B8: DEADLINE | C8: Set on HOME each gameweek.
B10: TEST DATE | C10: Set on HOME each gameweek.
B12: RESULT ENTRY | C12: Each student enters their own test % on TEST RESULTS.
B14: POINTS | C14: Based on class average. Average = 5 pts. Every step above/below = ±1 pt. Step size adjusts to class spread. Capped 0–10.
B16: PRICE CHANGES | C16: Move based on 3-week form vs class average. First 2 weeks: no change. Week 3 onward: max ±£0.5m per week.
B18: PRICE SCALING | C18: Cheap players rise faster (×1.0). Mid-price ×0.75. Expensive ×0.5.
B20: PRICE LIMITS | C20: Minimum £7.0m. Maximum £13.0m.
B22: TRANSFERS | C22: Unlimited free transfers between gameweeks.
B24: GOLDEN RULE | C24: Pick 5 players + captain, enter your test score. Excel does the rest.

Sheet PICK YOUR TEAM
B1: PICK YOUR TEAM
B2: Click your name to jump to your team sheet.
B4: Manager | C4: ="Status: " & COUNTIF(C6:C26,"VALID TEAM") & "/" & COUNTA(B6:B26) -> Status: 11/20
B5: Alexa Amesimeku | C5: =CALCULATIONS!U2 -> VALID TEAM
B6: Alfie Foley | C6: =CALCULATIONS!U3 -> VALID TEAM
B7: Alyza Rai | C7: =CALCULATIONS!U4 -> LESS THAN 5 PLAYERS
B8: Ava Swinfen | C8: =CALCULATIONS!U5 -> VALID TEAM
B9: Azlan Husain | C9: =CALCULATIONS!U6 -> VALID TEAM
B10: Chinedu Chile | C10: =CALCULATIONS!U7 -> VALID TEAM
B11: Daniel Liu | C11: =CALCULATIONS!U8 -> LESS THAN 5 PLAYERS
B12: David Wu | C12: =CALCULATIONS!U9 -> VALID TEAM
B13: Edwin Mayers | C13: =CALCULATIONS!U10 -> VALID TEAM
B14: Emily Warburton | C14: =CALCULATIONS!U11 -> LESS THAN 5 PLAYERS
B15: Esme Beston | C15: =CALCULATIONS!U12 -> LESS THAN 5 PLAYERS
B16: Iona Smith | C16: =CALCULATIONS!U13 -> LESS THAN 5 PLAYERS
... B25: Xander Meijer | C25: =CALCULATIONS!U22 -> VALID TEAM

Sheet PLAYER MARKET
B1: PLAYER MARKET
B2: Prices • This week's change • Ownership
B4: Player | C4: Price | D4: Change | E4: Ownership %
B5: =CALCULATIONS!A2 -> Lia Li | C5: =CALCULATIONS!C2 -> 13 | D5: =IF(SETTINGS!C30=0,0,CALCULATIONS!C2-CALCULATIONS!B2) -> 0 | E5: =COUNTIF(CALCULATIONS!$L$2:$P$22,CALCULATIONS!A2)/COUNTA(CALCULATIONS!$K$2:$K$22) -> 0.23809524
B6: =CALCULATIONS!A3 -> Sophie Barker | C6: =CALCULATIONS!C3 -> 13 | D6: =IF(SETTINGS!C30=0,0,CALCULATIONS!C3-CALCULATIONS!B3) -> 0 | E6: =COUNTIF(CALCULATIONS!$L$2:$P$22,CALCULATIONS!A3)/COUNTA(CALCULATIONS!$K$2:$K$22) -> 0.14285714
B7: =CALCULATIONS!A4 -> Chinedu Chile | C7: =CALCULATIONS!C4 -> 11 | D7: =IF(SETTINGS!C30=0,0,CALCULATIONS!C4-CALCULATIONS!B4) -> 0 | E7: =COUNTIF(CALCULATIONS!$L$2:$P$22,CALCULATIONS!A4)/COUNTA(CALCULATIONS!$K$2:$K$22) -> 0.33333333
B8: =CALCULATIONS!A5 -> Emily Warburton | C8: =CALCULATIONS!C5 -> 11 | D8: =IF(SETTINGS!C30=0,0,CALCULATIONS!C5-CALCULATIONS!B5) -> 0 | E8: =COUNTIF(CALCULATIONS!$L$2:$P$22,CALCULATIONS!A5)/COUNTA(CALCULATIONS!$K$2:$K$22) -> 0.095238095
B9: =CALCULATIONS!A6 -> Alyza Rai | C9: =CALCULATIONS!C6 -> 10.5 | D9: =IF(SETTINGS!C30=0,0,CALCULATIONS!C6-CALCULATIONS!B6) -> 0 | E9: =COUNTIF(CALCULATIONS!$L$2:$P$22,CALCULATIONS!A6)/COUNTA(CALCULATIONS!$K$2:$K$22) -> 0.14285714
B10: =CALCULATIONS!A7 -> David Wu | C10: =CALCULATIONS!C7 -> 10.5 | D10: =IF(SETTINGS!C30=0,0,CALCULATIONS!C7-CALCULATIONS!B7) -> 0 | E10: =COUNTIF(CALCULATIONS!$L$2:$P$22,CALCULATIONS!A7)/COUNTA(CALCULATIONS!$K$2:$K$22) -> 0.33333333
B11: =CALCULATIONS!A8 -> Joe Paige | C11: =CALCULATIONS!C8 -> 10.5 | D11: =IF(SETTINGS!C30=0,0,CALCULATIONS!C8-CALCULATIONS!B8) -> 0 | E11: =COUNTIF(CALCULATIONS!$L$2:$P$22,CALCULATIONS!A8)/COUNTA(CALCULATIONS!$K$2:$K$22) -> 0.33333333
B12: =CALCULATIONS!A9 -> Azlan Husain | C12: =CALCULATIONS!C9 -> 10 | D12: =IF(SETTINGS!C30=0,0,CALCULATIONS!C9-CALCULATIONS!B9) -> 0 | E12: =COUNTIF(CALCULATIONS!$L$2:$P$22,CALCULATIONS!A9)/COUNTA(CALCULATIONS!$K$2:$K$22) -> 0.095238095
B13: =CALCULATIONS!A10 -> Nina De Saram | C13: =CALCULATIONS!C10 -> 10 | D13: =IF(SETTINGS!C30=0,0,CALCULATIONS!C10-CALCULATIONS!B10) -> 0 | E13: =COUNTIF(CALCULATIONS!$L$2:$P$22,CALCULATIONS!A10)/COUNTA(CALCULATIONS!$K$2:$K$22) -> 0.095238095
B14: =CALCULATIONS!A11 -> Alexa Amesimeku | C14: =CALCULATIONS!C11 -> 9.5 | D14: =IF(SETTINGS!C30=0,0,CALCULATIONS!C11-CALCULATIONS!B11) -> 0 | E14: =COUNTIF(CALCULATIONS!$L$2:$P$22,CALCULATIONS!A11)/COUNTA(CALCULATIONS!$K$2:$K$22) -> 0.095238095
B15: =CALCULATIONS!A12 -> Daniel Liu | C15: =CALCULATIONS!C12 -> 9.5 | D15: =IF(SETTINGS!C30=0,0,CALCULATIONS!C12-CALCULATIONS!B12) -> 0 | E15: =COUNTIF(CALCULATIONS!$L$2:$P$22,CALCULATIONS!A12)/COUNTA(CALCULATIONS!$K$2:$K$22) -> 0
B16: =CALCULATIONS!A13 -> Rebecca Seymour | C16: =CALCULATIONS!C13 -> 9.5 | D16: =IF(SETTINGS!C30=0,0,CALCULATIONS!C13-CALCULATIONS!B13) -> 0 | E16: =COUNTIF(CALCULATIONS!$L$2:$P$22,CALCULATIONS!A13)/COUNTA(CALCULATIONS!$K$2:$K$22) -> 0.095238095
B17: =CALCULATIONS!A14 -> Edwin Mayers | C17: =CALCULATIONS!C14 -> 9 | D17: =IF(SETTINGS!C30=0,0,CALCULATIONS!C14-CALCULATIONS!B14) -> 0 | E17: =COUNTIF(CALCULATIONS!$L$2:$P$22,CALCULATIONS!A14)/COUNTA(CALCULATIONS!$K$2:$K$22) -> 0.33333333
B18: =CALCULATIONS!A15 -> Melody Zhaeentan | C18: =CALCULATIONS!C15 -> 8.5 | D18: =IF(SETTINGS!C30=0,0,CALCULATIONS!C15-CALCULATIONS!B15) -> 0 | E18: =COUNTIF(CALCULATIONS!$L$2:$P$22,CALCULATIONS!A15)/COUNTA(CALCULATIONS!$K$2:$K$22) -> 0.095238095
B19: =CALCULATIONS!A16 -> Esme Beston | C19: =CALCULATIONS!C16 -> 8 | D19: =IF(SETTINGS!C30=0,0,CALCULATIONS!C16-CALCULATIONS!B16) -> 0 | E19: =COUNTIF(CALCULATIONS!$L$2:$P$22,CALCULATIONS!A16)/COUNTA(CALCULATIONS!$K$2:$K$22) -> 0.047619048
B20: =CALCULATIONS!A17 -> Iona Smith | C20: =CALCULATIONS!C17 -> 8 | D20: =IF(SETTINGS!C30=0,0,CALCULATIONS!C17-CALCULATIONS!B17) -> 0 | E20: =COUNTIF(CALCULATIONS!$L$2:$P$22,CALCULATIONS!A17)/COUNTA(CALCULATIONS!$K$2:$K$22) -> 0
B21: =CALCULATIONS!A18 -> Oscar Day-Duran | C21: =CALCULATIONS!C18 -> 8 | D21: =IF(SETTINGS!C30=0,0,CALCULATIONS!C18-CALCULATIONS!B18) -> 0 | E21: =COUNTIF(CALCULATIONS!$L$2:$P$22,CALCULATIONS!A18)/COUNTA(CALCULATIONS!$K$2:$K$22) -> 0.095238095
B22: =CALCULATIONS!A19 -> Alfie Foley | C22: =CALCULATIONS!C19 -> 7.5 | D22: =IF(SETTINGS!C30=0,0,CALCULATIONS!C19-CALCULATIONS!B19) -> 0 | E22: =COUNTIF(CALCULATIONS!$L$2:$P$22,CALCULATIONS!A19)/COUNTA(CALCULATIONS!$K$2:$K$22) -> 0.095238095
B23: =CALCULATIONS!A20 -> Ava Swinfen | C23: =CALCULATIONS!C20 -> 7 | D23: =IF(SETTINGS!C30=0,0,CALCULATIONS!C20-CALCULATIONS!B20) -> 0 | E23: =COUNTIF(CALCULATIONS!$L$2:$P$22,CALCULATIONS!A20)/COUNTA(CALCULATIONS!$K$2:$K$22) -> 0.28571429
B24: =CALCULATIONS!A21 -> Rory Bowman | C24: =CALCULATIONS!C21 -> 7 | D24: =IF(SETTINGS!C30=0,0,CALCULATIONS!C21-CALCULATIONS!B21) -> 0 | E24: =COUNTIF(CALCULATIONS!$L$2:$P$22,CALCULATIONS!A21)/COUNTA(CALCULATIONS!$K$2:$K$22) -> 0
B25: =CALCULATIONS!A22 -> Xander Meijer | C25: =CALCULATIONS!C22 -> 7 | D25: =IF(SETTINGS!C30=0,0,CALCULATIONS!C22-CALCULATIONS!B22) -> 0 | E25: =COUNTIF(CALCULATIONS!$L$2:$P$22,CALCULATIONS!A22)/COUNTA(CALCULATIONS!$K$2:$K$22) -> 0.095238095
B28: PRICE RULES Prices move based on 3-week form vs class average. First 2 gameweeks: no changes. Min £7.0m • Max £13.0m

Sheet TEST RESULTS
B1: TEST RESULTS
B2: Enter your test scores.
B4: Test name: English and Biology
B5: Student | C5: =IFERROR("English: Average = " & ROUND(AVERAGE(C6:C25), 1) & "%", "English: No results yet") -> English: Average = 55.6% | D5: =IFERROR("Biology: Average = " & ROUND(AVERAGE(D6:D25), 1) & "%", "Biology: No results yet") -> Biology: Average = 80.1% | E5: N/A | F5: N/A | G5: N/A | H5: Score
B6: Alexa Amesimeku | C6: 73 | D6: 88 | H6: =IFERROR(AVERAGE(C6:INDEX(C6:G6,SETTINGS!$C$17)),"") -> 80.5
B7: Alfie Foley | C7: 40 | D7: 65 | H7: =IFERROR(AVERAGE(C7:INDEX(C7:G7,SETTINGS!$C$17)),"") -> 52.5
B8: Alyza Rai | C8: 70 | D8: 86 | H8: =IFERROR(AVERAGE(C8:INDEX(C8:G8,SETTINGS!$C$17)),"") -> 78
B9: Ava Swinfen | C9: 35 | D9: 74 | H9: =IFERROR(AVERAGE(C9:INDEX(C9:G9,SETTINGS!$C$17)),"") -> 54.5
B10: Azlan Husain | C10: 50 | D10: 86 | H10: =IFERROR(AVERAGE(C10:INDEX(C10:G10,SETTINGS!$C$17)),"") -> 68
B11: Chinedu Chile | C11: 60 | D11: 86 | H11: =IFERROR(AVERAGE(C11:INDEX(C11:G11,SETTINGS!$C$17)),"") -> 73
B12: Daniel Liu | C12: 63 | D12: 74 | H12: =IFERROR(AVERAGE(C12:INDEX(C12:G12,SETTINGS!$C$17)),"") -> 68.5
B13: David Wu | C13: 60 | D13: 86 | H13: =IFERROR(AVERAGE(C13:INDEX(C13:G13,SETTINGS!$C$17)),"") -> 73
B14: Edwin Mayers | C14: 40 | D14: 81 | H14: =IFERROR(AVERAGE(C14:INDEX(C14:G14,SETTINGS!$C$17)),"") -> 60.5
B15: Esme Beston | C15: 38 | D15: 56 | H15: =IFERROR(AVERAGE(C15:INDEX(C15:G15,SETTINGS!$C$17)),"") -> 47
B16: Iona Smith | H16: =IFERROR(AVERAGE(C16:INDEX(C16:G16,SETTINGS!$C$17)),"")
B17: Joe Paige | C17: 83 | D17: 91 | H17: =IFERROR(AVERAGE(C17:INDEX(C17:G17,SETTINGS!$C$17)),"") -> 87
B18: Lia Li | C18: 55 | D18: 100 | H18: =IFERROR(AVERAGE(C18:INDEX(C18:G18,SETTINGS!$C$17)),"") -> 77.5
B19: Melody Zhaeentan | C19: 75 | D19: 74 | H19: =IFERROR(AVERAGE(C19:INDEX(C19:G19,SETTINGS!$C$17)),"") -> 74.5
B20: Nina De Saram | C20: 75 | D20: 86 | H20: =IFERROR(AVERAGE(C20:INDEX(C20:G20,SETTINGS!$C$17)),"") -> 80.5
B21: Oscar Day-Duran | C21: 38 | D21: 72 | H21: =IFERROR(AVERAGE(C21:INDEX(C21:G21,SETTINGS!$C$17)),"") -> 55
B22: Rebecca Seymour | H22: =IFERROR(AVERAGE(C22:INDEX(C22:G22,SETTINGS!$C$17)),"")
B23: Rory Bowman | C23: 25 | D23: 58 | H23: =IFERROR(AVERAGE(C23:INDEX(C23:G23,SETTINGS!$C$17)),"") -> 41.5
B24: Sophie Barker | C24: 88 | D24: 98 | H24: =IFERROR(AVERAGE(C24:INDEX(C24:G24,SETTINGS!$C$17)),"") -> 93
B25: Xander Meijer | C25: 33 | D25: 81 | H25: =IFERROR(AVERAGE(C25:INDEX(C25:G25,SETTINGS!$C$17)),"") -> 57
B27: Enter a whole number 0–100 in the gold cells.

Sheet  Overall Leaderboard
B1: OVERALL LEADERBOARD
B2: All gameweeks combined • Sorted by points
B3: =IF(MAX($D$6:$D$26)=0,"🏆 OVERALL LEADER: No results yet","🏆 OVERALL LEADER: "&INDEX($C$6:$C$26,MATCH(MAX($D$6:$D$26),$D$6:$D$26,0))&" — "&MAX($D$6:$D$26)&" pts") -> 🏆 OVERALL LEADER: Alexa Amesimeku — 43 pts
B5: Rank | C5: Manager | D5: Overall Points
B6: {=SUMPRODUCT((D$6:D$26>D6)/COUNTIF(D$6:D$26,D$6:D$26))+1} -> 1 | C6: =IFERROR(INDEX(CALCULATIONS!$K$2:$K$22,MATCH(LARGE(CALCULATIONS!$V$2:$V$22,ROW()-5),CALCULATIONS!$V$2:$V$22,0)),"") -> Alexa Amesimeku | D6: =ROUND(LARGE(CALCULATIONS!$V$2:$V$22,ROW()-5),0) -> 43
B7: {=SUMPRODUCT((D$6:D$26>D7)/COUNTIF(D$6:D$26,D$6:D$26))+1} -> 2 | C7: =IFERROR(INDEX(CALCULATIONS!$K$2:$K$22,MATCH(LARGE(CALCULATIONS!$V$2:$V$22,ROW()-5),CALCULATIONS!$V$2:$V$22,0)),"") -> Oscar Day-Duran | D7: =ROUND(LARGE(CALCULATIONS!$V$2:$V$22,ROW()-5),0) -> 36
B8: {=SUMPRODUCT((D$6:D$26>D8)/COUNTIF(D$6:D$26,D$6:D$26))+1} -> 2 | C8: =IFERROR(INDEX(CALCULATIONS!$K$2:$K$22,MATCH(LARGE(CALCULATIONS!$V$2:$V$22,ROW()-5),CALCULATIONS!$V$2:$V$22,0)),"") -> Alfie Foley | D8: =ROUND(LARGE(CALCULATIONS!$V$2:$V$22,ROW()-5),0) -> 36
B9: {=SUMPRODUCT((D$6:D$26>D9)/COUNTIF(D$6:D$26,D$6:D$26))+1} -> 3 | C9: =IFERROR(INDEX(CALCULATIONS!$K$2:$K$22,MATCH(LARGE(CALCULATIONS!$V$2:$V$22,ROW()-5),CALCULATIONS!$V$2:$V$22,0)),"") -> Xander Meijer | D9: =ROUND(LARGE(CALCULATIONS!$V$2:$V$22,ROW()-5),0) -> 34
B10: {=SUMPRODUCT((D$6:D$26>D10)/COUNTIF(D$6:D$26,D$6:D$26))+1} -> 4 | C10: =IFERROR(INDEX(CALCULATIONS!$K$2:$K$22,MATCH(LARGE(CALCULATIONS!$V$2:$V$22,ROW()-5),CALCULATIONS!$V$2:$V$22,0)),"") -> Chinedu Chile | D10: =ROUND(LARGE(CALCULATIONS!$V$2:$V$22,ROW()-5),0) -> 31
B11: {=SUMPRODUCT((D$6:D$26>D11)/COUNTIF(D$6:D$26,D$6:D$26))+1} -> 4 | C11: =IFERROR(INDEX(CALCULATIONS!$K$2:$K$22,MATCH(LARGE(CALCULATIONS!$V$2:$V$22,ROW()-5),CALCULATIONS!$V$2:$V$22,0)),"") -> Ava Swinfen | D11: =ROUND(LARGE(CALCULATIONS!$V$2:$V$22,ROW()-5),0) -> 31
B12: {=SUMPRODUCT((D$6:D$26>D12)/COUNTIF(D$6:D$26,D$6:D$26))+1} -> 5 | C12: =IFERROR(INDEX(CALCULATIONS!$K$2:$K$22,MATCH(LARGE(CALCULATIONS!$V$2:$V$22,ROW()-5),CALCULATIONS!$V$2:$V$22,0)),"") -> Rory Bowman | D12: =ROUND(LARGE(CALCULATIONS!$V$2:$V$22,ROW()-5),0) -> 30
B13: {=SUMPRODUCT((D$6:D$26>D13)/COUNTIF(D$6:D$26,D$6:D$26))+1} -> 5 | C13: =IFERROR(INDEX(CALCULATIONS!$K$2:$K$22,MATCH(LARGE(CALCULATIONS!$V$2:$V$22,ROW()-5),CALCULATIONS!$V$2:$V$22,0)),"") -> Joe Paige | D13: =ROUND(LARGE(CALCULATIONS!$V$2:$V$22,ROW()-5),0) -> 30
B14: {=SUMPRODUCT((D$6:D$26>D14)/COUNTIF(D$6:D$26,D$6:D$26))+1} -> 6 | C14: =IFERROR(INDEX(CALCULATIONS!$K$2:$K$22,MATCH(LARGE(CALCULATIONS!$V$2:$V$22,ROW()-5),CALCULATIONS!$V$2:$V$22,0)),"") -> Melody Zhaeentan | D14: =ROUND(LARGE(CALCULATIONS!$V$2:$V$22,ROW()-5),0) -> 27
B15: {=SUMPRODUCT((D$6:D$26>D15)/COUNTIF(D$6:D$26,D$6:D$26))+1} -> 7 | C15: =IFERROR(INDEX(CALCULATIONS!$K$2:$K$22,MATCH(LARGE(CALCULATIONS!$V$2:$V$22,ROW()-5),CALCULATIONS!$V$2:$V$22,0)),"") -> David Wu | D15: =ROUND(LARGE(CALCULATIONS!$V$2:$V$22,ROW()-5),0) -> 26
B16: {=SUMPRODUCT((D$6:D$26>D16)/COUNTIF(D$6:D$26,D$6:D$26))+1} -> 8 | C16: =IFERROR(INDEX(CALCULATIONS!$K$2:$K$22,MATCH(LARGE(CALCULATIONS!$V$2:$V$22,ROW()-5),CALCULATIONS!$V$2:$V$22,0)),"") -> Azlan Husain | D16: =ROUND(LARGE(CALCULATIONS!$V$2:$V$22,ROW()-5),0) -> 20
B17: {=SUMPRODUCT((D$6:D$26>D17)/COUNTIF(D$6:D$26,D$6:D$26))+1} -> 9 | C17: =IFERROR(INDEX(CALCULATIONS!$K$2:$K$22,MATCH(LARGE(CALCULATIONS!$V$2:$V$22,ROW()-5),CALCULATIONS!$V$2:$V$22,0)),"") -> Edwin Mayers | D17: =ROUND(LARGE(CALCULATIONS!$V$2:$V$22,ROW()-5),0) -> 17
... B26: {=SUMPRODUCT((D$6:D$26>D26)/COUNTIF(D$6:D$26,D$6:D$26))+1} -> 10 | C26: =IFERROR(INDEX(CALCULATIONS!$K$2:$K$22,MATCH(LARGE(CALCULATIONS!$V$2:$V$22,ROW()-5),CALCULATIONS!$V$2:$V$22,0)),"") -> Alyza Rai | D26: =ROUND(LARGE(CALCULATIONS!$V$2:$V$22,ROW()-5),0) -> 0

Sheet GW Leaderboard
B1: GAMEWEEK LEADERBOARD
B2: This gameweek only • Sorted by points
B3: CURRENT GAMEWEEK: | C3: =HOME!C7 -> 1
B5: =IF(MAX($D$8:$D$28)=0,"🏆 GW"&$C$3&" WINNER: No results yet","🏆 GW"&$C$3&" WINNER: "&INDEX($C$8:$C$28,MATCH(MAX($D$8:$D$28),$D$8:$D$28,0))&" — "&MAX($D$8:$D$28)&" pts") -> 🏆 GW1 WINNER: Alexa Amesimeku — 43 pts
B7: Rank | C7: Manager | D7: GW Points
B8: {=SUMPRODUCT((D$8:D$28>D8)/COUNTIF(D$8:D$28,D$8:D$28))+1} -> 1 | C8: =IFERROR(INDEX(CALCULATIONS!$K$2:$K$22,MATCH(LARGE(CALCULATIONS!$V$2:$V$22,ROW()-7),CALCULATIONS!$V$2:$V$22,0)),"") -> Alexa Amesimeku | D8: =ROUND(LARGE(CALCULATIONS!$V$2:$V$22,ROW()-7),0) -> 43
B9: {=SUMPRODUCT((D$8:D$28>D9)/COUNTIF(D$8:D$28,D$8:D$28))+1} -> 2 | C9: =IFERROR(INDEX(CALCULATIONS!$K$2:$K$22,MATCH(LARGE(CALCULATIONS!$V$2:$V$22,ROW()-7),CALCULATIONS!$V$2:$V$22,0)),"") -> Oscar Day-Duran | D9: =ROUND(LARGE(CALCULATIONS!$V$2:$V$22,ROW()-7),0) -> 36
B10: {=SUMPRODUCT((D$8:D$28>D10)/COUNTIF(D$8:D$28,D$8:D$28))+1} -> 2 | C10: =IFERROR(INDEX(CALCULATIONS!$K$2:$K$22,MATCH(LARGE(CALCULATIONS!$V$2:$V$22,ROW()-7),CALCULATIONS!$V$2:$V$22,0)),"") -> Alfie Foley | D10: =ROUND(LARGE(CALCULATIONS!$V$2:$V$22,ROW()-7),0) -> 36
B11: {=SUMPRODUCT((D$8:D$28>D11)/COUNTIF(D$8:D$28,D$8:D$28))+1} -> 3 | C11: =IFERROR(INDEX(CALCULATIONS!$K$2:$K$22,MATCH(LARGE(CALCULATIONS!$V$2:$V$22,ROW()-7),CALCULATIONS!$V$2:$V$22,0)),"") -> Xander Meijer | D11: =ROUND(LARGE(CALCULATIONS!$V$2:$V$22,ROW()-7),0) -> 34
B12: {=SUMPRODUCT((D$8:D$28>D12)/COUNTIF(D$8:D$28,D$8:D$28))+1} -> 4 | C12: =IFERROR(INDEX(CALCULATIONS!$K$2:$K$22,MATCH(LARGE(CALCULATIONS!$V$2:$V$22,ROW()-7),CALCULATIONS!$V$2:$V$22,0)),"") -> Chinedu Chile | D12: =ROUND(LARGE(CALCULATIONS!$V$2:$V$22,ROW()-7),0) -> 31
B13: {=SUMPRODUCT((D$8:D$28>D13)/COUNTIF(D$8:D$28,D$8:D$28))+1} -> 4 | C13: =IFERROR(INDEX(CALCULATIONS!$K$2:$K$22,MATCH(LARGE(CALCULATIONS!$V$2:$V$22,ROW()-7),CALCULATIONS!$V$2:$V$22,0)),"") -> Ava Swinfen | D13: =ROUND(LARGE(CALCULATIONS!$V$2:$V$22,ROW()-7),0) -> 31
B14: {=SUMPRODUCT((D$8:D$28>D14)/COUNTIF(D$8:D$28,D$8:D$28))+1} -> 5 | C14: =IFERROR(INDEX(CALCULATIONS!$K$2:$K$22,MATCH(LARGE(CALCULATIONS!$V$2:$V$22,ROW()-7),CALCULATIONS!$V$2:$V$22,0)),"") -> Rory Bowman | D14: =ROUND(LARGE(CALCULATIONS!$V$2:$V$22,ROW()-7),0) -> 30
B15: {=SUMPRODUCT((D$8:D$28>D15)/COUNTIF(D$8:D$28,D$8:D$28))+1} -> 5 | C15: =IFERROR(INDEX(CALCULATIONS!$K$2:$K$22,MATCH(LARGE(CALCULATIONS!$V$2:$V$22,ROW()-7),CALCULATIONS!$V$2:$V$22,0)),"") -> Joe Paige | D15: =ROUND(LARGE(CALCULATIONS!$V$2:$V$22,ROW()-7),0) -> 30
B16: {=SUMPRODUCT((D$8:D$28>D16)/COUNTIF(D$8:D$28,D$8:D$28))+1} -> 6 | C16: =IFERROR(INDEX(CALCULATIONS!$K$2:$K$22,MATCH(LARGE(CALCULATIONS!$V$2:$V$22,ROW()-7),CALCULATIONS!$V$2:$V$22,0)),"") -> Melody Zhaeentan | D16: =ROUND(LARGE(CALCULATIONS!$V$2:$V$22,ROW()-7),0) -> 27
B17: {=SUMPRODUCT((D$8:D$28>D17)/COUNTIF(D$8:D$28,D$8:D$28))+1} -> 7 | C17: =IFERROR(INDEX(CALCULATIONS!$K$2:$K$22,MATCH(LARGE(CALCULATIONS!$V$2:$V$22,ROW()-7),CALCULATIONS!$V$2:$V$22,0)),"") -> David Wu | D17: =ROUND(LARGE(CALCULATIONS!$V$2:$V$22,ROW()-7),0) -> 26
B18: {=SUMPRODUCT((D$8:D$28>D18)/COUNTIF(D$8:D$28,D$8:D$28))+1} -> 8 | C18: =IFERROR(INDEX(CALCULATIONS!$K$2:$K$22,MATCH(LARGE(CALCULATIONS!$V$2:$V$22,ROW()-7),CALCULATIONS!$V$2:$V$22,0)),"") -> Azlan Husain | D18: =ROUND(LARGE(CALCULATIONS!$V$2:$V$22,ROW()-7),0) -> 20
B19: {=SUMPRODUCT((D$8:D$28>D19)/COUNTIF(D$8:D$28,D$8:D$28))+1} -> 9 | C19: =IFERROR(INDEX(CALCULATIONS!$K$2:$K$22,MATCH(LARGE(CALCULATIONS!$V$2:$V$22,ROW()-7),CALCULATIONS!$V$2:$V$22,0)),"") -> Edwin Mayers | D19: =ROUND(LARGE(CALCULATIONS!$V$2:$V$22,ROW()-7),0) -> 17
... B28: {=SUMPRODUCT((D$8:D$28>D28)/COUNTIF(D$8:D$28,D$8:D$28))+1} -> 10 | C28: =IFERROR(INDEX(CALCULATIONS!$K$2:$K$22,MATCH(LARGE(CALCULATIONS!$V$2:$V$22,ROW()-7),CALCULATIONS!$V$2:$V$22,0)),"") -> Alyza Rai | D28: =ROUND(LARGE(CALCULATIONS!$V$2:$V$22,ROW()-7),0) -> 0

Sheet SETTINGS
B1: SETTINGS — CONTROL PANEL
B2: Change the numbers below to update the whole league. Only gold cells are editable.
B3: GAME RULES
B4: Setting | C4: Value | D4: Notes
B5: Baseline points (at avg) | C5: 5 | D5: Points for scoring exactly the class average
B6: Dynamic step divisor | C6: 10 | D6: Class range (max−min) ÷ this = step size
B7: Minimum points | C7: 0 | D7: Floor
B8: Maximum points | C8: 10 | D8: Ceiling
B9: Max weekly price change | C9: 0.5 | D9: Absolute cap per week (£m)
B10: Tier multiplier (low) | C10: 1 | D10: £7.0–8.9m price band multiplier
B11: Tier multiplier (mid) | C11: 0.75 | D11: £9.0–10.9m price band multiplier
B12: Tier multiplier (high) | C12: 0.5 | D12: £11.0–13.0m price band multiplier
B13: Price change step | C13: 0.1 | D13: Ladder increment (£m)
B14: Minimum price | C14: 7 | D14: Floor (£m)
B15: Maximum price | C15: 13 | D15: Ceiling (£m)
B16: Price changes start at week | C16: 3 | D16: First week that price changes apply
... B18: Captain multiplier | C18: 2 | D18: Multiplier applied to captain's points (2 = double, 3 = triple)
B21: PLAYER PRICES
B22: Player | C22: Base | D22: Cumulative | E22: Override | F22: Final | H22: Dropdown
B23: Lia Li | C23: 13 | D23: =SUM(J23:Z23) -> 0 | F23: =IF(E23<>"",E23,MIN(SETTINGS!$C$15,MAX(SETTINGS!$C$14,C23+D23))) -> 13 | H23: =IF(B23="","",B23) -> Lia Li
B24: Sophie Barker | C24: 13 | D24: =SUM(J24:Z24) -> 0 | F24: =IF(E24<>"",E24,MIN(SETTINGS!$C$15,MAX(SETTINGS!$C$14,C24+D24))) -> 13 | H24: =IF(B24="","",B24) -> Sophie Barker
B25: Chinedu Chile | C25: 11 | D25: =SUM(J25:Z25) -> 0 | F25: =IF(E25<>"",E25,MIN(SETTINGS!$C$15,MAX(SETTINGS!$C$14,C25+D25))) -> 11 | H25: =IF(B25="","",B25) -> Chinedu Chile
B26: Emily Warburton | C26: 11 | D26: =SUM(J26:Z26) -> 0 | F26: =IF(E26<>"",E26,MIN(SETTINGS!$C$15,MAX(SETTINGS!$C$14,C26+D26))) -> 11 | H26: =IF(B26="","",B26) -> Emily Warburton
B27: Alyza Rai | C27: 10.5 | D27: =SUM(J27:Z27) -> 0 | F27: =IF(E27<>"",E27,MIN(SETTINGS!$C$15,MAX(SETTINGS!$C$14,C27+D27))) -> 10.5 | H27: =IF(B27="","",B27) -> Alyza Rai
B28: David Wu | C28: 10.5 | D28: =SUM(J28:Z28) -> 0 | F28: =IF(E28<>"",E28,MIN(SETTINGS!$C$15,MAX(SETTINGS!$C$14,C28+D28))) -> 10.5 | H28: =IF(B28="","",B28) -> David Wu
B29: Joe Paige | C29: 10.5 | D29: =SUM(J29:Z29) -> 0 | F29: =IF(E29<>"",E29,MIN(SETTINGS!$C$15,MAX(SETTINGS!$C$14,C29+D29))) -> 10.5 | H29: =IF(B29="","",B29) -> Joe Paige
B30: Azlan Husain | C30: 10 | D30: =SUM(J30:Z30) -> 0 | F30: =IF(E30<>"",E30,MIN(SETTINGS!$C$15,MAX(SETTINGS!$C$14,C30+D30))) -> 10 | H30: =IF(B30="","",B30) -> Azlan Husain
B31: Nina De Saram | C31: 10 | D31: =SUM(J31:Z31) -> 0 | F31: =IF(E31<>"",E31,MIN(SETTINGS!$C$15,MAX(SETTINGS!$C$14,C31+D31))) -> 10 | H31: =IF(B31="","",B31) -> Nina De Saram
B32: Alexa Amesimeku | C32: 9.5 | D32: =SUM(J32:Z32) -> 0 | F32: =IF(E32<>"",E32,MIN(SETTINGS!$C$15,MAX(SETTINGS!$C$14,C32+D32))) -> 9.5 | H32: =IF(B32="","",B32) -> Alexa Amesimeku
B33: Daniel Liu | C33: 9.5 | D33: =SUM(J33:Z33) -> 0 | F33: =IF(E33<>"",E33,MIN(SETTINGS!$C$15,MAX(SETTINGS!$C$14,C33+D33))) -> 9.5 | H33: =IF(B33="","",B33) -> Daniel Liu
B34: Rebecca Seymour | C34: 9.5 | D34: =SUM(J34:Z34) -> 0 | F34: =IF(E34<>"",E34,MIN(SETTINGS!$C$15,MAX(SETTINGS!$C$14,C34+D34))) -> 9.5 | H34: =IF(B34="","",B34) -> Rebecca Seymour
... B43: Xander Meijer | C43: 7 | D43: =SUM(J43:Z43) -> 0 | F43: =IF(E43<>"",E43,MIN(SETTINGS!$C$15,MAX(SETTINGS!$C$14,C43+D43))) -> 7 | H43: =IF(B43="","",B43) -> Xander Meijer
B47: WEEKLY PRICE LOG (auto-written by advance script)
B48: Player | C48: GW1 | D48: GW2 | E48: GW3 | F48: GW4 | G48: GW5 | H48: GW6 | I48: GW7 | J48: GW8 | K48: GW9 | L48: GW10 | M48: GW11 | N48: GW12 | O48: GW13 | P48: GW14 | Q48: GW15 | R48: GW16 | S48: GW17 | T48: GW18 | U48: GW19 | V48: GW20
B49: Lia Li
B50: Sophie Barker
B51: Chinedu Chile
B52: Emily Warburton
B53: Alyza Rai
B54: David Wu
...

Sheet RAW RESULTS
B1: Manager | C1: GW1 | D1: GW2 | E1: GW3 | F1: GW4 | G1: GW5 | H1: GW6 | I1: GW7 | J1: GW8 | K1: GW9 | L1: GW10 | M1: GW11 | N1: GW12 | O1: GW13 | P1: GW14 | Q1: GW15 | R1: GW16 | S1: GW17 | T1: GW18 | U1: GW19 | V1: GW20
B2: Alexa Amesimeku
B3: Alfie Foley
B4: Alyza Rai
B5: Ava Swinfen
B6: Azlan Husain
B7: Chinedu Chile
B8: Daniel Liu
B9: David Wu
B10: Edwin Mayers
B11: Emily Warburton
B12: Esme Beston
B13: Iona Smith
... B22: Xander Meijer

Sheet CALCULATIONS
A1: Player | B1: Base | C1: Current | D1: Pts | K1: Manager | L1: P1 | M1: P2 | N1: P3 | O1: P4 | P1: P5 | Q1: Captain | R1: Team Value | S1: Budget Left | T1: GW Score | U1: Status | V1: Tiebreak
A2: Lia Li | B2: 13 | C2: =SETTINGS!F23 -> 13 | D2: =IFERROR(IF(INDEX('TEST RESULTS'!$H$6:$H$26,MATCH(A2,'TEST RESULTS'!$B$6:$B$26,0))="",0,MAX(SETTINGS!$C$7,MIN(SETTINGS!$C$8,SETTINGS!$C$5+ROUNDDOWN((INDEX('TEST RESULTS'!$H$6:$H$26,MATCH(A2,'TEST RESULTS'!$B$6:$B$26,0))-AVERAGE('TEST RESULTS'!$H$6:$H$26))/MAX((MAX('TEST RESULTS'!$H$6:$H$26)-MIN('TEST RESULTS'!$H$6:$H$26))/SETTINGS!$C$6,0.1),0)))),0) -> 6 | K2: Alexa Amesimeku | L2: ='Alexa Amesimeku'!C10 -> Sophie Barker | M2: ='Alexa Amesimeku'!C11 -> Joe Paige | N2: ='Alexa Amesimeku'!C12 -> Alexa Amesimeku | O2: ='Alexa Amesimeku'!C13 -> Nina De Saram | P2: ='Alexa Amesimeku'!C14 -> Xander Meijer | Q2: ='Alexa Amesimeku'!C5 -> Sophie Barker | R2: ='Alexa Amesimeku'!C17 -> 50 | S2: ='Alexa Amesimeku'!C18 -> 0 | T2: =IF($U2="VALID TEAM",SUMPRODUCT(SUMIF($A$2:$A$22,L2:P2,$D$2:$D$22))+SUMIF($A$2:$A$22,Q2,$D$2:$D$22)*(SETTINGS!$C$18-1),0) -> 43 | U2: ='Alexa Amesimeku'!C20 -> VALID TEAM | V2: =T2+ROW()/10000 -> 43.0002
A3: Sophie Barker | B3: 13 | C3: =SETTINGS!F24 -> 13 | D3: =IFERROR(IF(INDEX('TEST RESULTS'!$H$6:$H$26,MATCH(A3,'TEST RESULTS'!$B$6:$B$26,0))="",0,MAX(SETTINGS!$C$7,MIN(SETTINGS!$C$8,SETTINGS!$C$5+ROUNDDOWN((INDEX('TEST RESULTS'!$H$6:$H$26,MATCH(A3,'TEST RESULTS'!$B$6:$B$26,0))-AVERAGE('TEST RESULTS'!$H$6:$H$26))/MAX((MAX('TEST RESULTS'!$H$6:$H$26)-MIN('TEST RESULTS'!$H$6:$H$26))/SETTINGS!$C$6,0.1),0)))),0) -> 9 | K3: Alfie Foley | L3: ='Alfie Foley'!C10 -> Ava Swinfen | M3: ='Alfie Foley'!C11 -> David Wu | N3: ='Alfie Foley'!C12 -> Alyza Rai | O3: ='Alfie Foley'!C13 -> Sophie Barker | P3: ='Alfie Foley'!C14 -> Edwin Mayers | Q3: ='Alfie Foley'!C5 -> Sophie Barker | R3: ='Alfie Foley'!C17 -> 50 | S3: ='Alfie Foley'!C18 -> 0 | T3: =IF($U3="VALID TEAM",SUMPRODUCT(SUMIF($A$2:$A$22,L3:P3,$D$2:$D$22))+SUMIF($A$2:$A$22,Q3,$D$2:$D$22)*(SETTINGS!$C$18-1),0) -> 36 | U3: ='Alfie Foley'!C20 -> VALID TEAM | V3: =T3+ROW()/10000 -> 36.0003
A4: Chinedu Chile | B4: 11 | C4: =SETTINGS!F25 -> 11 | D4: =IFERROR(IF(INDEX('TEST RESULTS'!$H$6:$H$26,MATCH(A4,'TEST RESULTS'!$B$6:$B$26,0))="",0,MAX(SETTINGS!$C$7,MIN(SETTINGS!$C$8,SETTINGS!$C$5+ROUNDDOWN((INDEX('TEST RESULTS'!$H$6:$H$26,MATCH(A4,'TEST RESULTS'!$B$6:$B$26,0))-AVERAGE('TEST RESULTS'!$H$6:$H$26))/MAX((MAX('TEST RESULTS'!$H$6:$H$26)-MIN('TEST RESULTS'!$H$6:$H$26))/SETTINGS!$C$6,0.1),0)))),0) -> 5 | K4: Alyza Rai | L4: ='Alyza Rai'!C10 -> 0 | M4: ='Alyza Rai'!C11 -> 0 | N4: ='Alyza Rai'!C12 -> 0 | O4: ='Alyza Rai'!C13 -> 0 | P4: ='Alyza Rai'!C14 -> 0 | Q4: ='Alyza Rai'!C5 -> 0 | R4: ='Alyza Rai'!C17 -> 0 | S4: ='Alyza Rai'!C18 -> 50 | T4: =IF($U4="VALID TEAM",SUMPRODUCT(SUMIF($A$2:$A$22,L4:P4,$D$2:$D$22))+SUMIF($A$2:$A$22,Q4,$D$2:$D$22)*(SETTINGS!$C$18-1),0) -> 0 | U4: ='Alyza Rai'!C20 -> LESS THAN 5 PLAYERS | V4: =T4+ROW()/10000 -> 0.0004
A5: Emily Warburton | B5: 11 | C5: =SETTINGS!F26 -> 11 | D5: =IFERROR(IF(INDEX('TEST RESULTS'!$H$6:$H$26,MATCH(A5,'TEST RESULTS'!$B$6:$B$26,0))="",0,MAX(SETTINGS!$C$7,MIN(SETTINGS!$C$8,SETTINGS!$C$5+ROUNDDOWN((INDEX('TEST RESULTS'!$H$6:$H$26,MATCH(A5,'TEST RESULTS'!$B$6:$B$26,0))-AVERAGE('TEST RESULTS'!$H$6:$H$26))/MAX((MAX('TEST RESULTS'!$H$6:$H$26)-MIN('TEST RESULTS'!$H$6:$H$26))/SETTINGS!$C$6,0.1),0)))),0) -> 0 | K5: Ava Swinfen | L5: ='Ava Swinfen'!C10 -> Ava Swinfen | M5: ='Ava Swinfen'!C11 -> Melody Zhaeentan | N5: ='Ava Swinfen'!C12 -> Lia Li | O5: ='Ava Swinfen'!C13 -> Chinedu Chile | P5: ='Ava Swinfen'!C14 -> David Wu | Q5: ='Ava Swinfen'!C5 -> Lia Li | R5: ='Ava Swinfen'!C17 -> 50 | S5: ='Ava Swinfen'!C18 -> 0 | T5: =IF($U5="VALID TEAM",SUMPRODUCT(SUMIF($A$2:$A$22,L5:P5,$D$2:$D$22))+SUMIF($A$2:$A$22,Q5,$D$2:$D$22)*(SETTINGS!$C$18-1),0) -> 31 | U5: ='Ava Swinfen'!C20 -> VALID TEAM | V5: =T5+ROW()/10000 -> 31.0005
A6: Alyza Rai | B6: 10.5 | C6: =SETTINGS!F27 -> 10.5 | D6: =IFERROR(IF(INDEX('TEST RESULTS'!$H$6:$H$26,MATCH(A6,'TEST RESULTS'!$B$6:$B$26,0))="",0,MAX(SETTINGS!$C$7,MIN(SETTINGS!$C$8,SETTINGS!$C$5+ROUNDDOWN((INDEX('TEST RESULTS'!$H$6:$H$26,MATCH(A6,'TEST RESULTS'!$B$6:$B$26,0))-AVERAGE('TEST RESULTS'!$H$6:$H$26))/MAX((MAX('TEST RESULTS'!$H$6:$H$26)-MIN('TEST RESULTS'!$H$6:$H$26))/SETTINGS!$C$6,0.1),0)))),0) -> 6 | K6: Azlan Husain | L6: ='Azlan Husain'!C10 -> Emily Warburton | M6: ='Azlan Husain'!C11 -> Chinedu Chile | N6: ='Azlan Husain'!C12 -> Joe Paige | O6: ='Azlan Husain'!C13 -> Alfie Foley | P6: ='Azlan Husain'!C14 -> Edwin Mayers | Q6: ='Azlan Husain'!C5 -> Emily Warburton | R6: ='Azlan Husain'!C17 -> 49 | S6: ='Azlan Husain'!C18 -> 1 | T6: =IF($U6="VALID TEAM",SUMPRODUCT(SUMIF($A$2:$A$22,L6:P6,$D$2:$D$22))+SUMIF($A$2:$A$22,Q6,$D$2:$D$22)*(SETTINGS!$C$18-1),0) -> 20 | U6: ='Azlan Husain'!C20 -> VALID TEAM | V6: =T6+ROW()/10000 -> 20.0006
A7: David Wu | B7: 10.5 | C7: =SETTINGS!F28 -> 10.5 | D7: =IFERROR(IF(INDEX('TEST RESULTS'!$H$6:$H$26,MATCH(A7,'TEST RESULTS'!$B$6:$B$26,0))="",0,MAX(SETTINGS!$C$7,MIN(SETTINGS!$C$8,SETTINGS!$C$5+ROUNDDOWN((INDEX('TEST RESULTS'!$H$6:$H$26,MATCH(A7,'TEST RESULTS'!$B$6:$B$26,0))-AVERAGE('TEST RESULTS'!$H$6:$H$26))/MAX((MAX('TEST RESULTS'!$H$6:$H$26)-MIN('TEST RESULTS'!$H$6:$H$26))/SETTINGS!$C$6,0.1),0)))),0) -> 5 | K7: Chinedu Chile | L7: ='Chinedu Chile'!C10 -> Chinedu Chile | M7: ='Chinedu Chile'!C11 -> Alexa Amesimeku | N7: ='Chinedu Chile'!C12 -> David Wu | O7: ='Chinedu Chile'!C13 -> Edwin Mayers | P7: ='Chinedu Chile'!C14 -> Azlan Husain | Q7: ='Chinedu Chile'!C5 -> Chinedu Chile | R7: ='Chinedu Chile'!C17 -> 50 | S7: ='Chinedu Chile'!C18 -> 0 | T7: =IF($U7="VALID TEAM",SUMPRODUCT(SUMIF($A$2:$A$22,L7:P7,$D$2:$D$22))+SUMIF($A$2:$A$22,Q7,$D$2:$D$22)*(SETTINGS!$C$18-1),0) -> 31 | U7: ='Chinedu Chile'!C20 -> VALID TEAM | V7: =T7+ROW()/10000 -> 31.0007
A8: Joe Paige | B8: 10.5 | C8: =SETTINGS!F29 -> 10.5 | D8: =IFERROR(IF(INDEX('TEST RESULTS'!$H$6:$H$26,MATCH(A8,'TEST RESULTS'!$B$6:$B$26,0))="",0,MAX(SETTINGS!$C$7,MIN(SETTINGS!$C$8,SETTINGS!$C$5+ROUNDDOWN((INDEX('TEST RESULTS'!$H$6:$H$26,MATCH(A8,'TEST RESULTS'!$B$6:$B$26,0))-AVERAGE('TEST RESULTS'!$H$6:$H$26))/MAX((MAX('TEST RESULTS'!$H$6:$H$26)-MIN('TEST RESULTS'!$H$6:$H$26))/SETTINGS!$C$6,0.1),0)))),0) -> 8 | K8: Daniel Liu | L8: ='Daniel Liu'!C10 -> Alyza Rai | M8: ='Daniel Liu'!C11 -> Ava Swinfen | N8: ='Daniel Liu'!C12 -> 0 | O8: ='Daniel Liu'!C13 -> David Wu | P8: ='Daniel Liu'!C14 -> Chinedu Chile | Q8: ='Daniel Liu'!C5 -> 0 | R8: ='Daniel Liu'!C17 -> 39 | S8: ='Daniel Liu'!C18 -> 11 | T8: =IF($U8="VALID TEAM",SUMPRODUCT(SUMIF($A$2:$A$22,L8:P8,$D$2:$D$22))+SUMIF($A$2:$A$22,Q8,$D$2:$D$22)*(SETTINGS!$C$18-1),0) -> 0 | U8: ='Daniel Liu'!C20 -> LESS THAN 5 PLAYERS | V8: =T8+ROW()/10000 -> 0.0008
A9: Azlan Husain | B9: 10 | C9: =SETTINGS!F30 -> 10 | D9: =IFERROR(IF(INDEX('TEST RESULTS'!$H$6:$H$26,MATCH(A9,'TEST RESULTS'!$B$6:$B$26,0))="",0,MAX(SETTINGS!$C$7,MIN(SETTINGS!$C$8,SETTINGS!$C$5+ROUNDDOWN((INDEX('TEST RESULTS'!$H$6:$H$26,MATCH(A9,'TEST RESULTS'!$B$6:$B$26,0))-AVERAGE('TEST RESULTS'!$H$6:$H$26))/MAX((MAX('TEST RESULTS'!$H$6:$H$26)-MIN('TEST RESULTS'!$H$6:$H$26))/SETTINGS!$C$6,0.1),0)))),0) -> 5 | K9: David Wu | L9: ='David Wu'!C10 -> Azlan Husain | M9: ='David Wu'!C11 -> Rebecca Seymour | N9: ='David Wu'!C12 -> Edwin Mayers | O9: ='David Wu'!C13 -> Chinedu Chile | P9: ='David Wu'!C14 -> Joe Paige | Q9: ='David Wu'!C5 -> Edwin Mayers | R9: ='David Wu'!C17 -> 50 | S9: ='David Wu'!C18 -> 0 | T9: =IF($U9="VALID TEAM",SUMPRODUCT(SUMIF($A$2:$A$22,L9:P9,$D$2:$D$22))+SUMIF($A$2:$A$22,Q9,$D$2:$D$22)*(SETTINGS!$C$18-1),0) -> 26 | U9: ='David Wu'!C20 -> VALID TEAM | V9: =T9+ROW()/10000 -> 26.0009
A10: Nina De Saram | B10: 10 | C10: =SETTINGS!F31 -> 10 | D10: =IFERROR(IF(INDEX('TEST RESULTS'!$H$6:$H$26,MATCH(A10,'TEST RESULTS'!$B$6:$B$26,0))="",0,MAX(SETTINGS!$C$7,MIN(SETTINGS!$C$8,SETTINGS!$C$5+ROUNDDOWN((INDEX('TEST RESULTS'!$H$6:$H$26,MATCH(A10,'TEST RESULTS'!$B$6:$B$26,0))-AVERAGE('TEST RESULTS'!$H$6:$H$26))/MAX((MAX('TEST RESULTS'!$H$6:$H$26)-MIN('TEST RESULTS'!$H$6:$H$26))/SETTINGS!$C$6,0.1),0)))),0) -> 7 | K10: Edwin Mayers | L10: ='Edwin Mayers'!C10 -> Sophie Barker | M10: ='Edwin Mayers'!C11 -> Esme Beston | N10: ='Edwin Mayers'!C12 -> Edwin Mayers | O10: ='Edwin Mayers'!C13 -> Emily Warburton | P10: ='Edwin Mayers'!C14 -> Ava Swinfen | Q10: ='Edwin Mayers'!C5 -> Emily Warburton | R10: ='Edwin Mayers'!C17 -> 48 | S10: ='Edwin Mayers'!C18 -> 2 | T10: =IF($U10="VALID TEAM",SUMPRODUCT(SUMIF($A$2:$A$22,L10:P10,$D$2:$D$22))+SUMIF($A$2:$A$22,Q10,$D$2:$D$22)*(SETTINGS!$C$18-1),0) -> 17 | U10: ='Edwin Mayers'!C20 -> VALID TEAM | V10: =T10+ROW()/10000 -> 17.001
A11: Alexa Amesimeku | B11: 9.5 | C11: =SETTINGS!F32 -> 9.5 | D11: =IFERROR(IF(INDEX('TEST RESULTS'!$H$6:$H$26,MATCH(A11,'TEST RESULTS'!$B$6:$B$26,0))="",0,MAX(SETTINGS!$C$7,MIN(SETTINGS!$C$8,SETTINGS!$C$5+ROUNDDOWN((INDEX('TEST RESULTS'!$H$6:$H$26,MATCH(A11,'TEST RESULTS'!$B$6:$B$26,0))-AVERAGE('TEST RESULTS'!$H$6:$H$26))/MAX((MAX('TEST RESULTS'!$H$6:$H$26)-MIN('TEST RESULTS'!$H$6:$H$26))/SETTINGS!$C$6,0.1),0)))),0) -> 7 | K11: Emily Warburton | L11: ='Emily Warburton'!C10 -> 0 | M11: ='Emily Warburton'!C11 -> 0 | N11: ='Emily Warburton'!C12 -> 0 | O11: ='Emily Warburton'!C13 -> 0 | P11: ='Emily Warburton'!C14 -> 0 | Q11: ='Emily Warburton'!C5 -> 0 | R11: ='Emily Warburton'!C17 -> 0 | S11: ='Emily Warburton'!C18 -> 50 | T11: =IF($U11="VALID TEAM",SUMPRODUCT(SUMIF($A$2:$A$22,L11:P11,$D$2:$D$22))+SUMIF($A$2:$A$22,Q11,$D$2:$D$22)*(SETTINGS!$C$18-1),0) -> 0 | U11: ='Emily Warburton'!C20 -> LESS THAN 5 PLAYERS | V11: =T11+ROW()/10000 -> 0.0011
A12: Daniel Liu | B12: 9.5 | C12: =SETTINGS!F33 -> 9.5 | D12: =IFERROR(IF(INDEX('TEST RESULTS'!$H$6:$H$26,MATCH(A12,'TEST RESULTS'!$B$6:$B$26,0))="",0,MAX(SETTINGS!$C$7,MIN(SETTINGS!$C$8,SETTINGS!$C$5+ROUNDDOWN((INDEX('TEST RESULTS'!$H$6:$H$26,MATCH(A12,'TEST RESULTS'!$B$6:$B$26,0))-AVERAGE('TEST RESULTS'!$H$6:$H$26))/MAX((MAX('TEST RESULTS'!$H$6:$H$26)-MIN('TEST RESULTS'!$H$6:$H$26))/SETTINGS!$C$6,0.1),0)))),0) -> 5 | K12: Esme Beston | L12: ='Esme Beston'!C10 -> 0 | M12: ='Esme Beston'!C11 -> 0 | N12: ='Esme Beston'!C12 -> 0 | O12: ='Esme Beston'!C13 -> 0 | P12: ='Esme Beston'!C14 -> 0 | Q12: ='Esme Beston'!C5 -> 0 | R12: ='Esme Beston'!C17 -> 0 | S12: ='Esme Beston'!C18 -> 50 | T12: =IF($U12="VALID TEAM",SUMPRODUCT(SUMIF($A$2:$A$22,L12:P12,$D$2:$D$22))+SUMIF($A$2:$A$22,Q12,$D$2:$D$22)*(SETTINGS!$C$18-1),0) -> 0 | U12: ='Esme Beston'!C20 -> LESS THAN 5 PLAYERS | V12: =T12+ROW()/10000 -> 0.0012
A13: Rebecca Seymour | B13: 9.5 | C13: =SETTINGS!F34 -> 9.5 | D13: =IFERROR(IF(INDEX('TEST RESULTS'!$H$6:$H$26,MATCH(A13,'TEST RESULTS'!$B$6:$B$26,0))="",0,MAX(SETTINGS!$C$7,MIN(SETTINGS!$C$8,SETTINGS!$C$5+ROUNDDOWN((INDEX('TEST RESULTS'!$H$6:$H$26,MATCH(A13,'TEST RESULTS'!$B$6:$B$26,0))-AVERAGE('TEST RESULTS'!$H$6:$H$26))/MAX((MAX('TEST RESULTS'!$H$6:$H$26)-MIN('TEST RESULTS'!$H$6:$H$26))/SETTINGS!$C$6,0.1),0)))),0) -> 0 | K13: Iona Smith | L13: ='Iona Smith'!C10 -> 0 | M13: ='Iona Smith'!C11 -> 0 | N13: ='Iona Smith'!C12 -> 0 | O13: ='Iona Smith'!C13 -> 0 | P13: ='Iona Smith'!C14 -> 0 | Q13: ='Iona Smith'!C5 -> 0 | R13: ='Iona Smith'!C17 -> 0 | S13: ='Iona Smith'!C18 -> 50 | T13: =IF($U13="VALID TEAM",SUMPRODUCT(SUMIF($A$2:$A$22,L13:P13,$D$2:$D$22))+SUMIF($A$2:$A$22,Q13,$D$2:$D$22)*(SETTINGS!$C$18-1),0) -> 0 | U13: ='Iona Smith'!C20 -> LESS THAN 5 PLAYERS | V13: =T13+ROW()/10000 -> 0.0013
A14: Edwin Mayers | B14: 9 | C14: =SETTINGS!F35 -> 9 | D14: =IFERROR(IF(INDEX('TEST RESULTS'!$H$6:$H$26,MATCH(A14,'TEST RESULTS'!$B$6:$B$26,0))="",0,MAX(SETTINGS!$C$7,MIN(SETTINGS!$C$8,SETTINGS!$C$5+ROUNDDOWN((INDEX('TEST RESULTS'!$H$6:$H$26,MATCH(A14,'TEST RESULTS'!$B$6:$B$26,0))-AVERAGE('TEST RESULTS'!$H$6:$H$26))/MAX((MAX('TEST RESULTS'!$H$6:$H$26)-MIN('TEST RESULTS'!$H$6:$H$26))/SETTINGS!$C$6,0.1),0)))),0) -> 4 | K14: Joe Paige | L14: ='Joe Paige'!C10 -> Chinedu Chile | M14: ='Joe Paige'!C11 -> Joe Paige | N14: ='Joe Paige'!C12 -> Alfie Foley | O14: ='Joe Paige'!C13 -> Lia Li | P14: ='Joe Paige'!C14 -> Oscar Day-Duran | Q14: ='Joe Paige'!C5 -> Chinedu Chile | R14: ='Joe Paige'!C17 -> 50 | S14: ='Joe Paige'!C18 -> 0 | T14: =IF($U14="VALID TEAM",SUMPRODUCT(SUMIF($A$2:$A$22,L14:P14,$D$2:$D$22))+SUMIF($A$2:$A$22,Q14,$D$2:$D$22)*(SETTINGS!$C$18-1),0) -> 30 | U14: ='Joe Paige'!C20 -> VALID TEAM | V14: =T14+ROW()/10000 -> 30.0014
A15: Melody Zhaeentan | B15: 8.5 | C15: =SETTINGS!F36 -> 8.5 | D15: =IFERROR(IF(INDEX('TEST RESULTS'!$H$6:$H$26,MATCH(A15,'TEST RESULTS'!$B$6:$B$26,0))="",0,MAX(SETTINGS!$C$7,MIN(SETTINGS!$C$8,SETTINGS!$C$5+ROUNDDOWN((INDEX('TEST RESULTS'!$H$6:$H$26,MATCH(A15,'TEST RESULTS'!$B$6:$B$26,0))-AVERAGE('TEST RESULTS'!$H$6:$H$26))/MAX((MAX('TEST RESULTS'!$H$6:$H$26)-MIN('TEST RESULTS'!$H$6:$H$26))/SETTINGS!$C$6,0.1),0)))),0) -> 6 | K15: Lia Li | L15: ='Lia Li'!C10 -> 0 | M15: ='Lia Li'!C11 -> 0 | N15: ='Lia Li'!C12 -> 0 | O15: ='Lia Li'!C13 -> 0 | P15: ='Lia Li'!C14 -> 0 | Q15: ='Lia Li'!C5 -> 0 | R15: ='Lia Li'!C17 -> 0 | S15: ='Lia Li'!C18 -> 50 | T15: =IF($U15="VALID TEAM",SUMPRODUCT(SUMIF($A$2:$A$22,L15:P15,$D$2:$D$22))+SUMIF($A$2:$A$22,Q15,$D$2:$D$22)*(SETTINGS!$C$18-1),0) -> 0 | U15: ='Lia Li'!C20 -> LESS THAN 5 PLAYERS | V15: =T15+ROW()/10000 -> 0.0015
A16: Esme Beston | B16: 8 | C16: =SETTINGS!F37 -> 8 | D16: =IFERROR(IF(INDEX('TEST RESULTS'!$H$6:$H$26,MATCH(A16,'TEST RESULTS'!$B$6:$B$26,0))="",0,MAX(SETTINGS!$C$7,MIN(SETTINGS!$C$8,SETTINGS!$C$5+ROUNDDOWN((INDEX('TEST RESULTS'!$H$6:$H$26,MATCH(A16,'TEST RESULTS'!$B$6:$B$26,0))-AVERAGE('TEST RESULTS'!$H$6:$H$26))/MAX((MAX('TEST RESULTS'!$H$6:$H$26)-MIN('TEST RESULTS'!$H$6:$H$26))/SETTINGS!$C$6,0.1),0)))),0) -> 1 | K16: Melody Zhaeentan | L16: ='Melody Zhaeentan'!C10 -> Lia Li | M16: ='Melody Zhaeentan'!C11 -> Edwin Mayers | N16: ='Melody Zhaeentan'!C12 -> Rebecca Seymour | O16: ='Melody Zhaeentan'!C13 -> Joe Paige | P16: ='Melody Zhaeentan'!C14 -> Xander Meijer | Q16: ='Melody Zhaeentan'!C5 -> Lia Li | R16: ='Melody Zhaeentan'!C17 -> 49 | S16: ='Melody Zhaeentan'!C18 -> 1 | T16: =IF($U16="VALID TEAM",SUMPRODUCT(SUMIF($A$2:$A$22,L16:P16,$D$2:$D$22))+SUMIF($A$2:$A$22,Q16,$D$2:$D$22)*(SETTINGS!$C$18-1),0) -> 27 | U16: ='Melody Zhaeentan'!C20 -> VALID TEAM | V16: =T16+ROW()/10000 -> 27.0016
A17: Iona Smith | B17: 8 | C17: =SETTINGS!F38 -> 8 | D17: =IFERROR(IF(INDEX('TEST RESULTS'!$H$6:$H$26,MATCH(A17,'TEST RESULTS'!$B$6:$B$26,0))="",0,MAX(SETTINGS!$C$7,MIN(SETTINGS!$C$8,SETTINGS!$C$5+ROUNDDOWN((INDEX('TEST RESULTS'!$H$6:$H$26,MATCH(A17,'TEST RESULTS'!$B$6:$B$26,0))-AVERAGE('TEST RESULTS'!$H$6:$H$26))/MAX((MAX('TEST RESULTS'!$H$6:$H$26)-MIN('TEST RESULTS'!$H$6:$H$26))/SETTINGS!$C$6,0.1),0)))),0) -> 0 | K17: Nina De Saram | L17: ='Nina De Saram'!C10 -> 0 | M17: ='Nina De Saram'!C11 -> 0 | N17: ='Nina De Saram'!C12 -> 0 | O17: ='Nina De Saram'!C13 -> 0 | P17: ='Nina De Saram'!C14 -> 0 | Q17: ='Nina De Saram'!C5 -> 0 | R17: ='Nina De Saram'!C17 -> 0 | S17: ='Nina De Saram'!C18 -> 50 | T17: =IF($U17="VALID TEAM",SUMPRODUCT(SUMIF($A$2:$A$22,L17:P17,$D$2:$D$22))+SUMIF($A$2:$A$22,Q17,$D$2:$D$22)*(SETTINGS!$C$18-1),0) -> 0 | U17: ='Nina De Saram'!C20 -> LESS THAN 5 PLAYERS | V17: =T17+ROW()/10000 -> 0.0017
A18: Oscar Day-Duran | B18: 8 | C18: =SETTINGS!F39 -> 8 | D18: =IFERROR(IF(INDEX('TEST RESULTS'!$H$6:$H$26,MATCH(A18,'TEST RESULTS'!$B$6:$B$26,0))="",0,MAX(SETTINGS!$C$7,MIN(SETTINGS!$C$8,SETTINGS!$C$5+ROUNDDOWN((INDEX('TEST RESULTS'!$H$6:$H$26,MATCH(A18,'TEST RESULTS'!$B$6:$B$26,0))-AVERAGE('TEST RESULTS'!$H$6:$H$26))/MAX((MAX('TEST RESULTS'!$H$6:$H$26)-MIN('TEST RESULTS'!$H$6:$H$26))/SETTINGS!$C$6,0.1),0)))),0) -> 3 | K18: Oscar Day-Duran | L18: ='Oscar Day-Duran'!C10 -> Oscar Day-Duran | M18: ='Oscar Day-Duran'!C11 -> Chinedu Chile | N18: ='Oscar Day-Duran'!C12 -> Nina De Saram | O18: ='Oscar Day-Duran'!C13 -> David Wu | P18: ='Oscar Day-Duran'!C14 -> Joe Paige | Q18: ='Oscar Day-Duran'!C5 -> Joe Paige | R18: ='Oscar Day-Duran'!C17 -> 50 | S18: ='Oscar Day-Duran'!C18 -> 0 | T18: =IF($U18="VALID TEAM",SUMPRODUCT(SUMIF($A$2:$A$22,L18:P18,$D$2:$D$22))+SUMIF($A$2:$A$22,Q18,$D$2:$D$22)*(SETTINGS!$C$18-1),0) -> 36 | U18: ='Oscar Day-Duran'!C20 -> VALID TEAM | V18: =T18+ROW()/10000 -> 36.0018
A19: Alfie Foley | B19: 7.5 | C19: =SETTINGS!F40 -> 7.5 | D19: =IFERROR(IF(INDEX('TEST RESULTS'!$H$6:$H$26,MATCH(A19,'TEST RESULTS'!$B$6:$B$26,0))="",0,MAX(SETTINGS!$C$7,MIN(SETTINGS!$C$8,SETTINGS!$C$5+ROUNDDOWN((INDEX('TEST RESULTS'!$H$6:$H$26,MATCH(A19,'TEST RESULTS'!$B$6:$B$26,0))-AVERAGE('TEST RESULTS'!$H$6:$H$26))/MAX((MAX('TEST RESULTS'!$H$6:$H$26)-MIN('TEST RESULTS'!$H$6:$H$26))/SETTINGS!$C$6,0.1),0)))),0) -> 3 | K19: Rebecca Seymour | L19: ='Rebecca Seymour'!C10 -> 0 | M19: ='Rebecca Seymour'!C11 -> 0 | N19: ='Rebecca Seymour'!C12 -> 0 | O19: ='Rebecca Seymour'!C13 -> 0 | P19: ='Rebecca Seymour'!C14 -> 0 | Q19: ='Rebecca Seymour'!C5 -> 0 | R19: ='Rebecca Seymour'!C17 -> 0 | S19: ='Rebecca Seymour'!C18 -> 50 | T19: =IF($U19="VALID TEAM",SUMPRODUCT(SUMIF($A$2:$A$22,L19:P19,$D$2:$D$22))+SUMIF($A$2:$A$22,Q19,$D$2:$D$22)*(SETTINGS!$C$18-1),0) -> 0 | U19: ='Rebecca Seymour'!C20 -> LESS THAN 5 PLAYERS | V19: =T19+ROW()/10000 -> 0.0019
A20: Ava Swinfen | B20: 7 | C20: =SETTINGS!F41 -> 7 | D20: =IFERROR(IF(INDEX('TEST RESULTS'!$H$6:$H$26,MATCH(A20,'TEST RESULTS'!$B$6:$B$26,0))="",0,MAX(SETTINGS!$C$7,MIN(SETTINGS!$C$8,SETTINGS!$C$5+ROUNDDOWN((INDEX('TEST RESULTS'!$H$6:$H$26,MATCH(A20,'TEST RESULTS'!$B$6:$B$26,0))-AVERAGE('TEST RESULTS'!$H$6:$H$26))/MAX((MAX('TEST RESULTS'!$H$6:$H$26)-MIN('TEST RESULTS'!$H$6:$H$26))/SETTINGS!$C$6,0.1),0)))),0) -> 3 | K20: Rory Bowman | L20: ='Rory Bowman'!C10 -> David Wu | M20: ='Rory Bowman'!C11 -> Ava Swinfen | N20: ='Rory Bowman'!C12 -> Alyza Rai | O20: ='Rory Bowman'!C13 -> Edwin Mayers | P20: ='Rory Bowman'!C14 -> Lia Li | Q20: ='Rory Bowman'!C5 -> Lia Li | R20: ='Rory Bowman'!C17 -> 50 | S20: ='Rory Bowman'!C18 -> 0 | T20: =IF($U20="VALID TEAM",SUMPRODUCT(SUMIF($A$2:$A$22,L20:P20,$D$2:$D$22))+SUMIF($A$2:$A$22,Q20,$D$2:$D$22)*(SETTINGS!$C$18-1),0) -> 30 | U20: ='Rory Bowman'!C20 -> VALID TEAM | V20: =T20+ROW()/10000 -> 30.002
A21: Rory Bowman | B21: 7 | C21: =SETTINGS!F42 -> 7 | D21: =IFERROR(IF(INDEX('TEST RESULTS'!$H$6:$H$26,MATCH(A21,'TEST RESULTS'!$B$6:$B$26,0))="",0,MAX(SETTINGS!$C$7,MIN(SETTINGS!$C$8,SETTINGS!$C$5+ROUNDDOWN((INDEX('TEST RESULTS'!$H$6:$H$26,MATCH(A21,'TEST RESULTS'!$B$6:$B$26,0))-AVERAGE('TEST RESULTS'!$H$6:$H$26))/MAX((MAX('TEST RESULTS'!$H$6:$H$26)-MIN('TEST RESULTS'!$H$6:$H$26))/SETTINGS!$C$6,0.1),0)))),0) -> 0 | K21: Sophie Barker | L21: ='Sophie Barker'!C10 -> 0 | M21: ='Sophie Barker'!C11 -> 0 | N21: ='Sophie Barker'!C12 -> 0 | O21: ='Sophie Barker'!C13 -> 0 | P21: ='Sophie Barker'!C14 -> 0 | Q21: ='Sophie Barker'!C5 -> 0 | R21: ='Sophie Barker'!C17 -> 0 | S21: ='Sophie Barker'!C18 -> 50 | T21: =IF($U21="VALID TEAM",SUMPRODUCT(SUMIF($A$2:$A$22,L21:P21,$D$2:$D$22))+SUMIF($A$2:$A$22,Q21,$D$2:$D$22)*(SETTINGS!$C$18-1),0) -> 0 | U21: ='Sophie Barker'!C20 -> LESS THAN 5 PLAYERS | V21: =T21+ROW()/10000 -> 0.0021
A22: Xander Meijer | B22: 7 | C22: =SETTINGS!F43 -> 7 | D22: =IFERROR(IF(INDEX('TEST RESULTS'!$H$6:$H$26,MATCH(A22,'TEST RESULTS'!$B$6:$B$26,0))="",0,MAX(SETTINGS!$C$7,MIN(SETTINGS!$C$8,SETTINGS!$C$5+ROUNDDOWN((INDEX('TEST RESULTS'!$H$6:$H$26,MATCH(A22,'TEST RESULTS'!$B$6:$B$26,0))-AVERAGE('TEST RESULTS'!$H$6:$H$26))/MAX((MAX('TEST RESULTS'!$H$6:$H$26)-MIN('TEST RESULTS'!$H$6:$H$26))/SETTINGS!$C$6,0.1),0)))),0) -> 3 | K22: Xander Meijer | L22: ='Xander Meijer'!C10 -> Lia Li | M22: ='Xander Meijer'!C11 -> David Wu | N22: ='Xander Meijer'!C12 -> Ava Swinfen | O22: ='Xander Meijer'!C13 -> Joe Paige | P22: ='Xander Meijer'!C14 -> Melody Zhaeentan | Q22: ='Xander Meijer'!C5 -> Lia Li | R22: ='Xander Meijer'!C17 -> 49.5 | S22: ='Xander Meijer'!C18 -> 0.5 | T22: =IF($U22="VALID TEAM",SUMPRODUCT(SUMIF($A$2:$A$22,L22:P22,$D$2:$D$22))+SUMIF($A$2:$A$22,Q22,$D$2:$D$22)*(SETTINGS!$C$18-1),0) -> 34 | U22: ='Xander Meijer'!C20 -> VALID TEAM | V22: =T22+ROW()/10000 -> 34.0022

Sheet Alexa Amesimeku
B1: ALEXA AMESIMEKU'S TEAM
B2: ← Back to PICK YOUR TEAM
B4: PICK YOUR CAPTAIN (scores 2× points)
C5: Sophie Barker
B6: Step 1: Pick 5 players. Step 2: Choose your captain in the GOLD box above.
B8: SQUAD
B9: Slot | C9: Player | D9: Price | E9: Points
B10: 1 | C10: Sophie Barker | D10: =IF(C10="","",IFERROR(INDEX(CALCULATIONS!$C$2:$C$22,MATCH(C10,CALCULATIONS!$A$2:$A$22,0)),"")) -> 13 | E10: =IF(C10="","",IF(C10=$C$5,TEXT(IFERROR(INDEX(CALCULATIONS!$D$2:$D$22,MATCH(C10,CALCULATIONS!$A$2:$A$22,0)),0)*SETTINGS!$C$18,"0")&" (×"&SETTINGS!$C$18&")",TEXT(IFERROR(INDEX(CALCULATIONS!$D$2:$D$22,MATCH(C10,CALCULATIONS!$A$2:$A$22,0)),0),"0"))) -> 18 (×2)
B11: 2 | C11: Joe Paige | D11: =IF(C11="","",IFERROR(INDEX(CALCULATIONS!$C$2:$C$22,MATCH(C11,CALCULATIONS!$A$2:$A$22,0)),"")) -> 10.5 | E11: =IF(C11="","",IF(C11=$C$5,TEXT(IFERROR(INDEX(CALCULATIONS!$D$2:$D$22,MATCH(C11,CALCULATIONS!$A$2:$A$22,0)),0)*SETTINGS!$C$18,"0")&" (×"&SETTINGS!$C$18&")",TEXT(IFERROR(INDEX(CALCULATIONS!$D$2:$D$22,MATCH(C11,CALCULATIONS!$A$2:$A$22,0)),0),"0"))) -> 8
B12: 3 | C12: Alexa Amesimeku | D12: =IF(C12="","",IFERROR(INDEX(CALCULATIONS!$C$2:$C$22,MATCH(C12,CALCULATIONS!$A$2:$A$22,0)),"")) -> 9.5 | E12: =IF(C12="","",IF(C12=$C$5,TEXT(IFERROR(INDEX(CALCULATIONS!$D$2:$D$22,MATCH(C12,CALCULATIONS!$A$2:$A$22,0)),0)*SETTINGS!$C$18,"0")&" (×"&SETTINGS!$C$18&")",TEXT(IFERROR(INDEX(CALCULATIONS!$D$2:$D$22,MATCH(C12,CALCULATIONS!$A$2:$A$22,0)),0),"0"))) -> 7
B13: 4 | C13: Nina De Saram | D13: =IF(C13="","",IFERROR(INDEX(CALCULATIONS!$C$2:$C$22,MATCH(C13,CALCULATIONS!$A$2:$A$22,0)),"")) -> 10 | E13: =IF(C13="","",IF(C13=$C$5,TEXT(IFERROR(INDEX(CALCULATIONS!$D$2:$D$22,MATCH(C13,CALCULATIONS!$A$2:$A$22,0)),0)*SETTINGS!$C$18,"0")&" (×"&SETTINGS!$C$18&")",TEXT(IFERROR(INDEX(CALCULATIONS!$D$2:$D$22,MATCH(C13,CALCULATIONS!$A$2:$A$22,0)),0),"0"))) -> 7
B14: 5 | C14: Xander Meijer | D14: =IF(C14="","",IFERROR(INDEX(CALCULATIONS!$C$2:$C$22,MATCH(C14,CALCULATIONS!$A$2:$A$22,0)),"")) -> 7 | E14: =IF(C14="","",IF(C14=$C$5,TEXT(IFERROR(INDEX(CALCULATIONS!$D$2:$D$22,MATCH(C14,CALCULATIONS!$A$2:$A$22,0)),0)*SETTINGS!$C$18,"0")&" (×"&SETTINGS!$C$18&")",TEXT(IFERROR(INDEX(CALCULATIONS!$D$2:$D$22,MATCH(C14,CALCULATIONS!$A$2:$A$22,0)),0),"0"))) -> 3
B16: TEAM SUMMARY
B17: Team Value | C17: =SUM(D10:D14) -> 50
B18: Budget Left | C18: =50-C17 -> 0
B19: GW Score | C19: =IF($C$20="VALID TEAM",SUMPRODUCT(SUMIF(CALCULATIONS!$A$2:$A$22,C10:C14,CALCULATIONS!$D$2:$D$22))+SUMIF(CALCULATIONS!$A$2:$A$22,C5,CALCULATIONS!$D$2:$D$22)*(SETTINGS!$C$18-1),0) -> 43
B20: Team Status | C20: =IF(COUNTBLANK(C10:C14)>0,"LESS THAN 5 PLAYERS",IF(SUM(D10:D14)>50,"OVER BUDGET",IF(C5="","NO CAPTAIN",IF(COUNTIF(C10:C14,C5)=0,"CAPTAIN NOT IN SQUAD",IF(SUMPRODUCT(COUNTIF(C10:C14,C10:C14))>5,"DUPLICATE PLAYER","VALID TEAM"))))) -> VALID TEAM
B22: INPUT CELLS ARE GOLD. Only the captain cell (C5) and the 5 player cells (C10:C14) should be edited. Do NOT type 'CAPTAIN' anywhere in the squad.

Sheet Alfie Foley
B1: ALFIE FOLEY'S TEAM
B2: ← Back to PICK YOUR TEAM
B4: PICK YOUR CAPTAIN (scores 2× points)
C5: Sophie Barker
B6: Step 1: Pick 5 players. Step 2: Choose your captain in the GOLD box above.
B8: SQUAD
B9: Slot | C9: Player | D9: Price | E9: Points
B10: 1 | C10: Ava Swinfen | D10: =IF(C10="","",IFERROR(INDEX(CALCULATIONS!$C$2:$C$22,MATCH(C10,CALCULATIONS!$A$2:$A$22,0)),"")) -> 7 | E10: =IF(C10="","",IF(C10=$C$5,TEXT(IFERROR(INDEX(CALCULATIONS!$D$2:$D$22,MATCH(C10,CALCULATIONS!$A$2:$A$22,0)),0)*SETTINGS!$C$18,"0")&" (×"&SETTINGS!$C$18&")",TEXT(IFERROR(INDEX(CALCULATIONS!$D$2:$D$22,MATCH(C10,CALCULATIONS!$A$2:$A$22,0)),0),"0"))) -> 3
B11: 2 | C11: David Wu | D11: =IF(C11="","",IFERROR(INDEX(CALCULATIONS!$C$2:$C$22,MATCH(C11,CALCULATIONS!$A$2:$A$22,0)),"")) -> 10.5 | E11: =IF(C11="","",IF(C11=$C$5,TEXT(IFERROR(INDEX(CALCULATIONS!$D$2:$D$22,MATCH(C11,CALCULATIONS!$A$2:$A$22,0)),0)*SETTINGS!$C$18,"0")&" (×"&SETTINGS!$C$18&")",TEXT(IFERROR(INDEX(CALCULATIONS!$D$2:$D$22,MATCH(C11,CALCULATIONS!$A$2:$A$22,0)),0),"0"))) -> 5
B12: 3 | C12: Alyza Rai | D12: =IF(C12="","",IFERROR(INDEX(CALCULATIONS!$C$2:$C$22,MATCH(C12,CALCULATIONS!$A$2:$A$22,0)),"")) -> 10.5 | E12: =IF(C12="","",IF(C12=$C$5,TEXT(IFERROR(INDEX(CALCULATIONS!$D$2:$D$22,MATCH(C12,CALCULATIONS!$A$2:$A$22,0)),0)*SETTINGS!$C$18,"0")&" (×"&SETTINGS!$C$18&")",TEXT(IFERROR(INDEX(CALCULATIONS!$D$2:$D$22,MATCH(C12,CALCULATIONS!$A$2:$A$22,0)),0),"0"))) -> 6
B13: 4 | C13: Sophie Barker | D13: =IF(C13="","",IFERROR(INDEX(CALCULATIONS!$C$2:$C$22,MATCH(C13,CALCULATIONS!$A$2:$A$22,0)),"")) -> 13 | E13: =IF(C13="","",IF(C13=$C$5,TEXT(IFERROR(INDEX(CALCULATIONS!$D$2:$D$22,MATCH(C13,CALCULATIONS!$A$2:$A$22,0)),0)*SETTINGS!$C$18,"0")&" (×"&SETTINGS!$C$18&")",TEXT(IFERROR(INDEX(CALCULATIONS!$D$2:$D$22,MATCH(C13,CALCULATIONS!$A$2:$A$22,0)),0),"0"))) -> 18 (×2)
B14: 5 | C14: Edwin Mayers | D14: =IF(C14="","",IFERROR(INDEX(CALCULATIONS!$C$2:$C$22,MATCH(C14,CALCULATIONS!$A$2:$A$22,0)),"")) -> 9 | E14: =IF(C14="","",IF(C14=$C$5,TEXT(IFERROR(INDEX(CALCULATIONS!$D$2:$D$22,MATCH(C14,CALCULATIONS!$A$2:$A$22,0)),0)*SETTINGS!$C$18,"0")&" (×"&SETTINGS!$C$18&")",TEXT(IFERROR(INDEX(CALCULATIONS!$D$2:$D$22,MATCH(C14,CALCULATIONS!$A$2:$A$22,0)),0),"0"))) -> 4
B16: TEAM SUMMARY
B17: Team Value | C17: =SUM(D10:D14) -> 50
B18: Budget Left | C18: =50-C17 -> 0
B19: GW Score | C19: =IF($C$20="VALID TEAM",SUMPRODUCT(SUMIF(CALCULATIONS!$A$2:$A$22,C10:C14,CALCULATIONS!$D$2:$D$22))+SUMIF(CALCULATIONS!$A$2:$A$22,C5,CALCULATIONS!$D$2:$D$22)*(SETTINGS!$C$18-1),0) -> 36
B20: Team Status | C20: =IF(COUNTBLANK(C10:C14)>0,"LESS THAN 5 PLAYERS",IF(SUM(D10:D14)>50,"OVER BUDGET",IF(C5="","NO CAPTAIN",IF(COUNTIF(C10:C14,C5)=0,"CAPTAIN NOT IN SQUAD",IF(SUMPRODUCT(COUNTIF(C10:C14,C10:C14))>5,"DUPLICATE PLAYER","VALID TEAM"))))) -> VALID TEAM
B22: INPUT CELLS ARE GOLD. Only the captain cell (C5) and the 5 player cells (C10:C14) should be edited. Do NOT type 'CAPTAIN' anywhere in the squad.

Sheet Alyza Rai
B1: ALYZA RAI'S TEAM
B2: ← Back to PICK YOUR TEAM
B4: PICK YOUR CAPTAIN (scores 2× points)
B6: Step 1: Pick 5 players. Step 2: Choose your captain in the GOLD box above.
B8: SQUAD
B9: Slot | C9: Player | D9: Price | E9: Points
B10: 1 | D10: =IF(C10="","",IFERROR(INDEX(CALCULATIONS!$C$2:$C$22,MATCH(C10,CALCULATIONS!$A$2:$A$22,0)),"")) | E10: =IF(C10="","",IF(C10=$C$5,TEXT(IFERROR(INDEX(CALCULATIONS!$D$2:$D$22,MATCH(C10,CALCULATIONS!$A$2:$A$22,0)),0)*SETTINGS!$C$18,"0")&" (×"&SETTINGS!$C$18&")",TEXT(IFERROR(INDEX(CALCULATIONS!$D$2:$D$22,MATCH(C10,CALCULATIONS!$A$2:$A$22,0)),0),"0")))
B11: 2 | D11: =IF(C11="","",IFERROR(INDEX(CALCULATIONS!$C$2:$C$22,MATCH(C11,CALCULATIONS!$A$2:$A$22,0)),"")) | E11: =IF(C11="","",IF(C11=$C$5,TEXT(IFERROR(INDEX(CALCULATIONS!$D$2:$D$22,MATCH(C11,CALCULATIONS!$A$2:$A$22,0)),0)*SETTINGS!$C$18,"0")&" (×"&SETTINGS!$C$18&")",TEXT(IFERROR(INDEX(CALCULATIONS!$D$2:$D$22,MATCH(C11,CALCULATIONS!$A$2:$A$22,0)),0),"0")))
B12: 3 | D12: =IF(C12="","",IFERROR(INDEX(CALCULATIONS!$C$2:$C$22,MATCH(C12,CALCULATIONS!$A$2:$A$22,0)),"")) | E12: =IF(C12="","",IF(C12=$C$5,TEXT(IFERROR(INDEX(CALCULATIONS!$D$2:$D$22,MATCH(C12,CALCULATIONS!$A$2:$A$22,0)),0)*SETTINGS!$C$18,"0")&" (×"&SETTINGS!$C$18&")",TEXT(IFERROR(INDEX(CALCULATIONS!$D$2:$D$22,MATCH(C12,CALCULATIONS!$A$2:$A$22,0)),0),"0")))
B13: 4 | D13: =IF(C13="","",IFERROR(INDEX(CALCULATIONS!$C$2:$C$22,MATCH(C13,CALCULATIONS!$A$2:$A$22,0)),"")) | E13: =IF(C13="","",IF(C13=$C$5,TEXT(IFERROR(INDEX(CALCULATIONS!$D$2:$D$22,MATCH(C13,CALCULATIONS!$A$2:$A$22,0)),0)*SETTINGS!$C$18,"0")&" (×"&SETTINGS!$C$18&")",TEXT(IFERROR(INDEX(CALCULATIONS!$D$2:$D$22,MATCH(C13,CALCULATIONS!$A$2:$A$22,0)),0),"0")))
B14: 5 | D14: =IF(C14="","",IFERROR(INDEX(CALCULATIONS!$C$2:$C$22,MATCH(C14,CALCULATIONS!$A$2:$A$22,0)),"")) | E14: =IF(C14="","",IF(C14=$C$5,TEXT(IFERROR(INDEX(CALCULATIONS!$D$2:$D$22,MATCH(C14,CALCULATIONS!$A$2:$A$22,0)),0)*SETTINGS!$C$18,"0")&" (×"&SETTINGS!$C$18&")",TEXT(IFERROR(INDEX(CALCULATIONS!$D$2:$D$22,MATCH(C14,CALCULATIONS!$A$2:$A$22,0)),0),"0")))
B16: TEAM SUMMARY
B17: Team Value | C17: =SUM(D10:D14) -> 0
B18: Budget Left | C18: =50-C17 -> 50
B19: GW Score | C19: =IF($C$20="VALID TEAM",SUMPRODUCT(SUMIF(CALCULATIONS!$A$2:$A$22,C10:C14,CALCULATIONS!$D$2:$D$22))+SUMIF(CALCULATIONS!$A$2:$A$22,C5,CALCULATIONS!$D$2:$D$22)*(SETTINGS!$C$18-1),0) -> 0
B20: Team Status | C20: =IF(COUNTBLANK(C10:C14)>0,"LESS THAN 5 PLAYERS",IF(SUM(D10:D14)>50,"OVER BUDGET",IF(C5="","NO CAPTAIN",IF(COUNTIF(C10:C14,C5)=0,"CAPTAIN NOT IN SQUAD",IF(SUMPRODUCT(COUNTIF(C10:C14,C10:C14))>5,"DUPLICATE PLAYER","VALID TEAM"))))) -> LESS THAN 5 PLAYERS
B22: INPUT CELLS ARE GOLD. Only the captain cell (C5) and the 5 player cells (C10:C14) should be edited. Do NOT type 'CAPTAIN' anywhere in the squad.

Sheet Ava Swinfen
B1: AVA SWINFEN'S TEAM
B2: ← Back to PICK YOUR TEAM
B4: PICK YOUR CAPTAIN (scores 2× points)
C5: Lia Li
B6: Step 1: Pick 5 players. Step 2: Choose your captain in the GOLD box above.
B8: SQUAD
B9: Slot | C9: Player | D9: Price | E9: Points
B10: 1 | C10: Ava Swinfen | D10: =IF(C10="","",IFERROR(INDEX(CALCULATIONS!$C$2:$C$22,MATCH(C10,CALCULATIONS!$A$2:$A$22,0)),"")) -> 7 | E10: =IF(C10="","",IF(C10=$C$5,TEXT(IFERROR(INDEX(CALCULATIONS!$D$2:$D$22,MATCH(C10,CALCULATIONS!$A$2:$A$22,0)),0)*SETTINGS!$C$18,"0")&" (×"&SETTINGS!$C$18&")",TEXT(IFERROR(INDEX(CALCULATIONS!$D$2:$D$22,MATCH(C10,CALCULATIONS!$A$2:$A$22,0)),0),"0"))) -> 3
B11: 2 | C11: Melody Zhaeentan | D11: =IF(C11="","",IFERROR(INDEX(CALCULATIONS!$C$2:$C$22,MATCH(C11,CALCULATIONS!$A$2:$A$22,0)),"")) -> 8.5 | E11: =IF(C11="","",IF(C11=$C$5,TEXT(IFERROR(INDEX(CALCULATIONS!$D$2:$D$22,MATCH(C11,CALCULATIONS!$A$2:$A$22,0)),0)*SETTINGS!$C$18,"0")&" (×"&SETTINGS!$C$18&")",TEXT(IFERROR(INDEX(CALCULATIONS!$D$2:$D$22,MATCH(C11,CALCULATIONS!$A$2:$A$22,0)),0),"0"))) -> 6
B12: 3 | C12: Lia Li | D12: =IF(C12="","",IFERROR(INDEX(CALCULATIONS!$C$2:$C$22,MATCH(C12,CALCULATIONS!$A$2:$A$22,0)),"")) -> 13 | E12: =IF(C12="","",IF(C12=$C$5,TEXT(IFERROR(INDEX(CALCULATIONS!$D$2:$D$22,MATCH(C12,CALCULATIONS!$A$2:$A$22,0)),0)*SETTINGS!$C$18,"0")&" (×"&SETTINGS!$C$18&")",TEXT(IFERROR(INDEX(CALCULATIONS!$D$2:$D$22,MATCH(C12,CALCULATIONS!$A$2:$A$22,0)),0),"0"))) -> 12 (×2)
B13: 4 | C13: Chinedu Chile | D13: =IF(C13="","",IFERROR(INDEX(CALCULATIONS!$C$2:$C$22,MATCH(C13,CALCULATIONS!$A$2:$A$22,0)),"")) -> 11 | E13: =IF(C13="","",IF(C13=$C$5,TEXT(IFERROR(INDEX(CALCULATIONS!$D$2:$D$22,MATCH(C13,CALCULATIONS!$A$2:$A$22,0)),0)*SETTINGS!$C$18,"0")&" (×"&SETTINGS!$C$18&")",TEXT(IFERROR(INDEX(CALCULATIONS!$D$2:$D$22,MATCH(C13,CALCULATIONS!$A$2:$A$22,0)),0),"0"))) -> 5
B14: 5 | C14: David Wu | D14: =IF(C14="","",IFERROR(INDEX(CALCULATIONS!$C$2:$C$22,MATCH(C14,CALCULATIONS!$A$2:$A$22,0)),"")) -> 10.5 | E14: =IF(C14="","",IF(C14=$C$5,TEXT(IFERROR(INDEX(CALCULATIONS!$D$2:$D$22,MATCH(C14,CALCULATIONS!$A$2:$A$22,0)),0)*SETTINGS!$C$18,"0")&" (×"&SETTINGS!$C$18&")",TEXT(IFERROR(INDEX(CALCULATIONS!$D$2:$D$22,MATCH(C14,CALCULATIONS!$A$2:$A$22,0)),0),"0"))) -> 5
B16: TEAM SUMMARY
B17: Team Value | C17: =SUM(D10:D14) -> 50
B18: Budget Left | C18: =50-C17 -> 0
B19: GW Score | C19: =IF($C$20="VALID TEAM",SUMPRODUCT(SUMIF(CALCULATIONS!$A$2:$A$22,C10:C14,CALCULATIONS!$D$2:$D$22))+SUMIF(CALCULATIONS!$A$2:$A$22,C5,CALCULATIONS!$D$2:$D$22)*(SETTINGS!$C$18-1),0) -> 31
B20: Team Status | C20: =IF(COUNTBLANK(C10:C14)>0,"LESS THAN 5 PLAYERS",IF(SUM(D10:D14)>50,"OVER BUDGET",IF(C5="","NO CAPTAIN",IF(COUNTIF(C10:C14,C5)=0,"CAPTAIN NOT IN SQUAD",IF(SUMPRODUCT(COUNTIF(C10:C14,C10:C14))>5,"DUPLICATE PLAYER","VALID TEAM"))))) -> VALID TEAM
B22: INPUT CELLS ARE GOLD. Only the captain cell (C5) and the 5 player cells (C10:C14) should be edited. Do NOT type 'CAPTAIN' anywhere in the squad.

Sheet Azlan Husain
B1: AZLAN HUSAIN'S TEAM
B2: ← Back to PICK YOUR TEAM
B4: PICK YOUR CAPTAIN (scores 2× points)
C5: Emily Warburton
B6: Step 1: Pick 5 players. Step 2: Choose your captain in the GOLD box above.
B8: SQUAD
B9: Slot | C9: Player | D9: Price | E9: Points
B10: 1 | C10: Emily Warburton | D10: =IF(C10="","",IFERROR(INDEX(CALCULATIONS!$C$2:$C$22,MATCH(C10,CALCULATIONS!$A$2:$A$22,0)),"")) -> 11 | E10: =IF(C10="","",IF(C10=$C$5,TEXT(IFERROR(INDEX(CALCULATIONS!$D$2:$D$22,MATCH(C10,CALCULATIONS!$A$2:$A$22,0)),0)*SETTINGS!$C$18,"0")&" (×"&SETTINGS!$C$18&")",TEXT(IFERROR(INDEX(CALCULATIONS!$D$2:$D$22,MATCH(C10,CALCULATIONS!$A$2:$A$22,0)),0),"0"))) -> 0 (×2)
B11: 2 | C11: Chinedu Chile | D11: =IF(C11="","",IFERROR(INDEX(CALCULATIONS!$C$2:$C$22,MATCH(C11,CALCULATIONS!$A$2:$A$22,0)),"")) -> 11 | E11: =IF(C11="","",IF(C11=$C$5,TEXT(IFERROR(INDEX(CALCULATIONS!$D$2:$D$22,MATCH(C11,CALCULATIONS!$A$2:$A$22,0)),0)*SETTINGS!$C$18,"0")&" (×"&SETTINGS!$C$18&")",TEXT(IFERROR(INDEX(CALCULATIONS!$D$2:$D$22,MATCH(C11,CALCULATIONS!$A$2:$A$22,0)),0),"0"))) -> 5
B12: 3 | C12: Joe Paige | D12: =IF(C12="","",IFERROR(INDEX(CALCULATIONS!$C$2:$C$22,MATCH(C12,CALCULATIONS!$A$2:$A$22,0)),"")) -> 10.5 | E12: =IF(C12="","",IF(C12=$C$5,TEXT(IFERROR(INDEX(CALCULATIONS!$D$2:$D$22,MATCH(C12,CALCULATIONS!$A$2:$A$22,0)),0)*SETTINGS!$C$18,"0")&" (×"&SETTINGS!$C$18&")",TEXT(IFERROR(INDEX(CALCULATIONS!$D$2:$D$22,MATCH(C12,CALCULATIONS!$A$2:$A$22,0)),0),"0"))) -> 8
B13: 4 | C13: Alfie Foley | D13: =IF(C13="","",IFERROR(INDEX(CALCULATIONS!$C$2:$C$22,MATCH(C13,CALCULATIONS!$A$2:$A$22,0)),"")) -> 7.5 | E13: =IF(C13="","",IF(C13=$C$5,TEXT(IFERROR(INDEX(CALCULATIONS!$D$2:$D$22,MATCH(C13,CALCULATIONS!$A$2:$A$22,0)),0)*SETTINGS!$C$18,"0")&" (×"&SETTINGS!$C$18&")",TEXT(IFERROR(INDEX(CALCULATIONS!$D$2:$D$22,MATCH(C13,CALCULATIONS!$A$2:$A$22,0)),0),"0"))) -> 3
B14: 5 | C14: Edwin Mayers | D14: =IF(C14="","",IFERROR(INDEX(CALCULATIONS!$C$2:$C$22,MATCH(C14,CALCULATIONS!$A$2:$A$22,0)),"")) -> 9 | E14: =IF(C14="","",IF(C14=$C$5,TEXT(IFERROR(INDEX(CALCULATIONS!$D$2:$D$22,MATCH(C14,CALCULATIONS!$A$2:$A$22,0)),0)*SETTINGS!$C$18,"0")&" (×"&SETTINGS!$C$18&")",TEXT(IFERROR(INDEX(CALCULATIONS!$D$2:$D$22,MATCH(C14,CALCULATIONS!$A$2:$A$22,0)),0),"0"))) -> 4
B16: TEAM SUMMARY
B17: Team Value | C17: =SUM(D10:D14) -> 49
B18: Budget Left | C18: =50-C17 -> 1
B19: GW Score | C19: =IF($C$20="VALID TEAM",SUMPRODUCT(SUMIF(CALCULATIONS!$A$2:$A$22,C10:C14,CALCULATIONS!$D$2:$D$22))+SUMIF(CALCULATIONS!$A$2:$A$22,C5,CALCULATIONS!$D$2:$D$22)*(SETTINGS!$C$18-1),0) -> 20
B20: Team Status | C20: =IF(COUNTBLANK(C10:C14)>0,"LESS THAN 5 PLAYERS",IF(SUM(D10:D14)>50,"OVER BUDGET",IF(C5="","NO CAPTAIN",IF(COUNTIF(C10:C14,C5)=0,"CAPTAIN NOT IN SQUAD",IF(SUMPRODUCT(COUNTIF(C10:C14,C10:C14))>5,"DUPLICATE PLAYER","VALID TEAM"))))) -> VALID TEAM
B22: INPUT CELLS ARE GOLD. Only the captain cell (C5) and the 5 player cells (C10:C14) should be edited. Do NOT type 'CAPTAIN' anywhere in the squad.

Sheet Chinedu Chile
B1: CHINEDU CHILE'S TEAM
B2: ← Back to PICK YOUR TEAM
B4: PICK YOUR CAPTAIN (scores 2× points)
C5: Chinedu Chile
B6: Step 1: Pick 5 players. Step 2: Choose your captain in the GOLD box above.
B8: SQUAD
B9: Slot | C9: Player | D9: Price | E9: Points
B10: 1 | C10: Chinedu Chile | D10: =IF(C10="","",IFERROR(INDEX(CALCULATIONS!$C$2:$C$22,MATCH(C10,CALCULATIONS!$A$2:$A$22,0)),"")) -> 11 | E10: =IF(C10="","",IF(C10=$C$5,TEXT(IFERROR(INDEX(CALCULATIONS!$D$2:$D$22,MATCH(C10,CALCULATIONS!$A$2:$A$22,0)),0)*SETTINGS!$C$18,"0")&" (×"&SETTINGS!$C$18&")",TEXT(IFERROR(INDEX(CALCULATIONS!$D$2:$D$22,MATCH(C10,CALCULATIONS!$A$2:$A$22,0)),0),"0"))) -> 10 (×2)
B11: 2 | C11: Alexa Amesimeku | D11: =IF(C11="","",IFERROR(INDEX(CALCULATIONS!$C$2:$C$22,MATCH(C11,CALCULATIONS!$A$2:$A$22,0)),"")) -> 9.5 | E11: =IF(C11="","",IF(C11=$C$5,TEXT(IFERROR(INDEX(CALCULATIONS!$D$2:$D$22,MATCH(C11,CALCULATIONS!$A$2:$A$22,0)),0)*SETTINGS!$C$18,"0")&" (×"&SETTINGS!$C$18&")",TEXT(IFERROR(INDEX(CALCULATIONS!$D$2:$D$22,MATCH(C11,CALCULATIONS!$A$2:$A$22,0)),0),"0"))) -> 7
B12: 3 | C12: David Wu | D12: =IF(C12="","",IFERROR(INDEX(CALCULATIONS!$C$2:$C$22,MATCH(C12,CALCULATIONS!$A$2:$A$22,0)),"")) -> 10.5 | E12: =IF(C12="","",IF(C12=$C$5,TEXT(IFERROR(INDEX(CALCULATIONS!$D$2:$D$22,MATCH(C12,CALCULATIONS!$A$2:$A$22,0)),0)*SETTINGS!$C$18,"0")&" (×"&SETTINGS!$C$18&")",TEXT(IFERROR(INDEX(CALCULATIONS!$D$2:$D$22,MATCH(C12,CALCULATIONS!$A$2:$A$22,0)),0),"0"))) -> 5
B13: 4 | C13: Edwin Mayers | D13: =IF(C13="","",IFERROR(INDEX(CALCULATIONS!$C$2:$C$22,MATCH(C13,CALCULATIONS!$A$2:$A$22,0)),"")) -> 9 | E13: =IF(C13="","",IF(C13=$C$5,TEXT(IFERROR(INDEX(CALCULATIONS!$D$2:$D$22,MATCH(C13,CALCULATIONS!$A$2:$A$22,0)),0)*SETTINGS!$C$18,"0")&" (×"&SETTINGS!$C$18&")",TEXT(IFERROR(INDEX(CALCULATIONS!$D$2:$D$22,MATCH(C13,CALCULATIONS!$A$2:$A$22,0)),0),"0"))) -> 4
B14: 5 | C14: Azlan Husain | D14: =IF(C14="","",IFERROR(INDEX(CALCULATIONS!$C$2:$C$22,MATCH(C14,CALCULATIONS!$A$2:$A$22,0)),"")) -> 10 | E14: =IF(C14="","",IF(C14=$C$5,TEXT(IFERROR(INDEX(CALCULATIONS!$D$2:$D$22,MATCH(C14,CALCULATIONS!$A$2:$A$22,0)),0)*SETTINGS!$C$18,"0")&" (×"&SETTINGS!$C$18&")",TEXT(IFERROR(INDEX(CALCULATIONS!$D$2:$D$22,MATCH(C14,CALCULATIONS!$A$2:$A$22,0)),0),"0"))) -> 5
B16: TEAM SUMMARY
B17: Team Value | C17: =SUM(D10:D14) -> 50
B18: Budget Left | C18: =50-C17 -> 0
