Workbook

Sheet HOME
B1: YEAR 11 FANTASY LEAGUE
B2: GAMEWEEK 1 - Biology
B4: DEADLINE: 27/09/26 - 19:00 • GAMEWEEK 1 • Biology
B5: TEST DATE: 28/09/26
B7: CURRENT GAMEWEEK: | C7: 1
B9: HOW TO PLAY
B10: 1. Go to PICK YOUR TEAM and click your name.
B11: 2. Pick 5 players from the dropdowns (each shows the price).
B12: 3. Pick 1 captain using the GOLD CAPTAIN BOX at the top.
B13: 4. Stay under the £50m budget.
B14: 5. Enter your own test % on TEST RESULTS after each test.
B17: HOW POINTS WORK
B18: 95–100% | D18: 10 points
B19: 90–94% | D19: 9 points
B20: 85–89% | D20: 8 points
B21: 80–84% | D21: 7 points
B22: 75–79% | D22: 6 points
B23: 70–74% | D23: 5 points
B24: 65–69% | D24: 4 points
B25: 60–64% | D25: 3 points
B26: Below 60% | D26: 0 points
B29: HOW PRICES WORK
B30: Prices move based on FORM — how each player performs compared to their OWN previous test. Consistent players don't move.
B32: Improved vs last test | E32: +£0.1m
B33: Same as last test | E33: No change
B34: Declined vs last test | E34: -£0.1m
B35: First gameweek | E35: No change
B36: Did not take test | E36: No change
B38: Prices stay between £7.0m and £13.0m. Small changes each week but add up over the season.

Sheet PICK YOUR TEAM
B1: PICK YOUR TEAM
B2: Click your name to jump to your team sheet.
B4: Manager | C4: Status
B5: Alexa Amesimeku | C5: =CALCULATIONS!U2 -> LESS THAN 5 PLAYERS
B6: Alfie Foley | C6: =CALCULATIONS!U3 -> VALID TEAM
B7: Alyza Rai | C7: =CALCULATIONS!U4 -> LESS THAN 5 PLAYERS
B8: Ava Swinfen | C8: =CALCULATIONS!U5 -> VALID TEAM
B9: Azlan Husain | C9: =CALCULATIONS!U6 -> VALID TEAM
B10: Chinedu Chile | C10: =CALCULATIONS!U7 -> VALID TEAM
B11: Daniel Liu | C11: =CALCULATIONS!U8 -> LESS THAN 5 PLAYERS
B12: David Wu | C12: =CALCULATIONS!U9 -> LESS THAN 5 PLAYERS
B13: Edwin Mayers | C13: =CALCULATIONS!U10 -> VALID TEAM
B14: Emily Warburton | C14: =CALCULATIONS!U11 -> LESS THAN 5 PLAYERS
B15: Esme Beston | C15: =CALCULATIONS!U12 -> LESS THAN 5 PLAYERS
B16: Iona Smith | C16: =CALCULATIONS!U13 -> LESS THAN 5 PLAYERS
... B25: Xander Meijer | C25: =CALCULATIONS!U22 -> LESS THAN 5 PLAYERS

Sheet TEST RESULTS
B1: TEST RESULTS
B2: GAMEWEEK 1 • Test on TBC
B4: Student | C4: Test % — type 90, not 90%
B5: Alexa Amesimeku
B6: Alfie Foley
B7: Alyza Rai
B8: Ava Swinfen
B9: Azlan Husain
B10: Chinedu Chile
B11: Daniel Liu
B12: David Wu
B13: Edwin Mayers
B14: Emily Warburton
B15: Esme Beston
B16: Iona Smith
... B28: Enter a whole number between 0 and 100. Do NOT type the % sign — just the number. Example: 90

Sheet PLAYER MARKET
B1: PLAYER MARKET
B2: Prices • This week's change • Ownership
B4: Player | C4: Price | D4: Change | E4: Ownership %
B5: =CALCULATIONS!A2 -> Lia Li | C5: =CALCULATIONS!C2 -> 13 | D5: =CALCULATIONS!F2 -> 0 | E5: =COUNTIF(CALCULATIONS!$L$2:$P$22,CALCULATIONS!W2)/COUNTA(CALCULATIONS!$K$2:$K$22) -> 0.14285714
B6: =CALCULATIONS!A3 -> Sophie Barker | C6: =CALCULATIONS!C3 -> 13 | D6: =CALCULATIONS!F3 -> 0 | E6: =COUNTIF(CALCULATIONS!$L$2:$P$22,CALCULATIONS!W3)/COUNTA(CALCULATIONS!$K$2:$K$22) -> 0.095238095
B7: =CALCULATIONS!A4 -> Chinedu Chile | C7: =CALCULATIONS!C4 -> 11 | D7: =CALCULATIONS!F4 -> 0 | E7: =COUNTIF(CALCULATIONS!$L$2:$P$22,CALCULATIONS!W4)/COUNTA(CALCULATIONS!$K$2:$K$22) -> 0.095238095
B8: =CALCULATIONS!A5 -> Emily Warburton | C8: =CALCULATIONS!C5 -> 11 | D8: =CALCULATIONS!F5 -> 0 | E8: =COUNTIF(CALCULATIONS!$L$2:$P$22,CALCULATIONS!W5)/COUNTA(CALCULATIONS!$K$2:$K$22) -> 0.047619048
B9: =CALCULATIONS!A6 -> Alyza Rai | C9: =CALCULATIONS!C6 -> 10.5 | D9: =CALCULATIONS!F6 -> 0 | E9: =COUNTIF(CALCULATIONS!$L$2:$P$22,CALCULATIONS!W6)/COUNTA(CALCULATIONS!$K$2:$K$22) -> 0.047619048
B10: =CALCULATIONS!A7 -> David Wu | C10: =CALCULATIONS!C7 -> 10.5 | D10: =CALCULATIONS!F7 -> 0 | E10: =COUNTIF(CALCULATIONS!$L$2:$P$22,CALCULATIONS!W7)/COUNTA(CALCULATIONS!$K$2:$K$22) -> 0.19047619
B11: =CALCULATIONS!A8 -> Joe Paige | C11: =CALCULATIONS!C8 -> 10.5 | D11: =CALCULATIONS!F8 -> 0 | E11: =COUNTIF(CALCULATIONS!$L$2:$P$22,CALCULATIONS!W8)/COUNTA(CALCULATIONS!$K$2:$K$22) -> 0.095238095
B12: =CALCULATIONS!A9 -> Azlan Husain | C12: =CALCULATIONS!C9 -> 10 | D12: =CALCULATIONS!F9 -> 0 | E12: =COUNTIF(CALCULATIONS!$L$2:$P$22,CALCULATIONS!W9)/COUNTA(CALCULATIONS!$K$2:$K$22) -> 0.047619048
B13: =CALCULATIONS!A10 -> Nina De Saram | C13: =CALCULATIONS!C10 -> 10 | D13: =CALCULATIONS!F10 -> 0 | E13: =COUNTIF(CALCULATIONS!$L$2:$P$22,CALCULATIONS!W10)/COUNTA(CALCULATIONS!$K$2:$K$22) -> 0
B14: =CALCULATIONS!A11 -> Alexa Amesimeku | C14: =CALCULATIONS!C11 -> 9.5 | D14: =CALCULATIONS!F11 -> 0 | E14: =COUNTIF(CALCULATIONS!$L$2:$P$22,CALCULATIONS!W11)/COUNTA(CALCULATIONS!$K$2:$K$22) -> 0.047619048
B15: =CALCULATIONS!A12 -> Daniel Liu | C15: =CALCULATIONS!C12 -> 9.5 | D15: =CALCULATIONS!F12 -> 0 | E15: =COUNTIF(CALCULATIONS!$L$2:$P$22,CALCULATIONS!W12)/COUNTA(CALCULATIONS!$K$2:$K$22) -> 0.047619048
B16: =CALCULATIONS!A13 -> Rebecca Seymour | C16: =CALCULATIONS!C13 -> 9.5 | D16: =CALCULATIONS!F13 -> 0 | E16: =COUNTIF(CALCULATIONS!$L$2:$P$22,CALCULATIONS!W13)/COUNTA(CALCULATIONS!$K$2:$K$22) -> 0
... B25: =CALCULATIONS!A22 -> Xander Meijer | C25: =CALCULATIONS!C22 -> 7 | D25: =CALCULATIONS!F22 -> 0 | E25: =COUNTIF(CALCULATIONS!$L$2:$P$22,CALCULATIONS!W22)/COUNTA(CALCULATIONS!$K$2:$K$22) -> 0.047619048
B28: PRICE RULES Prices move ±£0.1m based on form vs each player's previous test. Minimum £7.0m • Maximum £13.0m

Sheet 2. Overall Leaderboard
B1: OVERALL LEADERBOARD
B2: All gameweeks combined • Sorted by points (shared rank on ties)
B3: =IF(MAX($D$6:$D$26)=0,"🏆 OVERALL LEADER: No results yet","🏆 OVERALL LEADER: "&INDEX($C$6:$C$26,MATCH(MAX($D$6:$D$26),$D$6:$D$26,0))&" — "&MAX($D$6:$D$26)&" pts") -> 🏆 OVERALL LEADER: No results yet
B5: Rank | C5: Manager | D5: Overall Points
B6: {=_xlfn.LET(_xlpm.m,CALCULATIONS!$K$2:$K$22,_xlpm.pts,SUMIF('1. Raw Results'!$C$2:$C$1000,_xlpm.m,'1. Raw Results'!$D$2:$D$1000),_xlpm.N,ROWS(_xlpm.pts),_xlpm.rnk,MMULT(--(TRANSPOSE(_xlpm.pts)>_xlpm.pts),_xlfn.SEQUENCE(_xlpm.N,,1,0))+1,_xlfn.SORTBY(_xlfn.HSTACK(_xlpm.rnk,_xlpm.m,_xlpm.pts),_xlpm.pts,-1,_xlpm.m,1))} -> 1 | C6: Alexa Amesimeku | D6: 0
B7: 1 | C7: Alfie Foley | D7: 0
B8: 1 | C8: Alyza Rai | D8: 0
B9: 1 | C9: Ava Swinfen | D9: 0
B10: 1 | C10: Azlan Husain | D10: 0
B11: 1 | C11: Chinedu Chile | D11: 0
B12: 1 | C12: Daniel Liu | D12: 0
B13: 1 | C13: David Wu | D13: 0
B14: 1 | C14: Edwin Mayers | D14: 0
B15: 1 | C15: Emily Warburton | D15: 0
B16: 1 | C16: Esme Beston | D16: 0
B17: 1 | C17: Iona Smith | D17: 0
B18: 1 | C18: Joe Paige | D18: 0
... B26: 1 | C26: Xander Meijer | D26: 0

Sheet 3. GW Leaderboard
B1: GAMEWEEK LEADERBOARD
B2: This gameweek only • Sorted by points (shared rank on ties)
B3: CURRENT GAMEWEEK: | C3: 1
B5: =IF(MAX($D$8:$D$28)=0,"🏆 GW"&$C$3&" WINNER: No results yet","🏆 GW"&$C$3&" WINNER: "&INDEX($C$8:$C$28,MATCH(MAX($D$8:$D$28),$D$8:$D$28,0))&" — "&MAX($D$8:$D$28)&" pts") -> 🏆 GW1 WINNER: No results yet
B7: Rank | C7: Manager | D7: GW Points
B8: {=_xlfn.LET(_xlpm.m,CALCULATIONS!$K$2:$K$22,_xlpm.pts,SUMIFS('1. Raw Results'!$D$2:$D$1000,'1. Raw Results'!$B$2:$B$1000,"GW"&$C$3,'1. Raw Results'!$C$2:$C$1000,_xlpm.m),_xlpm.N,ROWS(_xlpm.pts),_xlpm.rnk,MMULT(--(TRANSPOSE(_xlpm.pts)>_xlpm.pts),_xlfn.SEQUENCE(_xlpm.N,,1,0))+1,_xlfn.SORTBY(_xlfn.HSTACK(_xlpm.rnk,_xlpm.m,_xlpm.pts),_xlpm.pts,-1,_xlpm.m,1))} -> 1 | C8: Alexa Amesimeku | D8: 0
B9: 1 | C9: Alfie Foley | D9: 0
B10: 1 | C10: Alyza Rai | D10: 0
B11: 1 | C11: Ava Swinfen | D11: 0
B12: 1 | C12: Azlan Husain | D12: 0
B13: 1 | C13: Chinedu Chile | D13: 0
B14: 1 | C14: Daniel Liu | D14: 0
B15: 1 | C15: David Wu | D15: 0
B16: 1 | C16: Edwin Mayers | D16: 0
B17: 1 | C17: Emily Warburton | D17: 0
B18: 1 | C18: Esme Beston | D18: 0
B19: 1 | C19: Iona Smith | D19: 0
B20: 1 | C20: Joe Paige | D20: 0
... B28: 1 | C28: Xander Meijer | D28: 0

Sheet RULES
B1: RULES & HOW TO PLAY
B4: BUDGET | C4: £50.0m per manager. Pick exactly 5 players. Squad value cannot exceed £50.0m.
B6: CAPTAIN | C6: Choose 1 captain using the GOLD dropdown at the top of your team sheet. The captain scores 2× their normal Gameweek points.
B8: DEADLINE | C8: Set manually on HOME each gameweek.
B10: TEST DATE | C10: Set manually on HOME each gameweek.
B12: RESULT ENTRY | C12: After the test, each student enters only their own percentage on TEST RESULTS.
B14: POINTS | C14: 95–100% = 10 • 90–94% = 9 • 85–89% = 8 • 80–84% = 7 • 75–79% = 6 • 70–74% = 5 • 65–69% = 4 • 60–64% = 3 • Below 60% = 0.
B16: PRICE CHANGES | C16: Prices move based on FORM. If a student improves vs their last test → +£0.1m. If they decline → -£0.1m. Same → no change. First week or blank test → no change.
B18: PRICE LIMITS | C18: Minimum £7.0m. Maximum £13.0m.
B20: TRANSFERS | C20: After every Gameweek: unlimited transfers, free transfers, no penalties, captains can change.
B22: TRANSFER DEADLINE | C22: The transfer window closes at the next Gameweek deadline.
B24: GOLDEN RULE | C24: Users only need to pick 5 players, pick a captain and enter their own test result. Excel handles the rest.

Sheet 1. Raw Results
B1: Gameweek | C1: Manager | D1: Points
B2: GW1 | C2: Alexa Amesimeku | D2: =CALCULATIONS!T2 -> 0
B3: GW1 | C3: Alfie Foley | D3: =CALCULATIONS!T3 -> 0
B4: GW1 | C4: Alyza Rai | D4: =CALCULATIONS!T4 -> 0
B5: GW1 | C5: Ava Swinfen | D5: =CALCULATIONS!T5 -> 0
B6: GW1 | C6: Azlan Husain | D6: =CALCULATIONS!T6 -> 0
B7: GW1 | C7: Chinedu Chile | D7: =CALCULATIONS!T7 -> 0
B8: GW1 | C8: Daniel Liu | D8: =CALCULATIONS!T8 -> 0
B9: GW1 | C9: David Wu | D9: =CALCULATIONS!T9 -> 0
B10: GW1 | C10: Edwin Mayers | D10: =CALCULATIONS!T10 -> 0
B11: GW1 | C11: Emily Warburton | D11: =CALCULATIONS!T11 -> 0
B12: GW1 | C12: Esme Beston | D12: =CALCULATIONS!T12 -> 0
B13: GW1 | C13: Iona Smith | D13: =CALCULATIONS!T13 -> 0
... B22: GW1 | C22: Xander Meijer | D22: =CALCULATIONS!T22 -> 0

Sheet CALCULATIONS
A1: Player | B1: Base Price | C1: Current Price | D1: Points This Week | E1: Last Week Pts | F1: Δ | K1: Manager | L1: P1 | M1: P2 | N1: P3 | O1: P4 | P1: P5 | Q1: Captain | R1: Team Value | S1: Budget Left | T1: GW Score | U1: Status | W1: Dropdown
A2: Lia Li | B2: 13 | C2: =MIN(13,MAX(7,B2)) -> 13 | D2: =IFERROR(IF(INDEX('TEST RESULTS'!$C$5:$C$25,MATCH(A2,'TEST RESULTS'!$B$5:$B$25,0))="",0,IF(INDEX('TEST RESULTS'!$C$5:$C$25,MATCH(A2,'TEST RESULTS'!$B$5:$B$25,0))>=95,10,IF(INDEX('TEST RESULTS'!$C$5:$C$25,MATCH(A2,'TEST RESULTS'!$B$5:$B$25,0))>=90,9,IF(INDEX('TEST RESULTS'!$C$5:$C$25,MATCH(A2,'TEST RESULTS'!$B$5:$B$25,0))>=85,8,IF(INDEX('TEST RESULTS'!$C$5:$C$25,MATCH(A2,'TEST RESULTS'!$B$5:$B$25,0))>=80,7,IF(INDEX('TEST RESULTS'!$C$5:$C$25,MATCH(A2,'TEST RESULTS'!$B$5:$B$25,0))>=75,6,IF(INDEX('TEST RESULTS'!$C$5:$C$25,MATCH(A2,'TEST RESULTS'!$B$5:$B$25,0))>=70,5,IF(INDEX('TEST RESULTS'!$C$5:$C$25,MATCH(A2,'TEST RESULTS'!$B$5:$B$25,0))>=65,4,IF(INDEX('TEST RESULTS'!$C$5:$C$25,MATCH(A2,'TEST RESULTS'!$B$5:$B$25,0))>=60,3,0))))))))),0) -> 0 | F2: =IF(INDEX('TEST RESULTS'!$C$5:$C$25,MATCH(A2,'TEST RESULTS'!$B$5:$B$25,0))="",0,IF(E2="",0,IF(D2>E2,0.1,IF(D2<E2,-0.1,0)))) -> 0 | K2: Alexa Amesimeku | L2: ='Alexa Amesimeku'!C10 -> 0 | M2: ='Alexa Amesimeku'!C11 -> 0 | N2: ='Alexa Amesimeku'!C12 -> 0 | O2: ='Alexa Amesimeku'!C13 -> 0 | P2: ='Alexa Amesimeku'!C14 -> 0 | Q2: ='Alexa Amesimeku'!C5 -> 0 | R2: ='Alexa Amesimeku'!C17 -> 0 | S2: ='Alexa Amesimeku'!C18 -> 50 | T2: ='Alexa Amesimeku'!C19 -> 0 | U2: ='Alexa Amesimeku'!C20 -> LESS THAN 5 PLAYERS | W2: =A2&" — £"&TEXT(B2,"0.0")&"m" -> Lia Li — £13.0m
A3: Sophie Barker | B3: 13 | C3: =MIN(13,MAX(7,B3)) -> 13 | D3: =IFERROR(IF(INDEX('TEST RESULTS'!$C$5:$C$25,MATCH(A3,'TEST RESULTS'!$B$5:$B$25,0))="",0,IF(INDEX('TEST RESULTS'!$C$5:$C$25,MATCH(A3,'TEST RESULTS'!$B$5:$B$25,0))>=95,10,IF(INDEX('TEST RESULTS'!$C$5:$C$25,MATCH(A3,'TEST RESULTS'!$B$5:$B$25,0))>=90,9,IF(INDEX('TEST RESULTS'!$C$5:$C$25,MATCH(A3,'TEST RESULTS'!$B$5:$B$25,0))>=85,8,IF(INDEX('TEST RESULTS'!$C$5:$C$25,MATCH(A3,'TEST RESULTS'!$B$5:$B$25,0))>=80,7,IF(INDEX('TEST RESULTS'!$C$5:$C$25,MATCH(A3,'TEST RESULTS'!$B$5:$B$25,0))>=75,6,IF(INDEX('TEST RESULTS'!$C$5:$C$25,MATCH(A3,'TEST RESULTS'!$B$5:$B$25,0))>=70,5,IF(INDEX('TEST RESULTS'!$C$5:$C$25,MATCH(A3,'TEST RESULTS'!$B$5:$B$25,0))>=65,4,IF(INDEX('TEST RESULTS'!$C$5:$C$25,MATCH(A3,'TEST RESULTS'!$B$5:$B$25,0))>=60,3,0))))))))),0) -> 0 | F3: =IF(INDEX('TEST RESULTS'!$C$5:$C$25,MATCH(A3,'TEST RESULTS'!$B$5:$B$25,0))="",0,IF(E3="",0,IF(D3>E3,0.1,IF(D3<E3,-0.1,0)))) -> 0 | K3: Alfie Foley | L3: ='Alfie Foley'!C10 -> Ava Swinfen — £7.0m | M3: ='Alfie Foley'!C11 -> David Wu — £10.5m | N3: ='Alfie Foley'!C12 -> Alyza Rai — £10.5m | O3: ='Alfie Foley'!C13 -> Sophie Barker — £13.0m | P3: ='Alfie Foley'!C14 -> Edwin Mayers — £9.0m | Q3: ='Alfie Foley'!C5 -> Sophie Barker — £13.0m | R3: ='Alfie Foley'!C17 -> 50 | S3: ='Alfie Foley'!C18 -> 0 | T3: ='Alfie Foley'!C19 -> 0 | U3: ='Alfie Foley'!C20 -> VALID TEAM | W3: =A3&" — £"&TEXT(B3,"0.0")&"m" -> Sophie Barker — £13.0m
A4: Chinedu Chile | B4: 11 | C4: =MIN(13,MAX(7,B4)) -> 11 | D4: =IFERROR(IF(INDEX('TEST RESULTS'!$C$5:$C$25,MATCH(A4,'TEST RESULTS'!$B$5:$B$25,0))="",0,IF(INDEX('TEST RESULTS'!$C$5:$C$25,MATCH(A4,'TEST RESULTS'!$B$5:$B$25,0))>=95,10,IF(INDEX('TEST RESULTS'!$C$5:$C$25,MATCH(A4,'TEST RESULTS'!$B$5:$B$25,0))>=90,9,IF(INDEX('TEST RESULTS'!$C$5:$C$25,MATCH(A4,'TEST RESULTS'!$B$5:$B$25,0))>=85,8,IF(INDEX('TEST RESULTS'!$C$5:$C$25,MATCH(A4,'TEST RESULTS'!$B$5:$B$25,0))>=80,7,IF(INDEX('TEST RESULTS'!$C$5:$C$25,MATCH(A4,'TEST RESULTS'!$B$5:$B$25,0))>=75,6,IF(INDEX('TEST RESULTS'!$C$5:$C$25,MATCH(A4,'TEST RESULTS'!$B$5:$B$25,0))>=70,5,IF(INDEX('TEST RESULTS'!$C$5:$C$25,MATCH(A4,'TEST RESULTS'!$B$5:$B$25,0))>=65,4,IF(INDEX('TEST RESULTS'!$C$5:$C$25,MATCH(A4,'TEST RESULTS'!$B$5:$B$25,0))>=60,3,0))))))))),0) -> 0 | F4: =IF(INDEX('TEST RESULTS'!$C$5:$C$25,MATCH(A4,'TEST RESULTS'!$B$5:$B$25,0))="",0,IF(E4="",0,IF(D4>E4,0.1,IF(D4<E4,-0.1,0)))) -> 0 | K4: Alyza Rai | L4: ='Alyza Rai'!C10 -> 0 | M4: ='Alyza Rai'!C11 -> 0 | N4: ='Alyza Rai'!C12 -> 0 | O4: ='Alyza Rai'!C13 -> 0 | P4: ='Alyza Rai'!C14 -> 0 | Q4: ='Alyza Rai'!C5 -> 0 | R4: ='Alyza Rai'!C17 -> 0 | S4: ='Alyza Rai'!C18 -> 50 | T4: ='Alyza Rai'!C19 -> 0 | U4: ='Alyza Rai'!C20 -> LESS THAN 5 PLAYERS | W4: =A4&" — £"&TEXT(B4,"0.0")&"m" -> Chinedu Chile — £11.0m
A5: Emily Warburton | B5: 11 | C5: =MIN(13,MAX(7,B5)) -> 11 | D5: =IFERROR(IF(INDEX('TEST RESULTS'!$C$5:$C$25,MATCH(A5,'TEST RESULTS'!$B$5:$B$25,0))="",0,IF(INDEX('TEST RESULTS'!$C$5:$C$25,MATCH(A5,'TEST RESULTS'!$B$5:$B$25,0))>=95,10,IF(INDEX('TEST RESULTS'!$C$5:$C$25,MATCH(A5,'TEST RESULTS'!$B$5:$B$25,0))>=90,9,IF(INDEX('TEST RESULTS'!$C$5:$C$25,MATCH(A5,'TEST RESULTS'!$B$5:$B$25,0))>=85,8,IF(INDEX('TEST RESULTS'!$C$5:$C$25,MATCH(A5,'TEST RESULTS'!$B$5:$B$25,0))>=80,7,IF(INDEX('TEST RESULTS'!$C$5:$C$25,MATCH(A5,'TEST RESULTS'!$B$5:$B$25,0))>=75,6,IF(INDEX('TEST RESULTS'!$C$5:$C$25,MATCH(A5,'TEST RESULTS'!$B$5:$B$25,0))>=70,5,IF(INDEX('TEST RESULTS'!$C$5:$C$25,MATCH(A5,'TEST RESULTS'!$B$5:$B$25,0))>=65,4,IF(INDEX('TEST RESULTS'!$C$5:$C$25,MATCH(A5,'TEST RESULTS'!$B$5:$B$25,0))>=60,3,0))))))))),0) -> 0 | F5: =IF(INDEX('TEST RESULTS'!$C$5:$C$25,MATCH(A5,'TEST RESULTS'!$B$5:$B$25,0))="",0,IF(E5="",0,IF(D5>E5,0.1,IF(D5<E5,-0.1,0)))) -> 0 | K5: Ava Swinfen | L5: ='Ava Swinfen'!C10 -> Rory Bowman — £7.0m | M5: ='Ava Swinfen'!C11 -> Melody Zhaeentan — £8.5m | N5: ='Ava Swinfen'!C12 -> Lia Li — £13.0m | O5: ='Ava Swinfen'!C13 -> Chinedu Chile — £11.0m | P5: ='Ava Swinfen'!C14 -> Daniel Liu — £9.5m | Q5: ='Ava Swinfen'!C5 -> Lia Li — £13.0m | R5: ='Ava Swinfen'!C17 -> 49 | S5: ='Ava Swinfen'!C18 -> 1 | T5: ='Ava Swinfen'!C19 -> 0 | U5: ='Ava Swinfen'!C20 -> VALID TEAM | W5: =A5&" — £"&TEXT(B5,"0.0")&"m" -> Emily Warburton — £11.0m
A6: Alyza Rai | B6: 10.5 | C6: =MIN(13,MAX(7,B6)) -> 10.5 | D6: =IFERROR(IF(INDEX('TEST RESULTS'!$C$5:$C$25,MATCH(A6,'TEST RESULTS'!$B$5:$B$25,0))="",0,IF(INDEX('TEST RESULTS'!$C$5:$C$25,MATCH(A6,'TEST RESULTS'!$B$5:$B$25,0))>=95,10,IF(INDEX('TEST RESULTS'!$C$5:$C$25,MATCH(A6,'TEST RESULTS'!$B$5:$B$25,0))>=90,9,IF(INDEX('TEST RESULTS'!$C$5:$C$25,MATCH(A6,'TEST RESULTS'!$B$5:$B$25,0))>=85,8,IF(INDEX('TEST RESULTS'!$C$5:$C$25,MATCH(A6,'TEST RESULTS'!$B$5:$B$25,0))>=80,7,IF(INDEX('TEST RESULTS'!$C$5:$C$25,MATCH(A6,'TEST RESULTS'!$B$5:$B$25,0))>=75,6,IF(INDEX('TEST RESULTS'!$C$5:$C$25,MATCH(A6,'TEST RESULTS'!$B$5:$B$25,0))>=70,5,IF(INDEX('TEST RESULTS'!$C$5:$C$25,MATCH(A6,'TEST RESULTS'!$B$5:$B$25,0))>=65,4,IF(INDEX('TEST RESULTS'!$C$5:$C$25,MATCH(A6,'TEST RESULTS'!$B$5:$B$25,0))>=60,3,0))))))))),0) -> 0 | F6: =IF(INDEX('TEST RESULTS'!$C$5:$C$25,MATCH(A6,'TEST RESULTS'!$B$5:$B$25,0))="",0,IF(E6="",0,IF(D6>E6,0.1,IF(D6<E6,-0.1,0)))) -> 0 | K6: Azlan Husain | L6: ='Azlan Husain'!C10 -> Lia Li — £13.0m | M6: ='Azlan Husain'!C11 -> David Wu — £10.5m | N6: ='Azlan Husain'!C12 -> Joe Paige — £10.5m | O6: ='Azlan Husain'!C13 -> Rory Bowman — £7.0m | P6: ='Azlan Husain'!C14 -> Edwin Mayers — £9.0m | Q6: ='Azlan Husain'!C5 -> Lia Li — £13.0m | R6: ='Azlan Husain'!C17 -> 50 | S6: ='Azlan Husain'!C18 -> 0 | T6: ='Azlan Husain'!C19 -> 0 | U6: ='Azlan Husain'!C20 -> VALID TEAM | W6: =A6&" — £"&TEXT(B6,"0.0")&"m" -> Alyza Rai — £10.5m
A7: David Wu | B7: 10.5 | C7: =MIN(13,MAX(7,B7)) -> 10.5 | D7: =IFERROR(IF(INDEX('TEST RESULTS'!$C$5:$C$25,MATCH(A7,'TEST RESULTS'!$B$5:$B$25,0))="",0,IF(INDEX('TEST RESULTS'!$C$5:$C$25,MATCH(A7,'TEST RESULTS'!$B$5:$B$25,0))>=95,10,IF(INDEX('TEST RESULTS'!$C$5:$C$25,MATCH(A7,'TEST RESULTS'!$B$5:$B$25,0))>=90,9,IF(INDEX('TEST RESULTS'!$C$5:$C$25,MATCH(A7,'TEST RESULTS'!$B$5:$B$25,0))>=85,8,IF(INDEX('TEST RESULTS'!$C$5:$C$25,MATCH(A7,'TEST RESULTS'!$B$5:$B$25,0))>=80,7,IF(INDEX('TEST RESULTS'!$C$5:$C$25,MATCH(A7,'TEST RESULTS'!$B$5:$B$25,0))>=75,6,IF(INDEX('TEST RESULTS'!$C$5:$C$25,MATCH(A7,'TEST RESULTS'!$B$5:$B$25,0))>=70,5,IF(INDEX('TEST RESULTS'!$C$5:$C$25,MATCH(A7,'TEST RESULTS'!$B$5:$B$25,0))>=65,4,IF(INDEX('TEST RESULTS'!$C$5:$C$25,MATCH(A7,'TEST RESULTS'!$B$5:$B$25,0))>=60,3,0))))))))),0) -> 0 | F7: =IF(INDEX('TEST RESULTS'!$C$5:$C$25,MATCH(A7,'TEST RESULTS'!$B$5:$B$25,0))="",0,IF(E7="",0,IF(D7>E7,0.1,IF(D7<E7,-0.1,0)))) -> 0 | K7: Chinedu Chile | L7: ='Chinedu Chile'!C10 -> Chinedu Chile — £11.0m | M7: ='Chinedu Chile'!C11 -> Alexa Amesimeku — £9.5m | N7: ='Chinedu Chile'!C12 -> David Wu — £10.5m | O7: ='Chinedu Chile'!C13 -> Edwin Mayers — £9.0m | P7: ='Chinedu Chile'!C14 -> Azlan Husain — £10.0m | Q7: ='Chinedu Chile'!C5 -> Chinedu Chile — £11.0m | R7: ='Chinedu Chile'!C17 -> 50 | S7: ='Chinedu Chile'!C18 -> 0 | T7: ='Chinedu Chile'!C19 -> 0 | U7: ='Chinedu Chile'!C20 -> VALID TEAM | W7: =A7&" — £"&TEXT(B7,"0.0")&"m" -> David Wu — £10.5m
A8: Joe Paige | B8: 10.5 | C8: =MIN(13,MAX(7,B8)) -> 10.5 | D8: =IFERROR(IF(INDEX('TEST RESULTS'!$C$5:$C$25,MATCH(A8,'TEST RESULTS'!$B$5:$B$25,0))="",0,IF(INDEX('TEST RESULTS'!$C$5:$C$25,MATCH(A8,'TEST RESULTS'!$B$5:$B$25,0))>=95,10,IF(INDEX('TEST RESULTS'!$C$5:$C$25,MATCH(A8,'TEST RESULTS'!$B$5:$B$25,0))>=90,9,IF(INDEX('TEST RESULTS'!$C$5:$C$25,MATCH(A8,'TEST RESULTS'!$B$5:$B$25,0))>=85,8,IF(INDEX('TEST RESULTS'!$C$5:$C$25,MATCH(A8,'TEST RESULTS'!$B$5:$B$25,0))>=80,7,IF(INDEX('TEST RESULTS'!$C$5:$C$25,MATCH(A8,'TEST RESULTS'!$B$5:$B$25,0))>=75,6,IF(INDEX('TEST RESULTS'!$C$5:$C$25,MATCH(A8,'TEST RESULTS'!$B$5:$B$25,0))>=70,5,IF(INDEX('TEST RESULTS'!$C$5:$C$25,MATCH(A8,'TEST RESULTS'!$B$5:$B$25,0))>=65,4,IF(INDEX('TEST RESULTS'!$C$5:$C$25,MATCH(A8,'TEST RESULTS'!$B$5:$B$25,0))>=60,3,0))))))))),0) -> 0 | F8: =IF(INDEX('TEST RESULTS'!$C$5:$C$25,MATCH(A8,'TEST RESULTS'!$B$5:$B$25,0))="",0,IF(E8="",0,IF(D8>E8,0.1,IF(D8<E8,-0.1,0)))) -> 0 | K8: Daniel Liu | L8: ='Daniel Liu'!C10 -> 0 | M8: ='Daniel Liu'!C11 -> 0 | N8: ='Daniel Liu'!C12 -> 0 | O8: ='Daniel Liu'!C13 -> 0 | P8: ='Daniel Liu'!C14 -> 0 | Q8: ='Daniel Liu'!C5 -> 0 | R8: ='Daniel Liu'!C17 -> 0 | S8: ='Daniel Liu'!C18 -> 50 | T8: ='Daniel Liu'!C19 -> 0 | U8: ='Daniel Liu'!C20 -> LESS THAN 5 PLAYERS | W8: =A8&" — £"&TEXT(B8,"0.0")&"m" -> Joe Paige — £10.5m
A9: Azlan Husain | B9: 10 | C9: =MIN(13,MAX(7,B9)) -> 10 | D9: =IFERROR(IF(INDEX('TEST RESULTS'!$C$5:$C$25,MATCH(A9,'TEST RESULTS'!$B$5:$B$25,0))="",0,IF(INDEX('TEST RESULTS'!$C$5:$C$25,MATCH(A9,'TEST RESULTS'!$B$5:$B$25,0))>=95,10,IF(INDEX('TEST RESULTS'!$C$5:$C$25,MATCH(A9,'TEST RESULTS'!$B$5:$B$25,0))>=90,9,IF(INDEX('TEST RESULTS'!$C$5:$C$25,MATCH(A9,'TEST RESULTS'!$B$5:$B$25,0))>=85,8,IF(INDEX('TEST RESULTS'!$C$5:$C$25,MATCH(A9,'TEST RESULTS'!$B$5:$B$25,0))>=80,7,IF(INDEX('TEST RESULTS'!$C$5:$C$25,MATCH(A9,'TEST RESULTS'!$B$5:$B$25,0))>=75,6,IF(INDEX('TEST RESULTS'!$C$5:$C$25,MATCH(A9,'TEST RESULTS'!$B$5:$B$25,0))>=70,5,IF(INDEX('TEST RESULTS'!$C$5:$C$25,MATCH(A9,'TEST RESULTS'!$B$5:$B$25,0))>=65,4,IF(INDEX('TEST RESULTS'!$C$5:$C$25,MATCH(A9,'TEST RESULTS'!$B$5:$B$25,0))>=60,3,0))))))))),0) -> 0 | F9: =IF(INDEX('TEST RESULTS'!$C$5:$C$25,MATCH(A9,'TEST RESULTS'!$B$5:$B$25,0))="",0,IF(E9="",0,IF(D9>E9,0.1,IF(D9<E9,-0.1,0)))) -> 0 | K9: David Wu | L9: ='David Wu'!C10 -> 0 | M9: ='David Wu'!C11 -> 0 | N9: ='David Wu'!C12 -> 0 | O9: ='David Wu'!C13 -> 0 | P9: ='David Wu'!C14 -> 0 | Q9: ='David Wu'!C5 -> 0 | R9: ='David Wu'!C17 -> 0 | S9: ='David Wu'!C18 -> 50 | T9: ='David Wu'!C19 -> 0 | U9: ='David Wu'!C20 -> LESS THAN 5 PLAYERS | W9: =A9&" — £"&TEXT(B9,"0.0")&"m" -> Azlan Husain — £10.0m
A10: Nina De Saram | B10: 10 | C10: =MIN(13,MAX(7,B10)) -> 10 | D10: =IFERROR(IF(INDEX('TEST RESULTS'!$C$5:$C$25,MATCH(A10,'TEST RESULTS'!$B$5:$B$25,0))="",0,IF(INDEX('TEST RESULTS'!$C$5:$C$25,MATCH(A10,'TEST RESULTS'!$B$5:$B$25,0))>=95,10,IF(INDEX('TEST RESULTS'!$C$5:$C$25,MATCH(A10,'TEST RESULTS'!$B$5:$B$25,0))>=90,9,IF(INDEX('TEST RESULTS'!$C$5:$C$25,MATCH(A10,'TEST RESULTS'!$B$5:$B$25,0))>=85,8,IF(INDEX('TEST RESULTS'!$C$5:$C$25,MATCH(A10,'TEST RESULTS'!$B$5:$B$25,0))>=80,7,IF(INDEX('TEST RESULTS'!$C$5:$C$25,MATCH(A10,'TEST RESULTS'!$B$5:$B$25,0))>=75,6,IF(INDEX('TEST RESULTS'!$C$5:$C$25,MATCH(A10,'TEST RESULTS'!$B$5:$B$25,0))>=70,5,IF(INDEX('TEST RESULTS'!$C$5:$C$25,MATCH(A10,'TEST RESULTS'!$B$5:$B$25,0))>=65,4,IF(INDEX('TEST RESULTS'!$C$5:$C$25,MATCH(A10,'TEST RESULTS'!$B$5:$B$25,0))>=60,3,0))))))))),0) -> 0 | F10: =IF(INDEX('TEST RESULTS'!$C$5:$C$25,MATCH(A10,'TEST RESULTS'!$B$5:$B$25,0))="",0,IF(E10="",0,IF(D10>E10,0.1,IF(D10<E10,-0.1,0)))) -> 0 | K10: Edwin Mayers | L10: ='Edwin Mayers'!C10 -> Sophie Barker — £13.0m | M10: ='Edwin Mayers'!C11 -> Esme Beston — £8.0m | N10: ='Edwin Mayers'!C12 -> Edwin Mayers — £9.0m | O10: ='Edwin Mayers'!C13 -> Emily Warburton — £11.0m | P10: ='Edwin Mayers'!C14 -> Ava Swinfen — £7.0m | Q10: ='Edwin Mayers'!C5 -> Emily Warburton — £11.0m | R10: ='Edwin Mayers'!C17 -> 48 | S10: ='Edwin Mayers'!C18 -> 2 | T10: ='Edwin Mayers'!C19 -> 0 | U10: ='Edwin Mayers'!C20 -> VALID TEAM | W10: =A10&" — £"&TEXT(B10,"0.0")&"m" -> Nina De Saram — £10.0m
A11: Alexa Amesimeku | B11: 9.5 | C11: =MIN(13,MAX(7,B11)) -> 9.5 | D11: =IFERROR(IF(INDEX('TEST RESULTS'!$C$5:$C$25,MATCH(A11,'TEST RESULTS'!$B$5:$B$25,0))="",0,IF(INDEX('TEST RESULTS'!$C$5:$C$25,MATCH(A11,'TEST RESULTS'!$B$5:$B$25,0))>=95,10,IF(INDEX('TEST RESULTS'!$C$5:$C$25,MATCH(A11,'TEST RESULTS'!$B$5:$B$25,0))>=90,9,IF(INDEX('TEST RESULTS'!$C$5:$C$25,MATCH(A11,'TEST RESULTS'!$B$5:$B$25,0))>=85,8,IF(INDEX('TEST RESULTS'!$C$5:$C$25,MATCH(A11,'TEST RESULTS'!$B$5:$B$25,0))>=80,7,IF(INDEX('TEST RESULTS'!$C$5:$C$25,MATCH(A11,'TEST RESULTS'!$B$5:$B$25,0))>=75,6,IF(INDEX('TEST RESULTS'!$C$5:$C$25,MATCH(A11,'TEST RESULTS'!$B$5:$B$25,0))>=70,5,IF(INDEX('TEST RESULTS'!$C$5:$C$25,MATCH(A11,'TEST RESULTS'!$B$5:$B$25,0))>=65,4,IF(INDEX('TEST RESULTS'!$C$5:$C$25,MATCH(A11,'TEST RESULTS'!$B$5:$B$25,0))>=60,3,0))))))))),0) -> 0 | F11: =IF(INDEX('TEST RESULTS'!$C$5:$C$25,MATCH(A11,'TEST RESULTS'!$B$5:$B$25,0))="",0,IF(E11="",0,IF(D11>E11,0.1,IF(D11<E11,-0.1,0)))) -> 0 | K11: Emily Warburton | L11: ='Emily Warburton'!C10 -> 0 | M11: ='Emily Warburton'!C11 -> 0 | N11: ='Emily Warburton'!C12 -> 0 | O11: ='Emily Warburton'!C13 -> 0 | P11: ='Emily Warburton'!C14 -> 0 | Q11: ='Emily Warburton'!C5 -> 0 | R11: ='Emily Warburton'!C17 -> 0 | S11: ='Emily Warburton'!C18 -> 50 | T11: ='Emily Warburton'!C19 -> 0 | U11: ='Emily Warburton'!C20 -> LESS THAN 5 PLAYERS | W11: =A11&" — £"&TEXT(B11,"0.0")&"m" -> Alexa Amesimeku — £9.5m
A12: Daniel Liu | B12: 9.5 | C12: =MIN(13,MAX(7,B12)) -> 9.5 | D12: =IFERROR(IF(INDEX('TEST RESULTS'!$C$5:$C$25,MATCH(A12,'TEST RESULTS'!$B$5:$B$25,0))="",0,IF(INDEX('TEST RESULTS'!$C$5:$C$25,MATCH(A12,'TEST RESULTS'!$B$5:$B$25,0))>=95,10,IF(INDEX('TEST RESULTS'!$C$5:$C$25,MATCH(A12,'TEST RESULTS'!$B$5:$B$25,0))>=90,9,IF(INDEX('TEST RESULTS'!$C$5:$C$25,MATCH(A12,'TEST RESULTS'!$B$5:$B$25,0))>=85,8,IF(INDEX('TEST RESULTS'!$C$5:$C$25,MATCH(A12,'TEST RESULTS'!$B$5:$B$25,0))>=80,7,IF(INDEX('TEST RESULTS'!$C$5:$C$25,MATCH(A12,'TEST RESULTS'!$B$5:$B$25,0))>=75,6,IF(INDEX('TEST RESULTS'!$C$5:$C$25,MATCH(A12,'TEST RESULTS'!$B$5:$B$25,0))>=70,5,IF(INDEX('TEST RESULTS'!$C$5:$C$25,MATCH(A12,'TEST RESULTS'!$B$5:$B$25,0))>=65,4,IF(INDEX('TEST RESULTS'!$C$5:$C$25,MATCH(A12,'TEST RESULTS'!$B$5:$B$25,0))>=60,3,0))))))))),0) -> 0 | F12: =IF(INDEX('TEST RESULTS'!$C$5:$C$25,MATCH(A12,'TEST RESULTS'!$B$5:$B$25,0))="",0,IF(E12="",0,IF(D12>E12,0.1,IF(D12<E12,-0.1,0)))) -> 0 | K12: Esme Beston | L12: ='Esme Beston'!C10 -> 0 | M12: ='Esme Beston'!C11 -> 0 | N12: ='Esme Beston'!C12 -> 0 | O12: ='Esme Beston'!C13 -> 0 | P12: ='Esme Beston'!C14 -> 0 | Q12: ='Esme Beston'!C5 -> 0 | R12: ='Esme Beston'!C17 -> 0 | S12: ='Esme Beston'!C18 -> 50 | T12: ='Esme Beston'!C19 -> 0 | U12: ='Esme Beston'!C20 -> LESS THAN 5 PLAYERS | W12: =A12&" — £"&TEXT(B12,"0.0")&"m" -> Daniel Liu — £9.5m
A13: Rebecca Seymour | B13: 9.5 | C13: =MIN(13,MAX(7,B13)) -> 9.5 | D13: =IFERROR(IF(INDEX('TEST RESULTS'!$C$5:$C$25,MATCH(A13,'TEST RESULTS'!$B$5:$B$25,0))="",0,IF(INDEX('TEST RESULTS'!$C$5:$C$25,MATCH(A13,'TEST RESULTS'!$B$5:$B$25,0))>=95,10,IF(INDEX('TEST RESULTS'!$C$5:$C$25,MATCH(A13,'TEST RESULTS'!$B$5:$B$25,0))>=90,9,IF(INDEX('TEST RESULTS'!$C$5:$C$25,MATCH(A13,'TEST RESULTS'!$B$5:$B$25,0))>=85,8,IF(INDEX('TEST RESULTS'!$C$5:$C$25,MATCH(A13,'TEST RESULTS'!$B$5:$B$25,0))>=80,7,IF(INDEX('TEST RESULTS'!$C$5:$C$25,MATCH(A13,'TEST RESULTS'!$B$5:$B$25,0))>=75,6,IF(INDEX('TEST RESULTS'!$C$5:$C$25,MATCH(A13,'TEST RESULTS'!$B$5:$B$25,0))>=70,5,IF(INDEX('TEST RESULTS'!$C$5:$C$25,MATCH(A13,'TEST RESULTS'!$B$5:$B$25,0))>=65,4,IF(INDEX('TEST RESULTS'!$C$5:$C$25,MATCH(A13,'TEST RESULTS'!$B$5:$B$25,0))>=60,3,0))))))))),0) -> 0 | F13: =IF(INDEX('TEST RESULTS'!$C$5:$C$25,MATCH(A13,'TEST RESULTS'!$B$5:$B$25,0))="",0,IF(E13="",0,IF(D13>E13,0.1,IF(D13<E13,-0.1,0)))) -> 0 | K13: Iona Smith | L13: ='Iona Smith'!C10 -> 0 | M13: ='Iona Smith'!C11 -> 0 | N13: ='Iona Smith'!C12 -> 0 | O13: ='Iona Smith'!C13 -> 0 | P13: ='Iona Smith'!C14 -> 0 | Q13: ='Iona Smith'!C5 -> 0 | R13: ='Iona Smith'!C17 -> 0 | S13: ='Iona Smith'!C18 -> 50 | T13: ='Iona Smith'!C19 -> 0 | U13: ='Iona Smith'!C20 -> LESS THAN 5 PLAYERS | W13: =A13&" — £"&TEXT(B13,"0.0")&"m" -> Rebecca Seymour — £9.5m
A14: Edwin Mayers | B14: 9 | C14: =MIN(13,MAX(7,B14)) -> 9 | D14: =IFERROR(IF(INDEX('TEST RESULTS'!$C$5:$C$25,MATCH(A14,'TEST RESULTS'!$B$5:$B$25,0))="",0,IF(INDEX('TEST RESULTS'!$C$5:$C$25,MATCH(A14,'TEST RESULTS'!$B$5:$B$25,0))>=95,10,IF(INDEX('TEST RESULTS'!$C$5:$C$25,MATCH(A14,'TEST RESULTS'!$B$5:$B$25,0))>=90,9,IF(INDEX('TEST RESULTS'!$C$5:$C$25,MATCH(A14,'TEST RESULTS'!$B$5:$B$25,0))>=85,8,IF(INDEX('TEST RESULTS'!$C$5:$C$25,MATCH(A14,'TEST RESULTS'!$B$5:$B$25,0))>=80,7,IF(INDEX('TEST RESULTS'!$C$5:$C$25,MATCH(A14,'TEST RESULTS'!$B$5:$B$25,0))>=75,6,IF(INDEX('TEST RESULTS'!$C$5:$C$25,MATCH(A14,'TEST RESULTS'!$B$5:$B$25,0))>=70,5,IF(INDEX('TEST RESULTS'!$C$5:$C$25,MATCH(A14,'TEST RESULTS'!$B$5:$B$25,0))>=65,4,IF(INDEX('TEST RESULTS'!$C$5:$C$25,MATCH(A14,'TEST RESULTS'!$B$5:$B$25,0))>=60,3,0))))))))),0) -> 0 | F14: =IF(INDEX('TEST RESULTS'!$C$5:$C$25,MATCH(A14,'TEST RESULTS'!$B$5:$B$25,0))="",0,IF(E14="",0,IF(D14>E14,0.1,IF(D14<E14,-0.1,0)))) -> 0 | K14: Joe Paige | L14: ='Joe Paige'!C10 -> 0 | M14: ='Joe Paige'!C11 -> 0 | N14: ='Joe Paige'!C12 -> 0 | O14: ='Joe Paige'!C13 -> 0 | P14: ='Joe Paige'!C14 -> 0 | Q14: ='Joe Paige'!C5 -> 0 | R14: ='Joe Paige'!C17 -> 0 | S14: ='Joe Paige'!C18 -> 50 | T14: ='Joe Paige'!C19 -> 0 | U14: ='Joe Paige'!C20 -> LESS THAN 5 PLAYERS | W14: =A14&" — £"&TEXT(B14,"0.0")&"m" -> Edwin Mayers — £9.0m
A15: Melody Zhaeentan | B15: 8.5 | C15: =MIN(13,MAX(7,B15)) -> 8.5 | D15: =IFERROR(IF(INDEX('TEST RESULTS'!$C$5:$C$25,MATCH(A15,'TEST RESULTS'!$B$5:$B$25,0))="",0,IF(INDEX('TEST RESULTS'!$C$5:$C$25,MATCH(A15,'TEST RESULTS'!$B$5:$B$25,0))>=95,10,IF(INDEX('TEST RESULTS'!$C$5:$C$25,MATCH(A15,'TEST RESULTS'!$B$5:$B$25,0))>=90,9,IF(INDEX('TEST RESULTS'!$C$5:$C$25,MATCH(A15,'TEST RESULTS'!$B$5:$B$25,0))>=85,8,IF(INDEX('TEST RESULTS'!$C$5:$C$25,MATCH(A15,'TEST RESULTS'!$B$5:$B$25,0))>=80,7,IF(INDEX('TEST RESULTS'!$C$5:$C$25,MATCH(A15,'TEST RESULTS'!$B$5:$B$25,0))>=75,6,IF(INDEX('TEST RESULTS'!$C$5:$C$25,MATCH(A15,'TEST RESULTS'!$B$5:$B$25,0))>=70,5,IF(INDEX('TEST RESULTS'!$C$5:$C$25,MATCH(A15,'TEST RESULTS'!$B$5:$B$25,0))>=65,4,IF(INDEX('TEST RESULTS'!$C$5:$C$25,MATCH(A15,'TEST RESULTS'!$B$5:$B$25,0))>=60,3,0))))))))),0) -> 0 | F15: =IF(INDEX('TEST RESULTS'!$C$5:$C$25,MATCH(A15,'TEST RESULTS'!$B$5:$B$25,0))="",0,IF(E15="",0,IF(D15>E15,0.1,IF(D15<E15,-0.1,0)))) -> 0 | K15: Lia Li | L15: ='Lia Li'!C10 -> 0 | M15: ='Lia Li'!C11 -> 0 | N15: ='Lia Li'!C12 -> 0 | O15: ='Lia Li'!C13 -> 0 | P15: ='Lia Li'!C14 -> 0 | Q15: ='Lia Li'!C5 -> 0 | R15: ='Lia Li'!C17 -> 0 | S15: ='Lia Li'!C18 -> 50 | T15: ='Lia Li'!C19 -> 0 | U15: ='Lia Li'!C20 -> LESS THAN 5 PLAYERS | W15: =A15&" — £"&TEXT(B15,"0.0")&"m" -> Melody Zhaeentan — £8.5m
A16: Esme Beston | B16: 8 | C16: =MIN(13,MAX(7,B16)) -> 8 | D16: =IFERROR(IF(INDEX('TEST RESULTS'!$C$5:$C$25,MATCH(A16,'TEST RESULTS'!$B$5:$B$25,0))="",0,IF(INDEX('TEST RESULTS'!$C$5:$C$25,MATCH(A16,'TEST RESULTS'!$B$5:$B$25,0))>=95,10,IF(INDEX('TEST RESULTS'!$C$5:$C$25,MATCH(A16,'TEST RESULTS'!$B$5:$B$25,0))>=90,9,IF(INDEX('TEST RESULTS'!$C$5:$C$25,MATCH(A16,'TEST RESULTS'!$B$5:$B$25,0))>=85,8,IF(INDEX('TEST RESULTS'!$C$5:$C$25,MATCH(A16,'TEST RESULTS'!$B$5:$B$25,0))>=80,7,IF(INDEX('TEST RESULTS'!$C$5:$C$25,MATCH(A16,'TEST RESULTS'!$B$5:$B$25,0))>=75,6,IF(INDEX('TEST RESULTS'!$C$5:$C$25,MATCH(A16,'TEST RESULTS'!$B$5:$B$25,0))>=70,5,IF(INDEX('TEST RESULTS'!$C$5:$C$25,MATCH(A16,'TEST RESULTS'!$B$5:$B$25,0))>=65,4,IF(INDEX('TEST RESULTS'!$C$5:$C$25,MATCH(A16,'TEST RESULTS'!$B$5:$B$25,0))>=60,3,0))))))))),0) -> 0 | F16: =IF(INDEX('TEST RESULTS'!$C$5:$C$25,MATCH(A16,'TEST RESULTS'!$B$5:$B$25,0))="",0,IF(E16="",0,IF(D16>E16,0.1,IF(D16<E16,-0.1,0)))) -> 0 | K16: Melody Zhaeentan | L16: ='Melody Zhaeentan'!C10 -> Lia Li — £13.0m | M16: ='Melody Zhaeentan'!C11 -> Edwin Mayers — £9.0m | N16: ='Melody Zhaeentan'!C12 -> David Wu — £10.5m | O16: ='Melody Zhaeentan'!C13 -> Joe Paige — £10.5m | P16: ='Melody Zhaeentan'!C14 -> Xander Meijer — £7.0m | Q16: ='Melody Zhaeentan'!C5 -> Lia Li — £13.0m | R16: ='Melody Zhaeentan'!C17 -> 50 | S16: ='Melody Zhaeentan'!C18 -> 0 | T16: ='Melody Zhaeentan'!C19 -> 0 | U16: ='Melody Zhaeentan'!C20 -> VALID TEAM | W16: =A16&" — £"&TEXT(B16,"0.0")&"m" -> Esme Beston — £8.0m
A17: Iona Smith | B17: 8 | C17: =MIN(13,MAX(7,B17)) -> 8 | D17: =IFERROR(IF(INDEX('TEST RESULTS'!$C$5:$C$25,MATCH(A17,'TEST RESULTS'!$B$5:$B$25,0))="",0,IF(INDEX('TEST RESULTS'!$C$5:$C$25,MATCH(A17,'TEST RESULTS'!$B$5:$B$25,0))>=95,10,IF(INDEX('TEST RESULTS'!$C$5:$C$25,MATCH(A17,'TEST RESULTS'!$B$5:$B$25,0))>=90,9,IF(INDEX('TEST RESULTS'!$C$5:$C$25,MATCH(A17,'TEST RESULTS'!$B$5:$B$25,0))>=85,8,IF(INDEX('TEST RESULTS'!$C$5:$C$25,MATCH(A17,'TEST RESULTS'!$B$5:$B$25,0))>=80,7,IF(INDEX('TEST RESULTS'!$C$5:$C$25,MATCH(A17,'TEST RESULTS'!$B$5:$B$25,0))>=75,6,IF(INDEX('TEST RESULTS'!$C$5:$C$25,MATCH(A17,'TEST RESULTS'!$B$5:$B$25,0))>=70,5,IF(INDEX('TEST RESULTS'!$C$5:$C$25,MATCH(A17,'TEST RESULTS'!$B$5:$B$25,0))>=65,4,IF(INDEX('TEST RESULTS'!$C$5:$C$25,MATCH(A17,'TEST RESULTS'!$B$5:$B$25,0))>=60,3,0))))))))),0) -> 0 | F17: =IF(INDEX('TEST RESULTS'!$C$5:$C$25,MATCH(A17,'TEST RESULTS'!$B$5:$B$25,0))="",0,IF(E17="",0,IF(D17>E17,0.1,IF(D17<E17,-0.1,0)))) -> 0 | K17: Nina De Saram | L17: ='Nina De Saram'!C10 -> 0 | M17: ='Nina De Saram'!C11 -> 0 | N17: ='Nina De Saram'!C12 -> 0 | O17: ='Nina De Saram'!C13 -> 0 | P17: ='Nina De Saram'!C14 -> 0 | Q17: ='Nina De Saram'!C5 -> 0 | R17: ='Nina De Saram'!C17 -> 0 | S17: ='Nina De Saram'!C18 -> 50 | T17: ='Nina De Saram'!C19 -> 0 | U17: ='Nina De Saram'!C20 -> LESS THAN 5 PLAYERS | W17: =A17&" — £"&TEXT(B17,"0.0")&"m" -> Iona Smith — £8.0m
A18: Oscar Day-Duran | B18: 8 | C18: =MIN(13,MAX(7,B18)) -> 8 | D18: =IFERROR(IF(INDEX('TEST RESULTS'!$C$5:$C$25,MATCH(A18,'TEST RESULTS'!$B$5:$B$25,0))="",0,IF(INDEX('TEST RESULTS'!$C$5:$C$25,MATCH(A18,'TEST RESULTS'!$B$5:$B$25,0))>=95,10,IF(INDEX('TEST RESULTS'!$C$5:$C$25,MATCH(A18,'TEST RESULTS'!$B$5:$B$25,0))>=90,9,IF(INDEX('TEST RESULTS'!$C$5:$C$25,MATCH(A18,'TEST RESULTS'!$B$5:$B$25,0))>=85,8,IF(INDEX('TEST RESULTS'!$C$5:$C$25,MATCH(A18,'TEST RESULTS'!$B$5:$B$25,0))>=80,7,IF(INDEX('TEST RESULTS'!$C$5:$C$25,MATCH(A18,'TEST RESULTS'!$B$5:$B$25,0))>=75,6,IF(INDEX('TEST RESULTS'!$C$5:$C$25,MATCH(A18,'TEST RESULTS'!$B$5:$B$25,0))>=70,5,IF(INDEX('TEST RESULTS'!$C$5:$C$25,MATCH(A18,'TEST RESULTS'!$B$5:$B$25,0))>=65,4,IF(INDEX('TEST RESULTS'!$C$5:$C$25,MATCH(A18,'TEST RESULTS'!$B$5:$B$25,0))>=60,3,0))))))))),0) -> 0 | F18: =IF(INDEX('TEST RESULTS'!$C$5:$C$25,MATCH(A18,'TEST RESULTS'!$B$5:$B$25,0))="",0,IF(E18="",0,IF(D18>E18,0.1,IF(D18<E18,-0.1,0)))) -> 0 | K18: Oscar Day-Duran | L18: ='Oscar Day-Duran'!C10 -> 0 | M18: ='Oscar Day-Duran'!C11 -> 0 | N18: ='Oscar Day-Duran'!C12 -> 0 | O18: ='Oscar Day-Duran'!C13 -> 0 | P18: ='Oscar Day-Duran'!C14 -> 0 | Q18: ='Oscar Day-Duran'!C5 -> 0 | R18: ='Oscar Day-Duran'!C17 -> 0 | S18: ='Oscar Day-Duran'!C18 -> 50 | T18: ='Oscar Day-Duran'!C19 -> 0 | U18: ='Oscar Day-Duran'!C20 -> LESS THAN 5 PLAYERS | W18: =A18&" — £"&TEXT(B18,"0.0")&"m" -> Oscar Day-Duran — £8.0m
A19: Alfie Foley | B19: 7.5 | C19: =MIN(13,MAX(7,B19)) -> 7.5 | D19: =IFERROR(IF(INDEX('TEST RESULTS'!$C$5:$C$25,MATCH(A19,'TEST RESULTS'!$B$5:$B$25,0))="",0,IF(INDEX('TEST RESULTS'!$C$5:$C$25,MATCH(A19,'TEST RESULTS'!$B$5:$B$25,0))>=95,10,IF(INDEX('TEST RESULTS'!$C$5:$C$25,MATCH(A19,'TEST RESULTS'!$B$5:$B$25,0))>=90,9,IF(INDEX('TEST RESULTS'!$C$5:$C$25,MATCH(A19,'TEST RESULTS'!$B$5:$B$25,0))>=85,8,IF(INDEX('TEST RESULTS'!$C$5:$C$25,MATCH(A19,'TEST RESULTS'!$B$5:$B$25,0))>=80,7,IF(INDEX('TEST RESULTS'!$C$5:$C$25,MATCH(A19,'TEST RESULTS'!$B$5:$B$25,0))>=75,6,IF(INDEX('TEST RESULTS'!$C$5:$C$25,MATCH(A19,'TEST RESULTS'!$B$5:$B$25,0))>=70,5,IF(INDEX('TEST RESULTS'!$C$5:$C$25,MATCH(A19,'TEST RESULTS'!$B$5:$B$25,0))>=65,4,IF(INDEX('TEST RESULTS'!$C$5:$C$25,MATCH(A19,'TEST RESULTS'!$B$5:$B$25,0))>=60,3,0))))))))),0) -> 0 | F19: =IF(INDEX('TEST RESULTS'!$C$5:$C$25,MATCH(A19,'TEST RESULTS'!$B$5:$B$25,0))="",0,IF(E19="",0,IF(D19>E19,0.1,IF(D19<E19,-0.1,0)))) -> 0 | K19: Rebecca Seymour | L19: ='Rebecca Seymour'!C10 -> 0 | M19: ='Rebecca Seymour'!C11 -> 0 | N19: ='Rebecca Seymour'!C12 -> 0 | O19: ='Rebecca Seymour'!C13 -> 0 | P19: ='Rebecca Seymour'!C14 -> 0 | Q19: ='Rebecca Seymour'!C5 -> 0 | R19: ='Rebecca Seymour'!C17 -> 0 | S19: ='Rebecca Seymour'!C18 -> 50 | T19: ='Rebecca Seymour'!C19 -> 0 | U19: ='Rebecca Seymour'!C20 -> LESS THAN 5 PLAYERS | W19: =A19&" — £"&TEXT(B19,"0.0")&"m" -> Alfie Foley — £7.5m
A20: Ava Swinfen | B20: 7 | C20: =MIN(13,MAX(7,B20)) -> 7 | D20: =IFERROR(IF(INDEX('TEST RESULTS'!$C$5:$C$25,MATCH(A20,'TEST RESULTS'!$B$5:$B$25,0))="",0,IF(INDEX('TEST RESULTS'!$C$5:$C$25,MATCH(A20,'TEST RESULTS'!$B$5:$B$25,0))>=95,10,IF(INDEX('TEST RESULTS'!$C$5:$C$25,MATCH(A20,'TEST RESULTS'!$B$5:$B$25,0))>=90,9,IF(INDEX('TEST RESULTS'!$C$5:$C$25,MATCH(A20,'TEST RESULTS'!$B$5:$B$25,0))>=85,8,IF(INDEX('TEST RESULTS'!$C$5:$C$25,MATCH(A20,'TEST RESULTS'!$B$5:$B$25,0))>=80,7,IF(INDEX('TEST RESULTS'!$C$5:$C$25,MATCH(A20,'TEST RESULTS'!$B$5:$B$25,0))>=75,6,IF(INDEX('TEST RESULTS'!$C$5:$C$25,MATCH(A20,'TEST RESULTS'!$B$5:$B$25,0))>=70,5,IF(INDEX('TEST RESULTS'!$C$5:$C$25,MATCH(A20,'TEST RESULTS'!$B$5:$B$25,0))>=65,4,IF(INDEX('TEST RESULTS'!$C$5:$C$25,MATCH(A20,'TEST RESULTS'!$B$5:$B$25,0))>=60,3,0))))))))),0) -> 0 | F20: =IF(INDEX('TEST RESULTS'!$C$5:$C$25,MATCH(A20,'TEST RESULTS'!$B$5:$B$25,0))="",0,IF(E20="",0,IF(D20>E20,0.1,IF(D20<E20,-0.1,0)))) -> 0 | K20: Rory Bowman | L20: ='Rory Bowman'!C10 -> 0 | M20: ='Rory Bowman'!C11 -> 0 | N20: ='Rory Bowman'!C12 -> 0 | O20: ='Rory Bowman'!C13 -> 0 | P20: ='Rory Bowman'!C14 -> 0 | Q20: ='Rory Bowman'!C5 -> 0 | R20: ='Rory Bowman'!C17 -> 0 | S20: ='Rory Bowman'!C18 -> 50 | T20: ='Rory Bowman'!C19 -> 0 | U20: ='Rory Bowman'!C20 -> LESS THAN 5 PLAYERS | W20: =A20&" — £"&TEXT(B20,"0.0")&"m" -> Ava Swinfen — £7.0m
A21: Rory Bowman | B21: 7 | C21: =MIN(13,MAX(7,B21)) -> 7 | D21: =IFERROR(IF(INDEX('TEST RESULTS'!$C$5:$C$25,MATCH(A21,'TEST RESULTS'!$B$5:$B$25,0))="",0,IF(INDEX('TEST RESULTS'!$C$5:$C$25,MATCH(A21,'TEST RESULTS'!$B$5:$B$25,0))>=95,10,IF(INDEX('TEST RESULTS'!$C$5:$C$25,MATCH(A21,'TEST RESULTS'!$B$5:$B$25,0))>=90,9,IF(INDEX('TEST RESULTS'!$C$5:$C$25,MATCH(A21,'TEST RESULTS'!$B$5:$B$25,0))>=85,8,IF(INDEX('TEST RESULTS'!$C$5:$C$25,MATCH(A21,'TEST RESULTS'!$B$5:$B$25,0))>=80,7,IF(INDEX('TEST RESULTS'!$C$5:$C$25,MATCH(A21,'TEST RESULTS'!$B$5:$B$25,0))>=75,6,IF(INDEX('TEST RESULTS'!$C$5:$C$25,MATCH(A21,'TEST RESULTS'!$B$5:$B$25,0))>=70,5,IF(INDEX('TEST RESULTS'!$C$5:$C$25,MATCH(A21,'TEST RESULTS'!$B$5:$B$25,0))>=65,4,IF(INDEX('TEST RESULTS'!$C$5:$C$25,MATCH(A21,'TEST RESULTS'!$B$5:$B$25,0))>=60,3,0))))))))),0) -> 0 | F21: =IF(INDEX('TEST RESULTS'!$C$5:$C$25,MATCH(A21,'TEST RESULTS'!$B$5:$B$25,0))="",0,IF(E21="",0,IF(D21>E21,0.1,IF(D21<E21,-0.1,0)))) -> 0 | K21: Sophie Barker | L21: ='Sophie Barker'!C10 -> 0 | M21: ='Sophie Barker'!C11 -> 0 | N21: ='Sophie Barker'!C12 -> 0 | O21: ='Sophie Barker'!C13 -> 0 | P21: ='Sophie Barker'!C14 -> 0 | Q21: ='Sophie Barker'!C5 -> 0 | R21: ='Sophie Barker'!C17 -> 0 | S21: ='Sophie Barker'!C18 -> 50 | T21: ='Sophie Barker'!C19 -> 0 | U21: ='Sophie Barker'!C20 -> LESS THAN 5 PLAYERS | W21: =A21&" — £"&TEXT(B21,"0.0")&"m" -> Rory Bowman — £7.0m
A22: Xander Meijer | B22: 7 | C22: =MIN(13,MAX(7,B22)) -> 7 | D22: =IFERROR(IF(INDEX('TEST RESULTS'!$C$5:$C$25,MATCH(A22,'TEST RESULTS'!$B$5:$B$25,0))="",0,IF(INDEX('TEST RESULTS'!$C$5:$C$25,MATCH(A22,'TEST RESULTS'!$B$5:$B$25,0))>=95,10,IF(INDEX('TEST RESULTS'!$C$5:$C$25,MATCH(A22,'TEST RESULTS'!$B$5:$B$25,0))>=90,9,IF(INDEX('TEST RESULTS'!$C$5:$C$25,MATCH(A22,'TEST RESULTS'!$B$5:$B$25,0))>=85,8,IF(INDEX('TEST RESULTS'!$C$5:$C$25,MATCH(A22,'TEST RESULTS'!$B$5:$B$25,0))>=80,7,IF(INDEX('TEST RESULTS'!$C$5:$C$25,MATCH(A22,'TEST RESULTS'!$B$5:$B$25,0))>=75,6,IF(INDEX('TEST RESULTS'!$C$5:$C$25,MATCH(A22,'TEST RESULTS'!$B$5:$B$25,0))>=70,5,IF(INDEX('TEST RESULTS'!$C$5:$C$25,MATCH(A22,'TEST RESULTS'!$B$5:$B$25,0))>=65,4,IF(INDEX('TEST RESULTS'!$C$5:$C$25,MATCH(A22,'TEST RESULTS'!$B$5:$B$25,0))>=60,3,0))))))))),0) -> 0 | F22: =IF(INDEX('TEST RESULTS'!$C$5:$C$25,MATCH(A22,'TEST RESULTS'!$B$5:$B$25,0))="",0,IF(E22="",0,IF(D22>E22,0.1,IF(D22<E22,-0.1,0)))) -> 0 | K22: Xander Meijer | L22: ='Xander Meijer'!C10 -> 0 | M22: ='Xander Meijer'!C11 -> 0 | N22: ='Xander Meijer'!C12 -> 0 | O22: ='Xander Meijer'!C13 -> 0 | P22: ='Xander Meijer'!C14 -> 0 | Q22: ='Xander Meijer'!C5 -> 0 | R22: ='Xander Meijer'!C17 -> 0 | S22: ='Xander Meijer'!C18 -> 50 | T22: ='Xander Meijer'!C19 -> 0 | U22: ='Xander Meijer'!C20 -> LESS THAN 5 PLAYERS | W22: =A22&" — £"&TEXT(B22,"0.0")&"m" -> Xander Meijer — £7.0m

Sheet Alexa Amesimeku
B1: ALEXA AMESIMEKU'S TEAM
B2: ← Back to PICK YOUR TEAM
B4: PICK YOUR CAPTAIN (scores 2× points)
B6: Step 1: Pick your 5 players below. Step 2: Choose your captain in the GOLD box above.
B8: SQUAD
B9: Slot | C9: Player | D9: Price
B10: 1 | D10: =IF(C10="","",IFERROR(INDEX(CALCULATIONS!$C$2:$C$22,MATCH(C10,CALCULATIONS!$W$2:$W$22,0)),""))
B11: 2 | D11: =IF(C11="","",IFERROR(INDEX(CALCULATIONS!$C$2:$C$22,MATCH(C11,CALCULATIONS!$W$2:$W$22,0)),""))
B12: 3 | D12: =IF(C12="","",IFERROR(INDEX(CALCULATIONS!$C$2:$C$22,MATCH(C12,CALCULATIONS!$W$2:$W$22,0)),""))
B13: 4 | D13: =IF(C13="","",IFERROR(INDEX(CALCULATIONS!$C$2:$C$22,MATCH(C13,CALCULATIONS!$W$2:$W$22,0)),""))
B14: 5 | D14: =IF(C14="","",IFERROR(INDEX(CALCULATIONS!$C$2:$C$22,MATCH(C14,CALCULATIONS!$W$2:$W$22,0)),""))
B16: TEAM SUMMARY
B17: Team Value | C17: =SUM(D10:D14) -> 0
B18: Budget Left | C18: =50-C17 -> 50
B19: GW Score | C19: =IF($C$20="VALID TEAM",SUMPRODUCT(SUMIF(CALCULATIONS!$W$2:$W$22,C10:C14,CALCULATIONS!$D$2:$D$22))+SUMIF(CALCULATIONS!$W$2:$W$22,C5,CALCULATIONS!$D$2:$D$22),0) -> 0
B20: Team Status | C20: =IF(COUNTBLANK(C10:C14)>0,"LESS THAN 5 PLAYERS",IF(SUM(D10:D14)>50,"OVER BUDGET",IF(C5="","NO CAPTAIN",IF(COUNTIF(C10:C14,C5)=0,"CAPTAIN NOT IN SQUAD",IF(SUMPRODUCT(COUNTIF(C10:C14,C10:C14))>5,"DUPLICATE PLAYER","VALID TEAM"))))) -> LESS THAN 5 PLAYERS
B22: INPUT CELLS ARE GOLD. Only the captain cell (C5) and the 5 player cells (C10:C14) should be edited. Do NOT type 'CAPTAIN' anywhere in the squad — use the GOLD box above.
B26: EXAMPLE (do not edit — for reference only)
B27: Slot | C27: Player | D27: Price
B28: 1 | C28: Chinedu Chile — £11.0m | D28: £11.0m
B29: 2 | C29: Emily Warburton — £11.0m | D29: £11.0m
B30: 3 | C30: Joe Paige — £10.5m | D30: £10.5m
B31: 4 | C31: Edwin Mayers — £9.0m | D31: £9.0m
B32: 5 | C32: Alfie Foley — £7.5m | D32: £7.5m
B33: CAPTAIN | C33: Emily Warburton — £11.0m
B34: TEAM VALUE | C34: £49.0m BUDGET LEFT £1.0m
B35: STATUS | C35: ✓ VALID TEAM

Sheet Alfie Foley
B1: ALFIE FOLEY'S TEAM
B2: ← Back to PICK YOUR TEAM
B4: PICK YOUR CAPTAIN (scores 2× points)
C5: Sophie Barker — £13.0m
B6: Step 1: Pick your 5 players below. Step 2: Choose your captain in the GOLD box above.
B8: SQUAD
B9: Slot | C9: Player | D9: Price
B10: 1 | C10: Ava Swinfen — £7.0m | D10: =IF(C10="","",IFERROR(INDEX(CALCULATIONS!$C$2:$C$22,MATCH(C10,CALCULATIONS!$W$2:$W$22,0)),"")) -> 7
B11: 2 | C11: David Wu — £10.5m | D11: =IF(C11="","",IFERROR(INDEX(CALCULATIONS!$C$2:$C$22,MATCH(C11,CALCULATIONS!$W$2:$W$22,0)),"")) -> 10.5
B12: 3 | C12: Alyza Rai — £10.5m | D12: =IF(C12="","",IFERROR(INDEX(CALCULATIONS!$C$2:$C$22,MATCH(C12,CALCULATIONS!$W$2:$W$22,0)),"")) -> 10.5
B13: 4 | C13: Sophie Barker — £13.0m | D13: =IF(C13="","",IFERROR(INDEX(CALCULATIONS!$C$2:$C$22,MATCH(C13,CALCULATIONS!$W$2:$W$22,0)),"")) -> 13
B14: 5 | C14: Edwin Mayers — £9.0m | D14: =IF(C14="","",IFERROR(INDEX(CALCULATIONS!$C$2:$C$22,MATCH(C14,CALCULATIONS!$W$2:$W$22,0)),"")) -> 9
B16: TEAM SUMMARY
B17: Team Value | C17: =SUM(D10:D14) -> 50
B18: Budget Left | C18: =50-C17 -> 0
B19: GW Score | C19: =IF($C$20="VALID TEAM",SUMPRODUCT(SUMIF(CALCULATIONS!$W$2:$W$22,C10:C14,CALCULATIONS!$D$2:$D$22))+SUMIF(CALCULATIONS!$W$2:$W$22,C5,CALCULATIONS!$D$2:$D$22),0) -> 0
B20: Team Status | C20: =IF(COUNTBLANK(C10:C14)>0,"LESS THAN 5 PLAYERS",IF(SUM(D10:D14)>50,"OVER BUDGET",IF(C5="","NO CAPTAIN",IF(COUNTIF(C10:C14,C5)=0,"CAPTAIN NOT IN SQUAD",IF(SUMPRODUCT(COUNTIF(C10:C14,C10:C14))>5,"DUPLICATE PLAYER","VALID TEAM"))))) -> VALID TEAM
B22: INPUT CELLS ARE GOLD. Only the captain cell (C5) and the 5 player cells (C10:C14) should be edited. Do NOT type 'CAPTAIN' anywhere in the squad — use the GOLD box above.
B26: EXAMPLE (do not edit — for reference only)
B27: Slot | C27: Player | D27: Price
B28: 1 | C28: Chinedu Chile — £11.0m | D28: £11.0m
B29: 2 | C29: Emily Warburton — £11.0m | D29: £11.0m
B30: 3 | C30: Joe Paige — £10.5m | D30: £10.5m
B31: 4 | C31: Edwin Mayers — £9.0m | D31: £9.0m
B32: 5 | C32: Alfie Foley — £7.5m | D32: £7.5m
B33: CAPTAIN | C33: Emily Warburton — £11.0m
B34: TEAM VALUE | C34: £49.0m BUDGET LEFT £1.0m
B35: STATUS | C35: ✓ VALID TEAM

Sheet Alyza Rai
B1: ALYZA RAI'S TEAM
B2: ← Back to PICK YOUR TEAM
B4: PICK YOUR CAPTAIN (scores 2× points)
B6: Step 1: Pick your 5 players below. Step 2: Choose your captain in the GOLD box above.
B8: SQUAD
B9: Slot | C9: Player | D9: Price
B10: 1 | D10: =IF(C10="","",IFERROR(INDEX(CALCULATIONS!$C$2:$C$22,MATCH(C10,CALCULATIONS!$W$2:$W$22,0)),""))
B11: 2 | D11: =IF(C11="","",IFERROR(INDEX(CALCULATIONS!$C$2:$C$22,MATCH(C11,CALCULATIONS!$W$2:$W$22,0)),""))
B12: 3 | D12: =IF(C12="","",IFERROR(INDEX(CALCULATIONS!$C$2:$C$22,MATCH(C12,CALCULATIONS!$W$2:$W$22,0)),""))
B13: 4 | D13: =IF(C13="","",IFERROR(INDEX(CALCULATIONS!$C$2:$C$22,MATCH(C13,CALCULATIONS!$W$2:$W$22,0)),""))
B14: 5 | D14: =IF(C14="","",IFERROR(INDEX(CALCULATIONS!$C$2:$C$22,MATCH(C14,CALCULATIONS!$W$2:$W$22,0)),""))
B16: TEAM SUMMARY
B17: Team Value | C17: =SUM(D10:D14) -> 0
B18: Budget Left | C18: =50-C17 -> 50
B19: GW Score | C19: =IF($C$20="VALID TEAM",SUMPRODUCT(SUMIF(CALCULATIONS!$W$2:$W$22,C10:C14,CALCULATIONS!$D$2:$D$22))+SUMIF(CALCULATIONS!$W$2:$W$22,C5,CALCULATIONS!$D$2:$D$22),0) -> 0
B20: Team Status | C20: =IF(COUNTBLANK(C10:C14)>0,"LESS THAN 5 PLAYERS",IF(SUM(D10:D14)>50,"OVER BUDGET",IF(C5="","NO CAPTAIN",IF(COUNTIF(C10:C14,C5)=0,"CAPTAIN NOT IN SQUAD",IF(SUMPRODUCT(COUNTIF(C10:C14,C10:C14))>5,"DUPLICATE PLAYER","VALID TEAM"))))) -> LESS THAN 5 PLAYERS
B22: INPUT CELLS ARE GOLD. Only the captain cell (C5) and the 5 player cells (C10:C14) should be edited. Do NOT type 'CAPTAIN' anywhere in the squad — use the GOLD box above.
B26: EXAMPLE (do not edit — for reference only)
B27: Slot | C27: Player | D27: Price
B28: 1 | C28: Chinedu Chile — £11.0m | D28: £11.0m
B29: 2 | C29: Emily Warburton — £11.0m | D29: £11.0m
B30: 3 | C30: Joe Paige — £10.5m | D30: £10.5m
B31: 4 | C31: Edwin Mayers — £9.0m | D31: £9.0m
B32: 5 | C32: Alfie Foley — £7.5m | D32: £7.5m
B33: CAPTAIN | C33: Emily Warburton — £11.0m
B34: TEAM VALUE | C34: £49.0m BUDGET LEFT £1.0m
B35: STATUS | C35: ✓ VALID TEAM

Sheet Ava Swinfen
B1: AVA SWINFEN'S TEAM
B2: ← Back to PICK YOUR TEAM
B4: PICK YOUR CAPTAIN (scores 2× points)
C5: Lia Li — £13.0m
B6: Step 1: Pick your 5 players below. Step 2: Choose your captain in the GOLD box above.
B8: SQUAD
B9: Slot | C9: Player | D9: Price
B10: 1 | C10: Rory Bowman — £7.0m | D10: =IF(C10="","",IFERROR(INDEX(CALCULATIONS!$C$2:$C$22,MATCH(C10,CALCULATIONS!$W$2:$W$22,0)),"")) -> 7
B11: 2 | C11: Melody Zhaeentan — £8.5m | D11: =IF(C11="","",IFERROR(INDEX(CALCULATIONS!$C$2:$C$22,MATCH(C11,CALCULATIONS!$W$2:$W$22,0)),"")) -> 8.5
B12: 3 | C12: Lia Li — £13.0m | D12: =IF(C12="","",IFERROR(INDEX(CALCULATIONS!$C$2:$C$22,MATCH(C12,CALCULATIONS!$W$2:$W$22,0)),"")) -> 13
B13: 4 | C13: Chinedu Chile — £11.0m | D13: =IF(C13="","",IFERROR(INDEX(CALCULATIONS!$C$2:$C$22,MATCH(C13,CALCULATIONS!$W$2:$W$22,0)),"")) -> 11
B14: 5 | C14: Daniel Liu — £9.5m | D14: =IF(C14="","",IFERROR(INDEX(CALCULATIONS!$C$2:$C$22,MATCH(C14,CALCULATIONS!$W$2:$W$22,0)),"")) -> 9.5
B16: TEAM SUMMARY
B17: Team Value | C17: =SUM(D10:D14) -> 49
B18: Budget Left | C18: =50-C17 -> 1
B19: GW Score | C19: =IF($C$20="VALID TEAM",SUMPRODUCT(SUMIF(CALCULATIONS!$W$2:$W$22,C10:C14,CALCULATIONS!$D$2:$D$22))+SUMIF(CALCULATIONS!$W$2:$W$22,C5,CALCULATIONS!$D$2:$D$22),0) -> 0
B20: Team Status | C20: =IF(COUNTBLANK(C10:C14)>0,"LESS THAN 5 PLAYERS",IF(SUM(D10:D14)>50,"OVER BUDGET",IF(C5="","NO CAPTAIN",IF(COUNTIF(C10:C14,C5)=0,"CAPTAIN NOT IN SQUAD",IF(SUMPRODUCT(COUNTIF(C10:C14,C10:C14))>5,"DUPLICATE PLAYER","VALID TEAM"))))) -> VALID TEAM
B22: INPUT CELLS ARE GOLD. Only the captain cell (C5) and the 5 player cells (C10:C14) should be edited. Do NOT type 'CAPTAIN' anywhere in the squad — use the GOLD box above.
B26: EXAMPLE (do not edit — for reference only)
B27: Slot | C27: Player | D27: Price
B28: 1 | C28: Chinedu Chile — £11.0m | D28: £11.0m
B29: 2 | C29: Emily Warburton — £11.0m | D29: £11.0m
B30: 3 | C30: Joe Paige — £10.5m | D30: £10.5m
B31: 4 | C31: Edwin Mayers — £9.0m | D31: £9.0m
B32: 5 | C32: Alfie Foley — £7.5m | D32: £7.5m
B33: CAPTAIN | C33: Emily Warburton — £11.0m
B34: TEAM VALUE | C34: £49.0m BUDGET LEFT £1.0m
B35: STATUS | C35: ✓ VALID TEAM

Sheet Azlan Husain
B1: AZLAN HUSAIN'S TEAM
B2: ← Back to PICK YOUR TEAM
B4: PICK YOUR CAPTAIN (scores 2× points)
C5: Lia Li — £13.0m
B6: Step 1: Pick your 5 players below. Step 2: Choose your captain in the GOLD box above.
B8: SQUAD
B9: Slot | C9: Player | D9: Price
B10: 1 | C10: Lia Li — £13.0m | D10: =IF(C10="","",IFERROR(INDEX(CALCULATIONS!$C$2:$C$22,MATCH(C10,CALCULATIONS!$W$2:$W$22,0)),"")) -> 13
B11: 2 | C11: David Wu — £10.5m | D11: =IF(C11="","",IFERROR(INDEX(CALCULATIONS!$C$2:$C$22,MATCH(C11,CALCULATIONS!$W$2:$W$22,0)),"")) -> 10.5
B12: 3 | C12: Joe Paige — £10.5m | D12: =IF(C12="","",IFERROR(INDEX(CALCULATIONS!$C$2:$C$22,MATCH(C12,CALCULATIONS!$W$2:$W$22,0)),"")) -> 10.5
B13: 4 | C13: Rory Bowman — £7.0m | D13: =IF(C13="","",IFERROR(INDEX(CALCULATIONS!$C$2:$C$22,MATCH(C13,CALCULATIONS!$W$2:$W$22,0)),"")) -> 7
B14: 5 | C14: Edwin Mayers — £9.0m | D14: =IF(C14="","",IFERROR(INDEX(CALCULATIONS!$C$2:$C$22,MATCH(C14,CALCULATIONS!$W$2:$W$22,0)),"")) -> 9
B16: TEAM SUMMARY
B17: Team Value | C17: =SUM(D10:D14) -> 50
B18: Budget Left | C18: =50-C17 -> 0
B19: GW Score | C19: =IF($C$20="VALID TEAM",SUMPRODUCT(SUMIF(CALCULATIONS!$W$2:$W$22,C10:C14,CALCULATIONS!$D$2:$D$22))+SUMIF(CALCULATIONS!$W$2:$W$22,C5,CALCULATIONS!$D$2:$D$22),0) -> 0
B20: Team Status | C20: =IF(COUNTBLANK(C10:C14)>0,"LESS THAN 5 PLAYERS",IF(SUM(D10:D14)>50,"OVER BUDGET",IF(C5="","NO CAPTAIN",IF(COUNTIF(C10:C14,C5)=0,"CAPTAIN NOT IN SQUAD",IF(SUMPRODUCT(COUNTIF(C10:C14,C10:C14))>5,"DUPLICATE PLAYER","VALID TEAM"))))) -> VALID TEAM
B22: INPUT CELLS ARE GOLD. Only the captain cell (C5) and the 5 player cells (C10:C14) should be edited. Do NOT type 'CAPTAIN' anywhere in the squad — use the GOLD box above.
B26: EXAMPLE (do not edit — for reference only)
B27: Slot | C27: Player | D27: Price
B28: 1 | C28: Chinedu Chile — £11.0m | D28: £11.0m
B29: 2 | C29: Emily Warburton — £11.0m | D29: £11.0m
B30: 3 | C30: Joe Paige — £10.5m | D30: £10.5m
B31: 4 | C31: Edwin Mayers — £9.0m | D31: £9.0m
B32: 5 | C32: Alfie Foley — £7.5m | D32: £7.5m
B33: CAPTAIN | C33: Emily Warburton — £11.0m
B34: TEAM VALUE | C34: £49.0m BUDGET LEFT £1.0m
B35: STATUS | C35: ✓ VALID TEAM

Sheet Chinedu Chile
B1: CHINEDU CHILE'S TEAM
B2: ← Back to PICK YOUR TEAM
B4: PICK YOUR CAPTAIN (scores 2× points)
C5: Chinedu Chile — £11.0m
B6: Step 1: Pick your 5 players below. Step 2: Choose your captain in the GOLD box above.
B8: SQUAD
B9: Slot | C9: Player | D9: Price
B10: 1 | C10: Chinedu Chile — £11.0m | D10: =IF(C10="","",IFERROR(INDEX(CALCULATIONS!$C$2:$C$22,MATCH(C10,CALCULATIONS!$W$2:$W$22,0)),"")) -> 11
B11: 2 | C11: Alexa Amesimeku — £9.5m | D11: =IF(C11="","",IFERROR(INDEX(CALCULATIONS!$C$2:$C$22,MATCH(C11,CALCULATIONS!$W$2:$W$22,0)),"")) -> 9.5
B12: 3 | C12: David Wu — £10.5m | D12: =IF(C12="","",IFERROR(INDEX(CALCULATIONS!$C$2:$C$22,MATCH(C12,CALCULATIONS!$W$2:$W$22,0)),"")) -> 10.5
B13: 4 | C13: Edwin Mayers — £9.0m | D13: =IF(C13="","",IFERROR(INDEX(CALCULATIONS!$C$2:$C$22,MATCH(C13,CALCULATIONS!$W$2:$W$22,0)),"")) -> 9
B14: 5 | C14: Azlan Husain — £10.0m | D14: =IF(C14="","",IFERROR(INDEX(CALCULATIONS!$C$2:$C$22,MATCH(C14,CALCULATIONS!$W$2:$W$22,0)),"")) -> 10
B16: TEAM SUMMARY
B17: Team Value | C17: =SUM(D10:D14) -> 50
B18: Budget Left | C18: =50-C17 -> 0
B19: GW Score | C19: =IF($C$20="VALID TEAM",SUMPRODUCT(SUMIF(CALCULATIONS!$W$2:$W$22,C10:C14,CALCULATIONS!$D$2:$D$22))+SUMIF(CALCULATIONS!$W$2:$W$22,C5,CALCULATIONS!$D$2:$D$22),0) -> 0
B20: Team Status | C20: =IF(COUNTBLANK(C10:C14)>0,"LESS THAN 5 PLAYERS",IF(SUM(D10:D14)>50,"OVER BUDGET",IF(C5="","NO CAPTAIN",IF(COUNTIF(C10:C14,C5)=0,"CAPTAIN NOT IN SQUAD",IF(SUMPRODUCT(COUNTIF(C10:C14,C10:C14))>5,"DUPLICATE PLAYER","VALID TEAM"))))) -> VALID TEAM
B22: INPUT CELLS ARE GOLD. Only the captain cell (C5) and the 5 player cells (C10:C14) should be edited. Do NOT type 'CAPTAIN' anywhere in the squad — use the GOLD box above.
B26: EXAMPLE (do not edit — for reference only)
B27: Slot | C27: Player | D27: Price
B28: 1 | C28: Chinedu Chile — £11.0m | D28: £11.0m
B29: 2 | C29: Emily Warburton — £11.0m | D29: £11.0m
B30: 3 | C30: Joe Paige — £10.5m | D30: £10.5m
B31: 4 | C31: Edwin Mayers — £9.0m | D31: £9.0m
B32: 5 | C32: Alfie Foley — £7.5m | D32: £7.5m
B33: CAPTAIN | C33: Emily Warburton — £11.0m
B34: TEAM VALUE | C34: £49.0m BUDGET LEFT £1.0m
B35: STATUS | C35: ✓ VALID TEAM

Sheet Daniel Liu
B1: DANIEL LIU'S TEAM
B2: ← Back to PICK YOUR TEAM
B4: PICK YOUR CAPTAIN (scores 2× points)
B6: Step 1: Pick your 5 players below. Step 2: Choose your captain in the GOLD box above.
B8: SQUAD
B9: Slot | C9: Player | D9: Price
B10: 1 | D10: =IF(C10="","",IFERROR(INDEX(CALCULATIONS!$C$2:$C$22,MATCH(C10,CALCULATIONS!$W$2:$W$22,0)),""))
B11: 2 | D11: =IF(C11="","",IFERROR(INDEX(CALCULATIONS!$C$2:$C$22,MATCH(C11,CALCULATIONS!$W$2:$W$22,0)),""))
B12: 3 | D12: =IF(C12="","",IFERROR(INDEX(CALCULATIONS!$C$2:$C$22,MATCH(C12,CALCULATIONS!$W$2:$W$22,0)),""))
B13: 4 | D13: =IF(C13="","",IFERROR(INDEX(CALCULATIONS!$C$2:$C$22,MATCH(C13,CALCULATIONS!$W$2:$W$22,0)),""))
B14: 5 | D14: =IF(C14="","",IFERROR(INDEX(CALCULATIONS!$C$2:$C$22,MATCH(C14,CALCULATIONS!$W$2:$W$22,0)),""))
B16: TEAM SUMMARY
B17: Team Value | C17: =SUM(D10:D14) -> 0
B18: Budget Left | C18: =50-C17 -> 50
B19: GW Score | C19: =IF($C$20="VALID TEAM",SUMPRODUCT(SUMIF(CALCULATIONS!$W$2:$W$22,C10:C14,CALCULATIONS!$D$2:$D$22))+SUMIF(CALCULATIONS!$W$2:$W$22,C5,CALCULATIONS!$D$2:$D$22),0) -> 0
B20: Team Status | C20: =IF(COUNTBLANK(C10:C14)>0,"LESS THAN 5 PLAYERS",IF(SUM(D10:D14)>50,"OVER BUDGET",IF(C5="","NO CAPTAIN",IF(COUNTIF(C10:C14,C5)=0,"CAPTAIN NOT IN SQUAD",IF(SUMPRODUCT(COUNTIF(C10:C14,C10:C14))>5,"DUPLICATE PLAYER","VALID TEAM"))))) -> LESS THAN 5 PLAYERS
B22: INPUT CELLS ARE GOLD. Only the captain cell (C5) and the 5 player cells (C10:C14) should be edited. Do NOT type 'CAPTAIN' anywhere in the squad — use the GOLD box above.
B26: EXAMPLE (do not edit — for reference only)
B27: Slot | C27: Player | D27: Price
B28: 1 | C28: Chinedu Chile — £11.0m | D28: £11.0m
B29: 2 | C29: Emily Warburton — £11.0m | D29: £11.0m
B30: 3 | C30: Joe Paige — £10.5m | D30: £10.5m
B31: 4 | C31: Edwin Mayers — £9.0m | D31: £9.0m
B32: 5 | C32: Alfie Foley — £7.5m | D32: £7.5m
B33: CAPTAIN | C33: Emily Warburton — £11.0m
B34: TEAM VALUE | C34: £49.0m BUDGET LEFT £1.0m
B35: STATUS | C35: ✓ VALID TEAM

Sheet David Wu
B1: DAVID WU'S TEAM
B2: ← Back to PICK YOUR TEAM
B4: PICK YOUR CAPTAIN (scores 2× points)
B6: Step 1: Pick your 5 players below. Step 2: Choose your captain in the GOLD box above.
B8: SQUAD
B9: Slot | C9: Player | D9: Price
B10: 1 | D10: =IF(C10="","",IFERROR(INDEX(CALCULATIONS!$C$2:$C$22,MATCH(C10,CALCULATIONS!$W$2:$W$22,0)),""))
B11: 2 | D11: =IF(C11="","",IFERROR(INDEX(CALCULATIONS!$C$2:$C$22,MATCH(C11,CALCULATIONS!$W$2:$W$22,0)),""))
B12: 3 | D12: =IF(C12="","",IFERROR(INDEX(CALCULATIONS!$C$2:$C$22,MATCH(C12,CALCULATIONS!$W$2:$W$22,0)),""))
B13: 4 | D13: =IF(C13="","",IFERROR(INDEX(CALCULATIONS!$C$2:$C$22,MATCH(C13,CALCULATIONS!$W$2:$W$22,0)),""))
B14: 5 | D14: =IF(C14="","",IFERROR(INDEX(CALCULATIONS!$C$2:$C$22,MATCH(C14,CALCULATIONS!$W$2:$W$22,0)),""))
B16: TEAM SUMMARY
B17: Team Value | C17: =SUM(D10:D14) -> 0
B18: Budget Left | C18: =50-C17 -> 50
B19: GW Score | C19: =IF($C$20="VALID TEAM",SUMPRODUCT(SUMIF(CALCULATIONS!$W$2:$W$22,C10:C14,CALCULATIONS!$D$2:$D$22))+SUMIF(CALCULATIONS!$W$2:$W$22,C5,CALCULATIONS!$D$2:$D$22),0) -> 0
B20: Team Status | C20: =IF(COUNTBLANK(C10:C14)>0,"LESS THAN 5 PLAYERS",IF(SUM(D10:D14)>50,"OVER BUDGET",IF(C5="","NO CAPTAIN",IF(COUNTIF(C10:C14,C5)=0,"CAPTAIN NOT IN SQUAD",IF(SUMPRODUCT(COUNTIF(C10:C14,C10:C14))>5,"DUPLICATE PLAYER","VALID TEAM"))))) -> LESS THAN 5 PLAYERS
B22: INPUT CELLS ARE GOLD. Only the captain cell (C5) and the 5 player cells (C10:C14) should be edited. Do NOT type 'CAPTAIN' anywhere in the squad — use the GOLD box above.
B26: EXAMPLE (do not edit — for reference only)
B27: Slot | C27: Player | D27: Price
B28: 1 | C28: Chinedu Chile — £11.0m | D28: £11.0m
B29: 2 | C29: Emily Warburton — £11.0m | D29: £11.0m
B30: 3 | C30: Joe Paige — £10.5m | D30: £10.5m
B31: 4 | C31: Edwin Mayers — £9.0m | D31: £9.0m
B32: 5 | C32: Alfie Foley — £7.5m | D32: £7.5m
B33: CAPTAIN | C33: Emily Warburton — £11.0m
B34: TEAM VALUE | C34: £49.0m BUDGET LEFT £1.0m
B35: STATUS | C35: ✓ VALID TEAM

Sheet Edwin Mayers
B1: EDWIN MAYERS'S TEAM
B2: ← Back to PICK YOUR TEAM
B4: PICK YOUR CAPTAIN (scores 2× points)
C5: Emily Warburton — £11.0m
B6: Step 1: Pick your 5 players below. Step 2: Choose your captain in the GOLD box above.
B8: SQUAD
B9: Slot | C9: Player | D9: Price
B10: 1 | C10: Sophie Barker — £13.0m | D10: =IF(C10="","",IFERROR(INDEX(CALCULATIONS!$C$2:$C$22,MATCH(C10,CALCULATIONS!$W$2:$W$22,0)),"")) -> 13
B11: 2 | C11: Esme Beston — £8.0m | D11: =IF(C11="","",IFERROR(INDEX(CALCULATIONS!$C$2:$C$22,MATCH(C11,CALCULATIONS!$W$2:$W$22,0)),"")) -> 8
B12: 3 | C12: Edwin Mayers — £9.0m | D12: =IF(C12="","",IFERROR(INDEX(CALCULATIONS!$C$2:$C$22,MATCH(C12,CALCULATIONS!$W$2:$W$22,0)),"")) -> 9
B13: 4 | C13: Emily Warburton — £11.0m | D13: =IF(C13="","",IFERROR(INDEX(CALCULATIONS!$C$2:$C$22,MATCH(C13,CALCULATIONS!$W$2:$W$22,0)),"")) -> 11
B14: 5 | C14: Ava Swinfen — £7.0m | D14: =IF(C14="","",IFERROR(INDEX(CALCULATIONS!$C$2:$C$22,MATCH(C14,CALCULATIONS!$W$2:$W$22,0)),"")) -> 7
B16: TEAM SUMMARY
B17: Team Value | C17: =SUM(D10:D14) -> 48
B18: Budget Left | C18: =50-C17 -> 2
B19: GW Score | C19: =IF($C$20="VALID TEAM",SUMPRODUCT(SUMIF(CALCULATIONS!$W$2:$W$22,C10:C14,CALCULATIONS!$D$2:$D$22))+SUMIF(CALCULATIONS!$W$2:$W$22,C5,CALCULATIONS!$D$2:$D$22),0) -> 0
B20: Team Status | C20: =IF(COUNTBLANK(C10:C14)>0,"LESS THAN 5 PLAYERS",IF(SUM(D10:D14)>50,"OVER BUDGET",IF(C5="","NO CAPTAIN",IF(COUNTIF(C10:C14,C5)=0,"CAPTAIN NOT IN SQUAD",IF(SUMPRODUCT(COUNTIF(C10:C14,C10:C14))>5,"DUPLICATE PLAYER","VALID TEAM"))))) -> VALID TEAM
B22: INPUT CELLS ARE GOLD. Only the captain cell (C5) and the 5 player cells (C10:C14) should be edited. Do NOT type 'CAPTAIN' anywhere in the squad — use the GOLD box above.
B26: EXAMPLE (do not edit — for reference only)
B27: Slot | C27: Player | D27: Price
B28: 1 | C28: Chinedu Chile — £11.0m | D28: £11.0m
B29: 2 | C29: Emily Warburton — £11.0m | D29: £11.0m
B30: 3 | C30: Joe Paige — £10.5m | D30: £10.5m
B31: 4 | C31: Edwin Mayers — £9.0m | D31: £9.0m
B32: 5 | C32: Alfie Foley — £7.5m | D32: £7.5m
B33: CAPTAIN | C33: Emily Warburton — £11.0m
B34: TEAM VALUE | C34: £49.0m BUDGET LEFT £1.0m
B35: STATUS | C35: ✓ VALID TEAM

Sheet Emily Warburton
B1: EMILY WARBURTON'S TEAM
B2: ← Back to PICK YOUR TEAM
B4: PICK YOUR CAPTAIN (scores 2× points)
B6: Step 1: Pick your 5 players below. Step 2: Choose your captain in the GOLD box above.
B8: SQUAD
B9: Slot | C9: Player | D9: Price
B10: 1 | D10: =IF(C10="","",IFERROR(INDEX(CALCULATIONS!$C$2:$C$22,MATCH(C10,CALCULATIONS!$W$2:$W$22,0)),""))
B11: 2 | D11: =IF(C11="","",IFERROR(INDEX(CALCULATIONS!$C$2:$C$22,MATCH(C11,CALCULATIONS!$W$2:$W$22,0)),""))
B12: 3 | D12: =IF(C12="","",IFERROR(INDEX(CALCULATIONS!$C$2:$C$22,MATCH(C12,CALCULATIONS!$W$2:$W$22,0)),""))
B13: 4 | D13: =IF(C13="","",IFERROR(INDEX(CALCULATIONS!$C$2:$C$22,MATCH(C13,CALCULATIONS!$W$2:$W$22,0)),""))
B14: 5 | D14: =IF(C14="","",IFERROR(INDEX(CALCULATIONS!$C$2:$C$22,MATCH(C14,CALCULATIONS!$W$2:$W$22,0)),""))
B16: TEAM SUMMARY
B17: Team Value | C17: =SUM(D10:D14) -> 0
B18: Budget Left | C18: =50-C17 -> 50
B19: GW Score | C19: =IF($C$20="VALID TEAM",SUMPRODUCT(SUMIF(CALCULATIONS!$W$2:$W$22,C10:C14,CALCULATIONS!$D$2:$D$22))+SUMIF(CALCULATIONS!$W$2:$W$22,C5,CALCULATIONS!$D$2:$D$22),0) -> 0
B20: Team Status | C20: =IF(COUNTBLANK(C10:C14)>0,"LESS THAN 5 PLAYERS",IF(SUM(D10:D14)>50,"OVER BUDGET",IF(C5="","NO CAPTAIN",IF(COUNTIF(C10:C14,C5)=0,"CAPTAIN NOT IN SQUAD",IF(SUMPRODUCT(COUNTIF(C10:C14,C10:C14))>5,"DUPLICATE PLAYER","VALID TEAM"))))) -> LESS THAN 5 PLAYERS
B22: INPUT CELLS ARE GOLD. Only the captain cell (C5) and the 5 player cells (C10:C14) should be edited. Do NOT type 'CAPTAIN' anywhere in the squad — use the GOLD box above.
B26: EXAMPLE (do not edit — for reference only)
B27: Slot | C27: Player | D27: Price
B28: 1 | C28: Chinedu Chile — £11.0m | D28: £11.0m
B29: 2 | C29: Emily Warburton — £11.0m | D29: £11.0m
