Workbook

Sheet HOME
B1: YEAR 11 FANTASY LEAGUE
B2: GAMEWEEK 1 • BIOLOGY
B4: DEADLINE • 27 SEPTEMBER 2026 • 11:59 PM
B5: TEST DATE • 28 SEPTEMBER 2026
B7: CURRENT GAMEWEEK: | C7: 1
B9: HOW TO PLAY
B10: 1. Click PICK YOUR TEAM at the top of the workbook.
B11: 2. Click your name to jump to your team sheet.
B12: 3. Pick 5 players from the dropdowns.
B13: 4. Pick 1 captain — your captain scores double points.
B14: 5. Enter your own Biology % on TEST RESULTS.
B17: THE GOLDEN RULE
B18: YOU ONLY NEED TO:
B19: ✓ Pick 5 players
B20: ✓ Pick a captain
B21: ✓ Enter your test result
B23: EXCEL DOES EVERYTHING ELSE. Points • Captain bonus • Scores • Leaderboard • Ownership • Prices

Sheet PICK YOUR TEAM
B1: PICK YOUR TEAM
B2: Click your name to jump to your team sheet.
B4: Manager | C4: Status | D4: GW Score
B5: Alexa Amesimeku | C5: =CALCULATIONS!U2 | D5: =CALCULATIONS!T2
B6: Alfie Foley | C6: =CALCULATIONS!U3 | D6: =CALCULATIONS!T3
B7: Alyza Rai | C7: =CALCULATIONS!U4 | D7: =CALCULATIONS!T4
B8: Ava Swinfen | C8: =CALCULATIONS!U5 | D8: =CALCULATIONS!T5
B9: Azlan Husain | C9: =CALCULATIONS!U6 | D9: =CALCULATIONS!T6
B10: Chinedu Chile | C10: =CALCULATIONS!U7 | D10: =CALCULATIONS!T7
B11: Daniel Liu | C11: =CALCULATIONS!U8 | D11: =CALCULATIONS!T8
B12: David Wu | C12: =CALCULATIONS!U9 | D12: =CALCULATIONS!T9
B13: Edwin Mayers | C13: =CALCULATIONS!U10 | D13: =CALCULATIONS!T10
B14: Emily Warburton | C14: =CALCULATIONS!U11 | D14: =CALCULATIONS!T11
B15: Esme Beston | C15: =CALCULATIONS!U12 | D15: =CALCULATIONS!T12
B16: Iona Smith | C16: =CALCULATIONS!U13 | D16: =CALCULATIONS!T13
... B25: Xander Meijer | C25: =CALCULATIONS!U22 | D25: =CALCULATIONS!T22

Sheet TEST RESULTS
B1: TEST RESULTS
B2: BIOLOGY • GAMEWEEK 1 • Test on 28 September 2026
B4: Student | C4: Biology % — type 90, not 90%
B5: Alexa Amesimeku
B6: Alfie Foley
B7: Alyza Rai
B8: Ava Swinfen
B9: Azlan Husain
B10: Chinedu Chile
B11: Daniel Liu
B12: David Wu
B13: Edwin Mayers
B14: Emily Warburton
B15: Esme Beston
B16: Iona Smith
... B28: Enter a whole number between 0 and 100. Do NOT type the % sign — just the number. Example: 90

Sheet PLAYER MARKET
B1: PLAYER MARKET
B2: Prices • Ownership
B4: Player | C4: Price | D4: Ownership %
B5: =CALCULATIONS!A2 | C5: =CALCULATIONS!C2 | D5: =COUNTIF('CALCULATIONS'!$L$2:$P$22,B5)/COUNTA('CALCULATIONS'!$K$2:$K$22)
B6: =CALCULATIONS!A3 | C6: =CALCULATIONS!C3 | D6: =COUNTIF('CALCULATIONS'!$L$2:$P$22,B6)/COUNTA('CALCULATIONS'!$K$2:$K$22)
B7: =CALCULATIONS!A4 | C7: =CALCULATIONS!C4 | D7: =COUNTIF('CALCULATIONS'!$L$2:$P$22,B7)/COUNTA('CALCULATIONS'!$K$2:$K$22)
B8: =CALCULATIONS!A5 | C8: =CALCULATIONS!C5 | D8: =COUNTIF('CALCULATIONS'!$L$2:$P$22,B8)/COUNTA('CALCULATIONS'!$K$2:$K$22)
B9: =CALCULATIONS!A6 | C9: =CALCULATIONS!C6 | D9: =COUNTIF('CALCULATIONS'!$L$2:$P$22,B9)/COUNTA('CALCULATIONS'!$K$2:$K$22)
B10: =CALCULATIONS!A7 | C10: =CALCULATIONS!C7 | D10: =COUNTIF('CALCULATIONS'!$L$2:$P$22,B10)/COUNTA('CALCULATIONS'!$K$2:$K$22)
B11: =CALCULATIONS!A8 | C11: =CALCULATIONS!C8 | D11: =COUNTIF('CALCULATIONS'!$L$2:$P$22,B11)/COUNTA('CALCULATIONS'!$K$2:$K$22)
B12: =CALCULATIONS!A9 | C12: =CALCULATIONS!C9 | D12: =COUNTIF('CALCULATIONS'!$L$2:$P$22,B12)/COUNTA('CALCULATIONS'!$K$2:$K$22)
B13: =CALCULATIONS!A10 | C13: =CALCULATIONS!C10 | D13: =COUNTIF('CALCULATIONS'!$L$2:$P$22,B13)/COUNTA('CALCULATIONS'!$K$2:$K$22)
B14: =CALCULATIONS!A11 | C14: =CALCULATIONS!C11 | D14: =COUNTIF('CALCULATIONS'!$L$2:$P$22,B14)/COUNTA('CALCULATIONS'!$K$2:$K$22)
B15: =CALCULATIONS!A12 | C15: =CALCULATIONS!C12 | D15: =COUNTIF('CALCULATIONS'!$L$2:$P$22,B15)/COUNTA('CALCULATIONS'!$K$2:$K$22)
B16: =CALCULATIONS!A13 | C16: =CALCULATIONS!C13 | D16: =COUNTIF('CALCULATIONS'!$L$2:$P$22,B16)/COUNTA('CALCULATIONS'!$K$2:$K$22)
... B25: =CALCULATIONS!A22 | C25: =CALCULATIONS!C22 | D25: =COUNTIF('CALCULATIONS'!$L$2:$P$22,B25)/COUNTA('CALCULATIONS'!$K$2:$K$22)
B28: PRICE RULES Prices move after each Gameweek in £0.5m steps, from -£2.0m to +£2.0m. Minimum £6.0m • Maximum £13.0m

Sheet LEADERBOARD
B1: LEADERBOARD
B2: Season so far
B4: Rank | C4: Manager | D4: GW1 | E4: Overall
B5: =RANK(E5,$E$5:$E$25,0) | C5: =CALCULATIONS!K2 | D5: =CALCULATIONS!T2 | E5: =D5
B6: =RANK(E6,$E$5:$E$25,0) | C6: =CALCULATIONS!K3 | D6: =CALCULATIONS!T3 | E6: =D6
B7: =RANK(E7,$E$5:$E$25,0) | C7: =CALCULATIONS!K4 | D7: =CALCULATIONS!T4 | E7: =D7
B8: =RANK(E8,$E$5:$E$25,0) | C8: =CALCULATIONS!K5 | D8: =CALCULATIONS!T5 | E8: =D8
B9: =RANK(E9,$E$5:$E$25,0) | C9: =CALCULATIONS!K6 | D9: =CALCULATIONS!T6 | E9: =D9
B10: =RANK(E10,$E$5:$E$25,0) | C10: =CALCULATIONS!K7 | D10: =CALCULATIONS!T7 | E10: =D10
B11: =RANK(E11,$E$5:$E$25,0) | C11: =CALCULATIONS!K8 | D11: =CALCULATIONS!T8 | E11: =D11
B12: =RANK(E12,$E$5:$E$25,0) | C12: =CALCULATIONS!K9 | D12: =CALCULATIONS!T9 | E12: =D12
B13: =RANK(E13,$E$5:$E$25,0) | C13: =CALCULATIONS!K10 | D13: =CALCULATIONS!T10 | E13: =D13
B14: =RANK(E14,$E$5:$E$25,0) | C14: =CALCULATIONS!K11 | D14: =CALCULATIONS!T11 | E14: =D14
B15: =RANK(E15,$E$5:$E$25,0) | C15: =CALCULATIONS!K12 | D15: =CALCULATIONS!T12 | E15: =D15
B16: =RANK(E16,$E$5:$E$25,0) | C16: =CALCULATIONS!K13 | D16: =CALCULATIONS!T13 | E16: =D16
... B25: =RANK(E25,$E$5:$E$25,0) | C25: =CALCULATIONS!K22 | D25: =CALCULATIONS!T22 | E25: =D25
B28: AWARDS
B29: 🏆 Highest Scorer | C29: =INDEX(C5:C25,MATCH(MAX(E5:E25),E5:E25,0))
B30: 📈 Most Improved Player | C30: Coming after Gameweek 2
B31: 🔥 Most Selected Player | C31: =INDEX('PLAYER MARKET'!B5:B25,MATCH(MAX('PLAYER MARKET'!D5:D25),'PLAYER MARKET'!D5:D25,0))
B32: 🎯 Best Captain Pick | C32: Coming after Gameweek 1 scoring is fully entered
B33: 💎 Best Value Player | C33: =INDEX('PLAYER MARKET'!B5:B25,MATCH(MAX('PLAYER MARKET'!C5:C25),'PLAYER MARKET'!C5:C25,0))

Sheet RULES
B1: RULES & HOW TO PLAY
B4: BUDGET | C4: £50.0m per manager. Pick exactly 5 players. Squad value cannot exceed £50.0m.
B6: CAPTAIN | C6: Choose 1 captain. The captain scores 2× their normal Gameweek points.
B8: DEADLINE | C8: Gameweek 1 deadline: 27 September 2026 at 11:59 PM.
B10: TEST DATE | C10: Biology test: 28 September 2026.
B12: RESULT ENTRY | C12: After the test, each student enters only their own percentage on TEST RESULTS.
B14: POINTS | C14: 90–100 = 10 • 80–89 = 8 • 70–79 = 6 • 60–69 = 5 • 50–59 = 3 • 40–49 = 2 • Below 40 = 1.
B16: PRICE CHANGES | C16: Prices update after each Gameweek. 10 → +£2.0m • 8 → +£1.5m • 6 → +£1.0m • 5 → £0 • 3 → -£1.0m • 2 → -£1.5m • 1 → -£2.0m.
B18: PRICE LIMITS | C18: Minimum £6.0m. Maximum £13.0m. Prices move only in £0.5m increments.
B20: TRANSFERS | C20: After every Gameweek: unlimited transfers, free transfers, no penalties, captains can change.
B22: TRANSFER DEADLINE | C22: The transfer window closes at the next Gameweek deadline.
B24: GOLDEN RULE | C24: Users only need to pick 5 players, pick a captain and enter their own test result. Excel handles the rest.

Sheet Alexa Amesimeku
B1: ALEXA AMESIMEKU'S TEAM
B2: ← Back to PICK YOUR TEAM
B4: PICK YOUR CAPTAIN (scores 2× points)
B6: Tip: pick your 5 players below first, then choose your captain.
B8: SQUAD
B9: Slot | C9: Player | D9: Price | E9: Captain?
B10: 1 | D10: =IF(C10="","",IFERROR(VLOOKUP(C10,'CALCULATIONS'!$A$2:$C$22,3,FALSE),"")) | E10: =IF(C10="","",IF($C$5=C10,"★ CAPTAIN",""))
B11: 2 | D11: =IF(C11="","",IFERROR(VLOOKUP(C11,'CALCULATIONS'!$A$2:$C$22,3,FALSE),"")) | E11: =IF(C11="","",IF($C$5=C11,"★ CAPTAIN",""))
B12: 3 | D12: =IF(C12="","",IFERROR(VLOOKUP(C12,'CALCULATIONS'!$A$2:$C$22,3,FALSE),"")) | E12: =IF(C12="","",IF($C$5=C12,"★ CAPTAIN",""))
B13: 4 | D13: =IF(C13="","",IFERROR(VLOOKUP(C13,'CALCULATIONS'!$A$2:$C$22,3,FALSE),"")) | E13: =IF(C13="","",IF($C$5=C13,"★ CAPTAIN",""))
B14: 5 | D14: =IF(C14="","",IFERROR(VLOOKUP(C14,'CALCULATIONS'!$A$2:$C$22,3,FALSE),"")) | E14: =IF(C14="","",IF($C$5=C14,"★ CAPTAIN",""))
B16: TEAM SUMMARY
B17: Team Value | C17: =SUM(D10:D14)
B18: Budget Left | C18: =50-C17
B19: GW Score | C19: =IF($C$20="VALID TEAM",SUMIF('CALCULATIONS'!$A$2:$A$22,C10:C14,'CALCULATIONS'!$D$2:$D$22)+SUMIF('CALCULATIONS'!$A$2:$A$22,C5,'CALCULATIONS'!$D$2:$D$22),0)
B20: Team Status | C20: =IF(COUNTBLANK(C10:C14)>0,"LESS THAN 5 PLAYERS",IF(SUM(D10:D14)>50,"OVER BUDGET",IF(C5="","NO CAPTAIN",IF(COUNTIF(C10:C14,C5)=0,"CAPTAIN NOT IN SQUAD",IF(SUMPRODUCT(COUNTIF(C10:C14,C10:C14))>5,"DUPLICATE PLAYER","VALID TEAM")))))
B22: INPUT CELLS ARE GOLD. Only the captain cell (C5) and the 5 player cells (C10:C14) should be edited. Everything else is calculated automatically.
B26: EXAMPLE (do not edit — for reference only)
B27: Slot | C27: Player | D27: Price | E27: Captain?
B28: 1 | C28: Chinedu Chile | D28: £11.0m
B29: 2 | C29: Emily Warburton | D29: £11.0m | E29: ★ CAPTAIN
B30: 3 | C30: Joe Paige | D30: £10.5m
B31: 4 | C31: Edwin Mayers | D31: £9.0m
B32: 5 | C32: Alfie Foley | D32: £7.5m
B33: CAPTAIN | C33: Emily Warburton
B34: TEAM VALUE | C34: £49.0m BUDGET LEFT £1.0m
B35: STATUS | C35: ✓ VALID TEAM

Sheet Alfie Foley
B1: ALFIE FOLEY'S TEAM
B2: ← Back to PICK YOUR TEAM
B4: PICK YOUR CAPTAIN (scores 2× points)
B6: Tip: pick your 5 players below first, then choose your captain.
B8: SQUAD
B9: Slot | C9: Player | D9: Price | E9: Captain?
B10: 1 | D10: =IF(C10="","",IFERROR(VLOOKUP(C10,'CALCULATIONS'!$A$2:$C$22,3,FALSE),"")) | E10: =IF(C10="","",IF($C$5=C10,"★ CAPTAIN",""))
B11: 2 | D11: =IF(C11="","",IFERROR(VLOOKUP(C11,'CALCULATIONS'!$A$2:$C$22,3,FALSE),"")) | E11: =IF(C11="","",IF($C$5=C11,"★ CAPTAIN",""))
B12: 3 | D12: =IF(C12="","",IFERROR(VLOOKUP(C12,'CALCULATIONS'!$A$2:$C$22,3,FALSE),"")) | E12: =IF(C12="","",IF($C$5=C12,"★ CAPTAIN",""))
B13: 4 | D13: =IF(C13="","",IFERROR(VLOOKUP(C13,'CALCULATIONS'!$A$2:$C$22,3,FALSE),"")) | E13: =IF(C13="","",IF($C$5=C13,"★ CAPTAIN",""))
B14: 5 | D14: =IF(C14="","",IFERROR(VLOOKUP(C14,'CALCULATIONS'!$A$2:$C$22,3,FALSE),"")) | E14: =IF(C14="","",IF($C$5=C14,"★ CAPTAIN",""))
B16: TEAM SUMMARY
B17: Team Value | C17: =SUM(D10:D14)
B18: Budget Left | C18: =50-C17
B19: GW Score | C19: =IF($C$20="VALID TEAM",SUMIF('CALCULATIONS'!$A$2:$A$22,C10:C14,'CALCULATIONS'!$D$2:$D$22)+SUMIF('CALCULATIONS'!$A$2:$A$22,C5,'CALCULATIONS'!$D$2:$D$22),0)
B20: Team Status | C20: =IF(COUNTBLANK(C10:C14)>0,"LESS THAN 5 PLAYERS",IF(SUM(D10:D14)>50,"OVER BUDGET",IF(C5="","NO CAPTAIN",IF(COUNTIF(C10:C14,C5)=0,"CAPTAIN NOT IN SQUAD",IF(SUMPRODUCT(COUNTIF(C10:C14,C10:C14))>5,"DUPLICATE PLAYER","VALID TEAM")))))
B22: INPUT CELLS ARE GOLD. Only the captain cell (C5) and the 5 player cells (C10:C14) should be edited. Everything else is calculated automatically.
B26: EXAMPLE (do not edit — for reference only)
B27: Slot | C27: Player | D27: Price | E27: Captain?
B28: 1 | C28: Chinedu Chile | D28: £11.0m
B29: 2 | C29: Emily Warburton | D29: £11.0m | E29: ★ CAPTAIN
B30: 3 | C30: Joe Paige | D30: £10.5m
B31: 4 | C31: Edwin Mayers | D31: £9.0m
B32: 5 | C32: Alfie Foley | D32: £7.5m
B33: CAPTAIN | C33: Emily Warburton
B34: TEAM VALUE | C34: £49.0m BUDGET LEFT £1.0m
B35: STATUS | C35: ✓ VALID TEAM

Sheet Alyza Rai
B1: ALYZA RAI'S TEAM
B2: ← Back to PICK YOUR TEAM
B4: PICK YOUR CAPTAIN (scores 2× points)
B6: Tip: pick your 5 players below first, then choose your captain.
B8: SQUAD
B9: Slot | C9: Player | D9: Price | E9: Captain?
B10: 1 | D10: =IF(C10="","",IFERROR(VLOOKUP(C10,'CALCULATIONS'!$A$2:$C$22,3,FALSE),"")) | E10: =IF(C10="","",IF($C$5=C10,"★ CAPTAIN",""))
B11: 2 | D11: =IF(C11="","",IFERROR(VLOOKUP(C11,'CALCULATIONS'!$A$2:$C$22,3,FALSE),"")) | E11: =IF(C11="","",IF($C$5=C11,"★ CAPTAIN",""))
B12: 3 | D12: =IF(C12="","",IFERROR(VLOOKUP(C12,'CALCULATIONS'!$A$2:$C$22,3,FALSE),"")) | E12: =IF(C12="","",IF($C$5=C12,"★ CAPTAIN",""))
B13: 4 | D13: =IF(C13="","",IFERROR(VLOOKUP(C13,'CALCULATIONS'!$A$2:$C$22,3,FALSE),"")) | E13: =IF(C13="","",IF($C$5=C13,"★ CAPTAIN",""))
B14: 5 | D14: =IF(C14="","",IFERROR(VLOOKUP(C14,'CALCULATIONS'!$A$2:$C$22,3,FALSE),"")) | E14: =IF(C14="","",IF($C$5=C14,"★ CAPTAIN",""))
B16: TEAM SUMMARY
B17: Team Value | C17: =SUM(D10:D14)
B18: Budget Left | C18: =50-C17
B19: GW Score | C19: =IF($C$20="VALID TEAM",SUMIF('CALCULATIONS'!$A$2:$A$22,C10:C14,'CALCULATIONS'!$D$2:$D$22)+SUMIF('CALCULATIONS'!$A$2:$A$22,C5,'CALCULATIONS'!$D$2:$D$22),0)
B20: Team Status | C20: =IF(COUNTBLANK(C10:C14)>0,"LESS THAN 5 PLAYERS",IF(SUM(D10:D14)>50,"OVER BUDGET",IF(C5="","NO CAPTAIN",IF(COUNTIF(C10:C14,C5)=0,"CAPTAIN NOT IN SQUAD",IF(SUMPRODUCT(COUNTIF(C10:C14,C10:C14))>5,"DUPLICATE PLAYER","VALID TEAM")))))
B22: INPUT CELLS ARE GOLD. Only the captain cell (C5) and the 5 player cells (C10:C14) should be edited. Everything else is calculated automatically.
B26: EXAMPLE (do not edit — for reference only)
B27: Slot | C27: Player | D27: Price | E27: Captain?
B28: 1 | C28: Chinedu Chile | D28: £11.0m
B29: 2 | C29: Emily Warburton | D29: £11.0m | E29: ★ CAPTAIN
B30: 3 | C30: Joe Paige | D30: £10.5m
B31: 4 | C31: Edwin Mayers | D31: £9.0m
B32: 5 | C32: Alfie Foley | D32: £7.5m
B33: CAPTAIN | C33: Emily Warburton
B34: TEAM VALUE | C34: £49.0m BUDGET LEFT £1.0m
B35: STATUS | C35: ✓ VALID TEAM

Sheet Ava Swinfen
B1: AVA SWINFEN'S TEAM
B2: ← Back to PICK YOUR TEAM
B4: PICK YOUR CAPTAIN (scores 2× points)
B6: Tip: pick your 5 players below first, then choose your captain.
B8: SQUAD
B9: Slot | C9: Player | D9: Price | E9: Captain?
B10: 1 | D10: =IF(C10="","",IFERROR(VLOOKUP(C10,'CALCULATIONS'!$A$2:$C$22,3,FALSE),"")) | E10: =IF(C10="","",IF($C$5=C10,"★ CAPTAIN",""))
B11: 2 | D11: =IF(C11="","",IFERROR(VLOOKUP(C11,'CALCULATIONS'!$A$2:$C$22,3,FALSE),"")) | E11: =IF(C11="","",IF($C$5=C11,"★ CAPTAIN",""))
B12: 3 | D12: =IF(C12="","",IFERROR(VLOOKUP(C12,'CALCULATIONS'!$A$2:$C$22,3,FALSE),"")) | E12: =IF(C12="","",IF($C$5=C12,"★ CAPTAIN",""))
B13: 4 | D13: =IF(C13="","",IFERROR(VLOOKUP(C13,'CALCULATIONS'!$A$2:$C$22,3,FALSE),"")) | E13: =IF(C13="","",IF($C$5=C13,"★ CAPTAIN",""))
B14: 5 | D14: =IF(C14="","",IFERROR(VLOOKUP(C14,'CALCULATIONS'!$A$2:$C$22,3,FALSE),"")) | E14: =IF(C14="","",IF($C$5=C14,"★ CAPTAIN",""))
B16: TEAM SUMMARY
B17: Team Value | C17: =SUM(D10:D14)
B18: Budget Left | C18: =50-C17
B19: GW Score | C19: =IF($C$20="VALID TEAM",SUMIF('CALCULATIONS'!$A$2:$A$22,C10:C14,'CALCULATIONS'!$D$2:$D$22)+SUMIF('CALCULATIONS'!$A$2:$A$22,C5,'CALCULATIONS'!$D$2:$D$22),0)
B20: Team Status | C20: =IF(COUNTBLANK(C10:C14)>0,"LESS THAN 5 PLAYERS",IF(SUM(D10:D14)>50,"OVER BUDGET",IF(C5="","NO CAPTAIN",IF(COUNTIF(C10:C14,C5)=0,"CAPTAIN NOT IN SQUAD",IF(SUMPRODUCT(COUNTIF(C10:C14,C10:C14))>5,"DUPLICATE PLAYER","VALID TEAM")))))
B22: INPUT CELLS ARE GOLD. Only the captain cell (C5) and the 5 player cells (C10:C14) should be edited. Everything else is calculated automatically.
B26: EXAMPLE (do not edit — for reference only)
B27: Slot | C27: Player | D27: Price | E27: Captain?
B28: 1 | C28: Chinedu Chile | D28: £11.0m
B29: 2 | C29: Emily Warburton | D29: £11.0m | E29: ★ CAPTAIN
B30: 3 | C30: Joe Paige | D30: £10.5m
B31: 4 | C31: Edwin Mayers | D31: £9.0m
B32: 5 | C32: Alfie Foley | D32: £7.5m
B33: CAPTAIN | C33: Emily Warburton
B34: TEAM VALUE | C34: £49.0m BUDGET LEFT £1.0m
B35: STATUS | C35: ✓ VALID TEAM

Sheet Azlan Husain
B1: AZLAN HUSAIN'S TEAM
B2: ← Back to PICK YOUR TEAM
B4: PICK YOUR CAPTAIN (scores 2× points)
B6: Tip: pick your 5 players below first, then choose your captain.
B8: SQUAD
B9: Slot | C9: Player | D9: Price | E9: Captain?
B10: 1 | D10: =IF(C10="","",IFERROR(VLOOKUP(C10,'CALCULATIONS'!$A$2:$C$22,3,FALSE),"")) | E10: =IF(C10="","",IF($C$5=C10,"★ CAPTAIN",""))
B11: 2 | D11: =IF(C11="","",IFERROR(VLOOKUP(C11,'CALCULATIONS'!$A$2:$C$22,3,FALSE),"")) | E11: =IF(C11="","",IF($C$5=C11,"★ CAPTAIN",""))
B12: 3 | D12: =IF(C12="","",IFERROR(VLOOKUP(C12,'CALCULATIONS'!$A$2:$C$22,3,FALSE),"")) | E12: =IF(C12="","",IF($C$5=C12,"★ CAPTAIN",""))
B13: 4 | D13: =IF(C13="","",IFERROR(VLOOKUP(C13,'CALCULATIONS'!$A$2:$C$22,3,FALSE),"")) | E13: =IF(C13="","",IF($C$5=C13,"★ CAPTAIN",""))
B14: 5 | D14: =IF(C14="","",IFERROR(VLOOKUP(C14,'CALCULATIONS'!$A$2:$C$22,3,FALSE),"")) | E14: =IF(C14="","",IF($C$5=C14,"★ CAPTAIN",""))
B16: TEAM SUMMARY
B17: Team Value | C17: =SUM(D10:D14)
B18: Budget Left | C18: =50-C17
B19: GW Score | C19: =IF($C$20="VALID TEAM",SUMIF('CALCULATIONS'!$A$2:$A$22,C10:C14,'CALCULATIONS'!$D$2:$D$22)+SUMIF('CALCULATIONS'!$A$2:$A$22,C5,'CALCULATIONS'!$D$2:$D$22),0)
B20: Team Status | C20: =IF(COUNTBLANK(C10:C14)>0,"LESS THAN 5 PLAYERS",IF(SUM(D10:D14)>50,"OVER BUDGET",IF(C5="","NO CAPTAIN",IF(COUNTIF(C10:C14,C5)=0,"CAPTAIN NOT IN SQUAD",IF(SUMPRODUCT(COUNTIF(C10:C14,C10:C14))>5,"DUPLICATE PLAYER","VALID TEAM")))))
B22: INPUT CELLS ARE GOLD. Only the captain cell (C5) and the 5 player cells (C10:C14) should be edited. Everything else is calculated automatically.
B26: EXAMPLE (do not edit — for reference only)
B27: Slot | C27: Player | D27: Price | E27: Captain?
B28: 1 | C28: Chinedu Chile | D28: £11.0m
B29: 2 | C29: Emily Warburton | D29: £11.0m | E29: ★ CAPTAIN
B30: 3 | C30: Joe Paige | D30: £10.5m
B31: 4 | C31: Edwin Mayers | D31: £9.0m
B32: 5 | C32: Alfie Foley | D32: £7.5m
B33: CAPTAIN | C33: Emily Warburton
B34: TEAM VALUE | C34: £49.0m BUDGET LEFT £1.0m
B35: STATUS | C35: ✓ VALID TEAM

Sheet Chinedu Chile
B1: CHINEDU CHILE'S TEAM
B2: ← Back to PICK YOUR TEAM
B4: PICK YOUR CAPTAIN (scores 2× points)
B6: Tip: pick your 5 players below first, then choose your captain.
B8: SQUAD
B9: Slot | C9: Player | D9: Price | E9: Captain?
B10: 1 | D10: =IF(C10="","",IFERROR(VLOOKUP(C10,'CALCULATIONS'!$A$2:$C$22,3,FALSE),"")) | E10: =IF(C10="","",IF($C$5=C10,"★ CAPTAIN",""))
B11: 2 | D11: =IF(C11="","",IFERROR(VLOOKUP(C11,'CALCULATIONS'!$A$2:$C$22,3,FALSE),"")) | E11: =IF(C11="","",IF($C$5=C11,"★ CAPTAIN",""))
B12: 3 | D12: =IF(C12="","",IFERROR(VLOOKUP(C12,'CALCULATIONS'!$A$2:$C$22,3,FALSE),"")) | E12: =IF(C12="","",IF($C$5=C12,"★ CAPTAIN",""))
B13: 4 | D13: =IF(C13="","",IFERROR(VLOOKUP(C13,'CALCULATIONS'!$A$2:$C$22,3,FALSE),"")) | E13: =IF(C13="","",IF($C$5=C13,"★ CAPTAIN",""))
B14: 5 | D14: =IF(C14="","",IFERROR(VLOOKUP(C14,'CALCULATIONS'!$A$2:$C$22,3,FALSE),"")) | E14: =IF(C14="","",IF($C$5=C14,"★ CAPTAIN",""))
B16: TEAM SUMMARY
B17: Team Value | C17: =SUM(D10:D14)
B18: Budget Left | C18: =50-C17
B19: GW Score | C19: =IF($C$20="VALID TEAM",SUMIF('CALCULATIONS'!$A$2:$A$22,C10:C14,'CALCULATIONS'!$D$2:$D$22)+SUMIF('CALCULATIONS'!$A$2:$A$22,C5,'CALCULATIONS'!$D$2:$D$22),0)
B20: Team Status | C20: =IF(COUNTBLANK(C10:C14)>0,"LESS THAN 5 PLAYERS",IF(SUM(D10:D14)>50,"OVER BUDGET",IF(C5="","NO CAPTAIN",IF(COUNTIF(C10:C14,C5)=0,"CAPTAIN NOT IN SQUAD",IF(SUMPRODUCT(COUNTIF(C10:C14,C10:C14))>5,"DUPLICATE PLAYER","VALID TEAM")))))
B22: INPUT CELLS ARE GOLD. Only the captain cell (C5) and the 5 player cells (C10:C14) should be edited. Everything else is calculated automatically.
B26: EXAMPLE (do not edit — for reference only)
B27: Slot | C27: Player | D27: Price | E27: Captain?
B28: 1 | C28: Chinedu Chile | D28: £11.0m
B29: 2 | C29: Emily Warburton | D29: £11.0m | E29: ★ CAPTAIN
B30: 3 | C30: Joe Paige | D30: £10.5m
B31: 4 | C31: Edwin Mayers | D31: £9.0m
B32: 5 | C32: Alfie Foley | D32: £7.5m
B33: CAPTAIN | C33: Emily Warburton
B34: TEAM VALUE | C34: £49.0m BUDGET LEFT £1.0m
B35: STATUS | C35: ✓ VALID TEAM

Sheet Daniel Liu
B1: DANIEL LIU'S TEAM
B2: ← Back to PICK YOUR TEAM
B4: PICK YOUR CAPTAIN (scores 2× points)
B6: Tip: pick your 5 players below first, then choose your captain.
B8: SQUAD
B9: Slot | C9: Player | D9: Price | E9: Captain?
B10: 1 | D10: =IF(C10="","",IFERROR(VLOOKUP(C10,'CALCULATIONS'!$A$2:$C$22,3,FALSE),"")) | E10: =IF(C10="","",IF($C$5=C10,"★ CAPTAIN",""))
B11: 2 | D11: =IF(C11="","",IFERROR(VLOOKUP(C11,'CALCULATIONS'!$A$2:$C$22,3,FALSE),"")) | E11: =IF(C11="","",IF($C$5=C11,"★ CAPTAIN",""))
B12: 3 | D12: =IF(C12="","",IFERROR(VLOOKUP(C12,'CALCULATIONS'!$A$2:$C$22,3,FALSE),"")) | E12: =IF(C12="","",IF($C$5=C12,"★ CAPTAIN",""))
B13: 4 | D13: =IF(C13="","",IFERROR(VLOOKUP(C13,'CALCULATIONS'!$A$2:$C$22,3,FALSE),"")) | E13: =IF(C13="","",IF($C$5=C13,"★ CAPTAIN",""))
B14: 5 | D14: =IF(C14="","",IFERROR(VLOOKUP(C14,'CALCULATIONS'!$A$2:$C$22,3,FALSE),"")) | E14: =IF(C14="","",IF($C$5=C14,"★ CAPTAIN",""))
B16: TEAM SUMMARY
B17: Team Value | C17: =SUM(D10:D14)
B18: Budget Left | C18: =50-C17
B19: GW Score | C19: =IF($C$20="VALID TEAM",SUMIF('CALCULATIONS'!$A$2:$A$22,C10:C14,'CALCULATIONS'!$D$2:$D$22)+SUMIF('CALCULATIONS'!$A$2:$A$22,C5,'CALCULATIONS'!$D$2:$D$22),0)
B20: Team Status | C20: =IF(COUNTBLANK(C10:C14)>0,"LESS THAN 5 PLAYERS",IF(SUM(D10:D14)>50,"OVER BUDGET",IF(C5="","NO CAPTAIN",IF(COUNTIF(C10:C14,C5)=0,"CAPTAIN NOT IN SQUAD",IF(SUMPRODUCT(COUNTIF(C10:C14,C10:C14))>5,"DUPLICATE PLAYER","VALID TEAM")))))
B22: INPUT CELLS ARE GOLD. Only the captain cell (C5) and the 5 player cells (C10:C14) should be edited. Everything else is calculated automatically.
B26: EXAMPLE (do not edit — for reference only)
B27: Slot | C27: Player | D27: Price | E27: Captain?
B28: 1 | C28: Chinedu Chile | D28: £11.0m
B29: 2 | C29: Emily Warburton | D29: £11.0m | E29: ★ CAPTAIN
B30: 3 | C30: Joe Paige | D30: £10.5m
B31: 4 | C31: Edwin Mayers | D31: £9.0m
B32: 5 | C32: Alfie Foley | D32: £7.5m
B33: CAPTAIN | C33: Emily Warburton
B34: TEAM VALUE | C34: £49.0m BUDGET LEFT £1.0m
B35: STATUS | C35: ✓ VALID TEAM

Sheet David Wu
B1: DAVID WU'S TEAM
B2: ← Back to PICK YOUR TEAM
B4: PICK YOUR CAPTAIN (scores 2× points)
B6: Tip: pick your 5 players below first, then choose your captain.
B8: SQUAD
B9: Slot | C9: Player | D9: Price | E9: Captain?
B10: 1 | D10: =IF(C10="","",IFERROR(VLOOKUP(C10,'CALCULATIONS'!$A$2:$C$22,3,FALSE),"")) | E10: =IF(C10="","",IF($C$5=C10,"★ CAPTAIN",""))
B11: 2 | D11: =IF(C11="","",IFERROR(VLOOKUP(C11,'CALCULATIONS'!$A$2:$C$22,3,FALSE),"")) | E11: =IF(C11="","",IF($C$5=C11,"★ CAPTAIN",""))
B12: 3 | D12: =IF(C12="","",IFERROR(VLOOKUP(C12,'CALCULATIONS'!$A$2:$C$22,3,FALSE),"")) | E12: =IF(C12="","",IF($C$5=C12,"★ CAPTAIN",""))
B13: 4 | D13: =IF(C13="","",IFERROR(VLOOKUP(C13,'CALCULATIONS'!$A$2:$C$22,3,FALSE),"")) | E13: =IF(C13="","",IF($C$5=C13,"★ CAPTAIN",""))
B14: 5 | D14: =IF(C14="","",IFERROR(VLOOKUP(C14,'CALCULATIONS'!$A$2:$C$22,3,FALSE),"")) | E14: =IF(C14="","",IF($C$5=C14,"★ CAPTAIN",""))
B16: TEAM SUMMARY
B17: Team Value | C17: =SUM(D10:D14)
B18: Budget Left | C18: =50-C17
B19: GW Score | C19: =IF($C$20="VALID TEAM",SUMIF('CALCULATIONS'!$A$2:$A$22,C10:C14,'CALCULATIONS'!$D$2:$D$22)+SUMIF('CALCULATIONS'!$A$2:$A$22,C5,'CALCULATIONS'!$D$2:$D$22),0)
B20: Team Status | C20: =IF(COUNTBLANK(C10:C14)>0,"LESS THAN 5 PLAYERS",IF(SUM(D10:D14)>50,"OVER BUDGET",IF(C5="","NO CAPTAIN",IF(COUNTIF(C10:C14,C5)=0,"CAPTAIN NOT IN SQUAD",IF(SUMPRODUCT(COUNTIF(C10:C14,C10:C14))>5,"DUPLICATE PLAYER","VALID TEAM")))))
B22: INPUT CELLS ARE GOLD. Only the captain cell (C5) and the 5 player cells (C10:C14) should be edited. Everything else is calculated automatically.
B26: EXAMPLE (do not edit — for reference only)
B27: Slot | C27: Player | D27: Price | E27: Captain?
B28: 1 | C28: Chinedu Chile | D28: £11.0m
B29: 2 | C29: Emily Warburton | D29: £11.0m | E29: ★ CAPTAIN
B30: 3 | C30: Joe Paige | D30: £10.5m
B31: 4 | C31: Edwin Mayers | D31: £9.0m
B32: 5 | C32: Alfie Foley | D32: £7.5m
B33: CAPTAIN | C33: Emily Warburton
B34: TEAM VALUE | C34: £49.0m BUDGET LEFT £1.0m
B35: STATUS | C35: ✓ VALID TEAM

Sheet Edwin Mayers
B1: EDWIN MAYERS'S TEAM
B2: ← Back to PICK YOUR TEAM
B4: PICK YOUR CAPTAIN (scores 2× points)
B6: Tip: pick your 5 players below first, then choose your captain.
B8: SQUAD
B9: Slot | C9: Player | D9: Price | E9: Captain?
B10: 1 | D10: =IF(C10="","",IFERROR(VLOOKUP(C10,'CALCULATIONS'!$A$2:$C$22,3,FALSE),"")) | E10: =IF(C10="","",IF($C$5=C10,"★ CAPTAIN",""))
B11: 2 | D11: =IF(C11="","",IFERROR(VLOOKUP(C11,'CALCULATIONS'!$A$2:$C$22,3,FALSE),"")) | E11: =IF(C11="","",IF($C$5=C11,"★ CAPTAIN",""))
B12: 3 | D12: =IF(C12="","",IFERROR(VLOOKUP(C12,'CALCULATIONS'!$A$2:$C$22,3,FALSE),"")) | E12: =IF(C12="","",IF($C$5=C12,"★ CAPTAIN",""))
B13: 4 | D13: =IF(C13="","",IFERROR(VLOOKUP(C13,'CALCULATIONS'!$A$2:$C$22,3,FALSE),"")) | E13: =IF(C13="","",IF($C$5=C13,"★ CAPTAIN",""))
B14: 5 | D14: =IF(C14="","",IFERROR(VLOOKUP(C14,'CALCULATIONS'!$A$2:$C$22,3,FALSE),"")) | E14: =IF(C14="","",IF($C$5=C14,"★ CAPTAIN",""))
B16: TEAM SUMMARY
B17: Team Value | C17: =SUM(D10:D14)
B18: Budget Left | C18: =50-C17
B19: GW Score | C19: =IF($C$20="VALID TEAM",SUMIF('CALCULATIONS'!$A$2:$A$22,C10:C14,'CALCULATIONS'!$D$2:$D$22)+SUMIF('CALCULATIONS'!$A$2:$A$22,C5,'CALCULATIONS'!$D$2:$D$22),0)
B20: Team Status | C20: =IF(COUNTBLANK(C10:C14)>0,"LESS THAN 5 PLAYERS",IF(SUM(D10:D14)>50,"OVER BUDGET",IF(C5="","NO CAPTAIN",IF(COUNTIF(C10:C14,C5)=0,"CAPTAIN NOT IN SQUAD",IF(SUMPRODUCT(COUNTIF(C10:C14,C10:C14))>5,"DUPLICATE PLAYER","VALID TEAM")))))
B22: INPUT CELLS ARE GOLD. Only the captain cell (C5) and the 5 player cells (C10:C14) should be edited. Everything else is calculated automatically.
B26: EXAMPLE (do not edit — for reference only)
B27: Slot | C27: Player | D27: Price | E27: Captain?
B28: 1 | C28: Chinedu Chile | D28: £11.0m
B29: 2 | C29: Emily Warburton | D29: £11.0m | E29: ★ CAPTAIN
B30: 3 | C30: Joe Paige | D30: £10.5m
B31: 4 | C31: Edwin Mayers | D31: £9.0m
B32: 5 | C32: Alfie Foley | D32: £7.5m
B33: CAPTAIN | C33: Emily Warburton
B34: TEAM VALUE | C34: £49.0m BUDGET LEFT £1.0m
B35: STATUS | C35: ✓ VALID TEAM

Sheet Emily Warburton
B1: EMILY WARBURTON'S TEAM
B2: ← Back to PICK YOUR TEAM
B4: PICK YOUR CAPTAIN (scores 2× points)
B6: Tip: pick your 5 players below first, then choose your captain.
B8: SQUAD
B9: Slot | C9: Player | D9: Price | E9: Captain?
B10: 1 | D10: =IF(C10="","",IFERROR(VLOOKUP(C10,'CALCULATIONS'!$A$2:$C$22,3,FALSE),"")) | E10: =IF(C10="","",IF($C$5=C10,"★ CAPTAIN",""))
B11: 2 | D11: =IF(C11="","",IFERROR(VLOOKUP(C11,'CALCULATIONS'!$A$2:$C$22,3,FALSE),"")) | E11: =IF(C11="","",IF($C$5=C11,"★ CAPTAIN",""))
B12: 3 | D12: =IF(C12="","",IFERROR(VLOOKUP(C12,'CALCULATIONS'!$A$2:$C$22,3,FALSE),"")) | E12: =IF(C12="","",IF($C$5=C12,"★ CAPTAIN",""))
B13: 4 | D13: =IF(C13="","",IFERROR(VLOOKUP(C13,'CALCULATIONS'!$A$2:$C$22,3,FALSE),"")) | E13: =IF(C13="","",IF($C$5=C13,"★ CAPTAIN",""))
B14: 5 | D14: =IF(C14="","",IFERROR(VLOOKUP(C14,'CALCULATIONS'!$A$2:$C$22,3,FALSE),"")) | E14: =IF(C14="","",IF($C$5=C14,"★ CAPTAIN",""))
B16: TEAM SUMMARY
B17: Team Value | C17: =SUM(D10:D14)
B18: Budget Left | C18: =50-C17
B19: GW Score | C19: =IF($C$20="VALID TEAM",SUMIF('CALCULATIONS'!$A$2:$A$22,C10:C14,'CALCULATIONS'!$D$2:$D$22)+SUMIF('CALCULATIONS'!$A$2:$A$22,C5,'CALCULATIONS'!$D$2:$D$22),0)
B20: Team Status | C20: =IF(COUNTBLANK(C10:C14)>0,"LESS THAN 5 PLAYERS",IF(SUM(D10:D14)>50,"OVER BUDGET",IF(C5="","NO CAPTAIN",IF(COUNTIF(C10:C14,C5)=0,"CAPTAIN NOT IN SQUAD",IF(SUMPRODUCT(COUNTIF(C10:C14,C10:C14))>5,"DUPLICATE PLAYER","VALID TEAM")))))
B22: INPUT CELLS ARE GOLD. Only the captain cell (C5) and the 5 player cells (C10:C14) should be edited. Everything else is calculated automatically.
B26: EXAMPLE (do not edit — for reference only)
B27: Slot | C27: Player | D27: Price | E27: Captain?
B28: 1 | C28: Chinedu Chile | D28: £11.0m
B29: 2 | C29: Emily Warburton | D29: £11.0m | E29: ★ CAPTAIN
B30: 3 | C30: Joe Paige | D30: £10.5m
B31: 4 | C31: Edwin Mayers | D31: £9.0m
B32: 5 | C32: Alfie Foley | D32: £7.5m
B33: CAPTAIN | C33: Emily Warburton
B34: TEAM VALUE | C34: £49.0m BUDGET LEFT £1.0m
B35: STATUS | C35: ✓ VALID TEAM

Sheet Esme Beston
B1: ESME BESTON'S TEAM
B2: ← Back to PICK YOUR TEAM
B4: PICK YOUR CAPTAIN (scores 2× points)
B6: Tip: pick your 5 players below first, then choose your captain.
B8: SQUAD
B9: Slot | C9: Player | D9: Price | E9: Captain?
B10: 1 | D10: =IF(C10="","",IFERROR(VLOOKUP(C10,'CALCULATIONS'!$A$2:$C$22,3,FALSE),"")) | E10: =IF(C10="","",IF($C$5=C10,"★ CAPTAIN",""))
B11: 2 | D11: =IF(C11="","",IFERROR(VLOOKUP(C11,'CALCULATIONS'!$A$2:$C$22,3,FALSE),"")) | E11: =IF(C11="","",IF($C$5=C11,"★ CAPTAIN",""))
B12: 3 | D12: =IF(C12="","",IFERROR(VLOOKUP(C12,'CALCULATIONS'!$A$2:$C$22,3,FALSE),"")) | E12: =IF(C12="","",IF($C$5=C12,"★ CAPTAIN",""))
B13: 4 | D13: =IF(C13="","",IFERROR(VLOOKUP(C13,'CALCULATIONS'!$A$2:$C$22,3,FALSE),"")) | E13: =IF(C13="","",IF($C$5=C13,"★ CAPTAIN",""))
B14: 5 | D14: =IF(C14="","",IFERROR(VLOOKUP(C14,'CALCULATIONS'!$A$2:$C$22,3,FALSE),"")) | E14: =IF(C14="","",IF($C$5=C14,"★ CAPTAIN",""))
B16: TEAM SUMMARY
B17: Team Value | C17: =SUM(D10:D14)
B18: Budget Left | C18: =50-C17
B19: GW Score | C19: =IF($C$20="VALID TEAM",SUMIF('CALCULATIONS'!$A$2:$A$22,C10:C14,'CALCULATIONS'!$D$2:$D$22)+SUMIF('CALCULATIONS'!$A$2:$A$22,C5,'CALCULATIONS'!$D$2:$D$22),0)
B20: Team Status | C20: =IF(COUNTBLANK(C10:C14)>0,"LESS THAN 5 PLAYERS",IF(SUM(D10:D14)>50,"OVER BUDGET",IF(C5="","NO CAPTAIN",IF(COUNTIF(C10:C14,C5)=0,"CAPTAIN NOT IN SQUAD",IF(SUMPRODUCT(COUNTIF(C10:C14,C10:C14))>5,"DUPLICATE PLAYER","VALID TEAM")))))
B22: INPUT CELLS ARE GOLD. Only the captain cell (C5) and the 5 player cells (C10:C14) should be edited. Everything else is calculated automatically.
B26: EXAMPLE (do not edit — for reference only)
B27: Slot | C27: Player | D27: Price | E27: Captain?
B28: 1 | C28: Chinedu Chile | D28: £11.0m
B29: 2 | C29: Emily Warburton | D29: £11.0m | E29: ★ CAPTAIN
B30: 3 | C30: Joe Paige | D30: £10.5m
B31: 4 | C31: Edwin Mayers | D31: £9.0m
B32: 5 | C32: Alfie Foley | D32: £7.5m
B33: CAPTAIN | C33: Emily Warburton
B34: TEAM VALUE | C34: £49.0m BUDGET LEFT £1.0m
B35: STATUS | C35: ✓ VALID TEAM

Sheet Iona Smith
B1: IONA SMITH'S TEAM
B2: ← Back to PICK YOUR TEAM
B4: PICK YOUR CAPTAIN (scores 2× points)
B6: Tip: pick your 5 players below first, then choose your captain.
B8: SQUAD
B9: Slot | C9: Player | D9: Price | E9: Captain?
B10: 1 | D10: =IF(C10="","",IFERROR(VLOOKUP(C10,'CALCULATIONS'!$A$2:$C$22,3,FALSE),"")) | E10: =IF(C10="","",IF($C$5=C10,"★ CAPTAIN",""))
B11: 2 | D11: =IF(C11="","",IFERROR(VLOOKUP(C11,'CALCULATIONS'!$A$2:$C$22,3,FALSE),"")) | E11: =IF(C11="","",IF($C$5=C11,"★ CAPTAIN",""))
B12: 3 | D12: =IF(C12="","",IFERROR(VLOOKUP(C12,'CALCULATIONS'!$A$2:$C$22,3,FALSE),"")) | E12: =IF(C12="","",IF($C$5=C12,"★ CAPTAIN",""))
B13: 4 | D13: =IF(C13="","",IFERROR(VLOOKUP(C13,'CALCULATIONS'!$A$2:$C$22,3,FALSE),"")) | E13: =IF(C13="","",IF($C$5=C13,"★ CAPTAIN",""))
B14: 5 | D14: =IF(C14="","",IFERROR(VLOOKUP(C14,'CALCULATIONS'!$A$2:$C$22,3,FALSE),"")) | E14: =IF(C14="","",IF($C$5=C14,"★ CAPTAIN",""))
B16: TEAM SUMMARY
B17: Team Value | C17: =SUM(D10:D14)
B18: Budget Left | C18: =50-C17
B19: GW Score | C19: =IF($C$20="VALID TEAM",SUMIF('CALCULATIONS'!$A$2:$A$22,C10:C14,'CALCULATIONS'!$D$2:$D$22)+SUMIF('CALCULATIONS'!$A$2:$A$22,C5,'CALCULATIONS'!$D$2:$D$22),0)
B20: Team Status | C20: =IF(COUNTBLANK(C10:C14)>0,"LESS THAN 5 PLAYERS",IF(SUM(D10:D14)>50,"OVER BUDGET",IF(C5="","NO CAPTAIN",IF(COUNTIF(C10:C14,C5)=0,"CAPTAIN NOT IN SQUAD",IF(SUMPRODUCT(COUNTIF(C10:C14,C10:C14))>5,"DUPLICATE PLAYER","VALID TEAM")))))
B22: INPUT CELLS ARE GOLD. Only the captain cell (C5) and the 5 player cells (C10:C14) should be edited. Everything else is calculated automatically.
B26: EXAMPLE (do not edit — for reference only)
B27: Slot | C27: Player | D27: Price | E27: Captain?
B28: 1 | C28: Chinedu Chile | D28: £11.0m
B29: 2 | C29: Emily Warburton | D29: £11.0m | E29: ★ CAPTAIN
B30: 3 | C30: Joe Paige | D30: £10.5m
B31: 4 | C31: Edwin Mayers | D31: £9.0m
B32: 5 | C32: Alfie Foley | D32: £7.5m
B33: CAPTAIN | C33: Emily Warburton
B34: TEAM VALUE | C34: £49.0m BUDGET LEFT £1.0m
B35: STATUS | C35: ✓ VALID TEAM

Sheet Joe Paige
B1: JOE PAIGE'S TEAM
B2: ← Back to PICK YOUR TEAM
B4: PICK YOUR CAPTAIN (scores 2× points)
B6: Tip: pick your 5 players below first, then choose your captain.
B8: SQUAD
B9: Slot | C9: Player | D9: Price | E9: Captain?
B10: 1 | D10: =IF(C10="","",IFERROR(VLOOKUP(C10,'CALCULATIONS'!$A$2:$C$22,3,FALSE),"")) | E10: =IF(C10="","",IF($C$5=C10,"★ CAPTAIN",""))
B11: 2 | D11: =IF(C11="","",IFERROR(VLOOKUP(C11,'CALCULATIONS'!$A$2:$C$22,3,FALSE),"")) | E11: =IF(C11="","",IF($C$5=C11,"★ CAPTAIN",""))
B12: 3 | D12: =IF(C12="","",IFERROR(VLOOKUP(C12,'CALCULATIONS'!$A$2:$C$22,3,FALSE),"")) | E12: =IF(C12="","",IF($C$5=C12,"★ CAPTAIN",""))
B13: 4 | D13: =IF(C13="","",IFERROR(VLOOKUP(C13,'CALCULATIONS'!$A$2:$C$22,3,FALSE),"")) | E13: =IF(C13="","",IF($C$5=C13,"★ CAPTAIN",""))
B14: 5 | D14: =IF(C14="","",IFERROR(VLOOKUP(C14,'CALCULATIONS'!$A$2:$C$22,3,FALSE),"")) | E14: =IF(C14="","",IF($C$5=C14,"★ CAPTAIN",""))
B16: TEAM SUMMARY
B17: Team Value | C17: =SUM(D10:D14)
B18: Budget Left | C18: =50-C17
B19: GW Score | C19: =IF($C$20="VALID TEAM",SUMIF('CALCULATIONS'!$A$2:$A$22,C10:C14,'CALCULATIONS'!$D$2:$D$22)+SUMIF('CALCULATIONS'!$A$2:$A$22,C5,'CALCULATIONS'!$D$2:$D$22),0)
B20: Team Status | C20: =IF(COUNTBLANK(C10:C14)>0,"LESS THAN 5 PLAYERS",IF(SUM(D10:D14)>50,"OVER BUDGET",IF(C5="","NO CAPTAIN",IF(COUNTIF(C10:C14,C5)=0,"CAPTAIN NOT IN SQUAD",IF(SUMPRODUCT(COUNTIF(C10:C14,C10:C14))>5,"DUPLICATE PLAYER","VALID TEAM")))))
B22: INPUT CELLS ARE GOLD. Only the captain cell (C5) and the 5 player cells (C10:C14) should be edited. Everything else is calculated automatically.
B26: EXAMPLE (do not edit — for reference only)
B27: Slot | C27: Player | D27: Price | E27: Captain?
B28: 1 | C28: Chinedu Chile | D28: £11.0m
B29: 2 | C29: Emily Warburton | D29: £11.0m | E29: ★ CAPTAIN
B30: 3 | C30: Joe Paige | D30: £10.5m
B31: 4 | C31: Edwin Mayers | D31: £9.0m
B32: 5 | C32: Alfie Foley | D32: £7.5m
B33: CAPTAIN | C33: Emily Warburton
B34: TEAM VALUE | C34: £49.0m BUDGET LEFT £1.0m
B35: STATUS | C35: ✓ VALID TEAM

Sheet Lia Li
B1: LIA LI'S TEAM
B2: ← Back to PICK YOUR TEAM
B4: PICK YOUR CAPTAIN (scores 2× points)
B6: Tip: pick your 5 players below first, then choose your captain.
B8: SQUAD
B9: Slot | C9: Player | D9: Price | E9: Captain?
B10: 1 | D10: =IF(C10="","",IFERROR(VLOOKUP(C10,'CALCULATIONS'!$A$2:$C$22,3,FALSE),"")) | E10: =IF(C10="","",IF($C$5=C10,"★ CAPTAIN",""))
B11: 2 | D11: =IF(C11="","",IFERROR(VLOOKUP(C11,'CALCULATIONS'!$A$2:$C$22,3,FALSE),"")) | E11: =IF(C11="","",IF($C$5=C11,"★ CAPTAIN",""))
B12: 3 | D12: =IF(C12="","",IFERROR(VLOOKUP(C12,'CALCULATIONS'!$A$2:$C$22,3,FALSE),"")) | E12: =IF(C12="","",IF($C$5=C12,"★ CAPTAIN",""))
B13: 4 | D13: =IF(C13="","",IFERROR(VLOOKUP(C13,'CALCULATIONS'!$A$2:$C$22,3,FALSE),"")) | E13: =IF(C13="","",IF($C$5=C13,"★ CAPTAIN",""))
B14: 5 | D14: =IF(C14="","",IFERROR(VLOOKUP(C14,'CALCULATIONS'!$A$2:$C$22,3,FALSE),"")) | E14: =IF(C14="","",IF($C$5=C14,"★ CAPTAIN",""))
B16: TEAM SUMMARY
B17: Team Value | C17: =SUM(D10:D14)
B18: Budget Left | C18: =50-C17
B19: GW Score | C19: =IF($C$20="VALID TEAM",SUMIF('CALCULATIONS'!$A$2:$A$22,C10:C14,'CALCULATIONS'!$D$2:$D$22)+SUMIF('CALCULATIONS'!$A$2:$A$22,C5,'CALCULATIONS'!$D$2:$D$22),0)
B20: Team Status | C20: =IF(COUNTBLANK(C10:C14)>0,"LESS THAN 5 PLAYERS",IF(SUM(D10:D14)>50,"OVER BUDGET",IF(C5="","NO CAPTAIN",IF(COUNTIF(C10:C14,C5)=0,"CAPTAIN NOT IN SQUAD",IF(SUMPRODUCT(COUNTIF(C10:C14,C10:C14))>5,"DUPLICATE PLAYER","VALID TEAM")))))
B22: INPUT CELLS ARE GOLD. Only the captain cell (C5) and the 5 player cells (C10:C14) should be edited. Everything else is calculated automatically.
B26: EXAMPLE (do not edit — for reference only)
B27: Slot | C27: Player | D27: Price | E27: Captain?
B28: 1 | C28: Chinedu Chile | D28: £11.0m
B29: 2 | C29: Emily Warburton | D29: £11.0m | E29: ★ CAPTAIN
B30: 3 | C30: Joe Paige | D30: £10.5m
B31: 4 | C31: Edwin Mayers | D31: £9.0m
B32: 5 | C32: Alfie Foley | D32: £7.5m
B33: CAPTAIN | C33: Emily Warburton
B34: TEAM VALUE | C34: £49.0m BUDGET LEFT £1.0m
B35: STATUS | C35: ✓ VALID TEAM

Sheet Melody Zhaeentan
B1: MELODY ZHAEENTAN'S TEAM
B2: ← Back to PICK YOUR TEAM
B4: PICK YOUR CAPTAIN (scores 2× points)
B6: Tip: pick your 5 players below first, then choose your captain.
B8: SQUAD
B9: Slot | C9: Player | D9: Price | E9: Captain?
B10: 1 | D10: =IF(C10="","",IFERROR(VLOOKUP(C10,'CALCULATIONS'!$A$2:$C$22,3,FALSE),"")) | E10: =IF(C10="","",IF($C$5=C10,"★ CAPTAIN",""))
B11: 2 | D11: =IF(C11="","",IFERROR(VLOOKUP(C11,'CALCULATIONS'!$A$2:$C$22,3,FALSE),"")) | E11: =IF(C11="","",IF($C$5=C11,"★ CAPTAIN",""))
B12: 3 | D12: =IF(C12="","",IFERROR(VLOOKUP(C12,'CALCULATIONS'!$A$2:$C$22,3,FALSE),"")) | E12: =IF(C12="","",IF($C$5=C12,"★ CAPTAIN",""))
B13: 4 | D13: =IF(C13="","",IFERROR(VLOOKUP(C13,'CALCULATIONS'!$A$2:$C$22,3,FALSE),"")) | E13: =IF(C13="","",IF($C$5=C13,"★ CAPTAIN",""))
B14: 5 | D14: =IF(C14="","",IFERROR(VLOOKUP(C14,'CALCULATIONS'!$A$2:$C$22,3,FALSE),"")) | E14: =IF(C14="","",IF($C$5=C14,"★ CAPTAIN",""))
B16: TEAM SUMMARY
B17: Team Value | C17: =SUM(D10:D14)
B18: Budget Left | C18: =50-C17
B19: GW Score | C19: =IF($C$20="VALID TEAM",SUMIF('CALCULATIONS'!$A$2:$A$22,C10:C14,'CALCULATIONS'!$D$2:$D$22)+SUMIF('CALCULATIONS'!$A$2:$A$22,C5,'CALCULATIONS'!$D$2:$D$22),0)
B20: Team Status | C20: =IF(COUNTBLANK(C10:C14)>0,"LESS THAN 5 PLAYERS",IF(SUM(D10:D14)>50,"OVER BUDGET",IF(C5="","NO CAPTAIN",IF(COUNTIF(C10:C14,C5)=0,"CAPTAIN NOT IN SQUAD",IF(SUMPRODUCT(COUNTIF(C10:C14,C10:C14))>5,"DUPLICATE PLAYER","VALID TEAM")))))
B22: INPUT CELLS ARE GOLD. Only the captain cell (C5) and the 5 player cells (C10:C14) should be edited. Everything else is calculated automatically.
B26: EXAMPLE (do not edit — for reference only)
B27: Slot | C27: Player | D27: Price | E27: Captain?
B28: 1 | C28: Chinedu Chile | D28: £11.0m
B29: 2 | C29: Emily Warburton | D29: £11.0m | E29: ★ CAPTAIN
B30: 3 | C30: Joe Paige | D30: £10.5m
B31: 4 | C31: Edwin Mayers | D31: £9.0m
B32: 5 | C32: Alfie Foley | D32: £7.5m
B33: CAPTAIN | C33: Emily Warburton
B34: TEAM VALUE | C34: £49.0m BUDGET LEFT £1.0m
B35: STATUS | C35: ✓ VALID TEAM

Sheet Nina De Saram
B1: NINA DE SARAM'S TEAM
B2: ← Back to PICK YOUR TEAM
B4: PICK YOUR CAPTAIN (scores 2× points)
B6: Tip: pick your 5 players below first, then choose your captain.
B8: SQUAD
B9: Slot | C9: Player | D9: Price | E9: Captain?
B10: 1 | D10: =IF(C10="","",IFERROR(VLOOKUP(C10,'CALCULATIONS'!$A$2:$C$22,3,FALSE),"")) | E10: =IF(C10="","",IF($C$5=C10,"★ CAPTAIN",""))
B11: 2 | D11: =IF(C11="","",IFERROR(VLOOKUP(C11,'CALCULATIONS'!$A$2:$C$22,3,FALSE),"")) | E11: =IF(C11="","",IF($C$5=C11,"★ CAPTAIN",""))
B12: 3 | D12: =IF(C12="","",IFERROR(VLOOKUP(C12,'CALCULATIONS'!$A$2:$C$22,3,FALSE),"")) | E12: =IF(C12="","",IF($C$5=C12,"★ CAPTAIN",""))
B13: 4 | D13: =IF(C13="","",IFERROR(VLOOKUP(C13,'CALCULATIONS'!$A$2:$C$22,3,FALSE),"")) | E13: =IF(C13="","",IF($C$5=C13,"★ CAPTAIN",""))
B14: 5 | D14: =IF(C14="","",IFERROR(VLOOKUP(C14,'CALCULATIONS'!$A$2:$C$22,3,FALSE),"")) | E14: =IF(C14="","",IF($C$5=C14,"★ CAPTAIN",""))
B16: TEAM SUMMARY
B17: Team Value | C17: =SUM(D10:D14)
B18: Budget Left | C18: =50-C17
B19: GW Score | C19: =IF($C$20="VALID TEAM",SUMIF('CALCULATIONS'!$A$2:$A$22,C10:C14,'CALCULATIONS'!$D$2:$D$22)+SUMIF('CALCULATIONS'!$A$2:$A$22,C5,'CALCULATIONS'!$D$2:$D$22),0)
B20: Team Status | C20: =IF(COUNTBLANK(C10:C14)>0,"LESS THAN 5 PLAYERS",IF(SUM(D10:D14)>50,"OVER BUDGET",IF(C5="","NO CAPTAIN",IF(COUNTIF(C10:C14,C5)=0,"CAPTAIN NOT IN SQUAD",IF(SUMPRODUCT(COUNTIF(C10:C14,C10:C14))>5,"DUPLICATE PLAYER","VALID TEAM")))))
B22: INPUT CELLS ARE GOLD. Only the captain cell (C5) and the 5 player cells (C10:C14) should be edited. Everything else is calculated automatically.
B26: EXAMPLE (do not edit — for reference only)
B27: Slot | C27: Player | D27: Price | E27: Captain?
B28: 1 | C28: Chinedu Chile | D28: £11.0m
B29: 2 | C29: Emily Warburton | D29: £11.0m | E29: ★ CAPTAIN
B30: 3 | C30: Joe Paige | D30: £10.5m
B31: 4 | C31: Edwin Mayers | D31: £9.0m
B32: 5 | C32: Alfie Foley | D32: £7.5m
B33: CAPTAIN | C33: Emily Warburton
B34: TEAM VALUE | C34: £49.0m BUDGET LEFT £1.0m
B35: STATUS | C35: ✓ VALID TEAM

Sheet Oscar Day-Duran
B1: OSCAR DAY-DURAN'S TEAM
B2: ← Back to PICK YOUR TEAM
B4: PICK YOUR CAPTAIN (scores 2× points)
B6: Tip: pick your 5 players below first, then choose your captain.
B8: SQUAD
B9: Slot | C9: Player | D9: Price | E9: Captain?
B10: 1 | D10: =IF(C10="","",IFERROR(VLOOKUP(C10,'CALCULATIONS'!$A$2:$C$22,3,FALSE),"")) | E10: =IF(C10="","",IF($C$5=C10,"★ CAPTAIN",""))
B11: 2 | D11: =IF(C11="","",IFERROR(VLOOKUP(C11,'CALCULATIONS'!$A$2:$C$22,3,FALSE),"")) | E11: =IF(C11="","",IF($C$5=C11,"★ CAPTAIN",""))
B12: 3 | D12: =IF(C12="","",IFERROR(VLOOKUP(C12,'CALCULATIONS'!$A$2:$C$22,3,FALSE),"")) | E12: =IF(C12="","",IF($C$5=C12,"★ CAPTAIN",""))
B13: 4 | D13: =IF(C13="","",IFERROR(VLOOKUP(C13,'CALCULATIONS'!$A$2:$C$22,3,FALSE),"")) | E13: =IF(C13="","",IF($C$5=C13,"★ CAPTAIN",""))
B14: 5 | D14: =IF(C14="","",IFERROR(VLOOKUP(C14,'CALCULATIONS'!$A$2:$C$22,3,FALSE),"")) | E14: =IF(C14="","",IF($C$5=C14,"★ CAPTAIN",""))
B16: TEAM SUMMARY
B17: Team Value | C17: =SUM(D10:D14)
B18: Budget Left | C18: =50-C17
B19: GW Score | C19: =IF($C$20="VALID TEAM",SUMIF('CALCULATIONS'!$A$2:$A$22,C10:C14,'CALCULATIONS'!$D$2:$D$22)+SUMIF('CALCULATIONS'!$A$2:$A$22,C5,'CALCULATIONS'!$D$2:$D$22),0)
B20: Team Status | C20: =IF(COUNTBLANK(C10:C14)>0,"LESS THAN 5 PLAYERS",IF(SUM(D10:D14)>50,"OVER BUDGET",IF(C5="","NO CAPTAIN",IF(COUNTIF(C10:C14,C5)=0,"CAPTAIN NOT IN SQUAD",IF(SUMPRODUCT(COUNTIF(C10:C14,C10:C14))>5,"DUPLICATE PLAYER","VALID TEAM")))))
B22: INPUT CELLS ARE GOLD. Only the captain cell (C5) and the 5 player cells (C10:C14) should be edited. Everything else is calculated automatically.
B26: EXAMPLE (do not edit — for reference only)
B27: Slot | C27: Player | D27: Price | E27: Captain?
B28: 1 | C28: Chinedu Chile | D28: £11.0m
B29: 2 | C29: Emily Warburton | D29: £11.0m | E29: ★ CAPTAIN
B30: 3 | C30: Joe Paige | D30: £10.5m
B31: 4 | C31: Edwin Mayers | D31: £9.0m
B32: 5 | C32: Alfie Foley | D32: £7.5m
B33: CAPTAIN | C33: Emily Warburton
B34: TEAM VALUE | C34: £49.0m BUDGET LEFT £1.0m
B35: STATUS | C35: ✓ VALID TEAM

Sheet Rebecca Seymour
B1: REBECCA SEYMOUR'S TEAM
B2: ← Back to PICK YOUR TEAM
B4: PICK YOUR CAPTAIN (scores 2× points)
B6: Tip: pick your 5 players below first, then choose your captain.
B8: SQUAD
B9: Slot | C9: Player | D9: Price | E9: Captain?
B10: 1 | D10: =IF(C10="","",IFERROR(VLOOKUP(C10,'CALCULATIONS'!$A$2:$C$22,3,FALSE),"")) | E10: =IF(C10="","",IF($C$5=C10,"★ CAPTAIN",""))
B11: 2 | D11: =IF(C11="","",IFERROR(VLOOKUP(C11,'CALCULATIONS'!$A$2:$C$22,3,FALSE),"")) | E11: =IF(C11="","",IF($C$5=C11,"★ CAPTAIN",""))
B12: 3 | D12: =IF(C12="","",IFERROR(VLOOKUP(C12,'CALCULATIONS'!$A$2:$C$22,3,FALSE),"")) | E12: =IF(C12="","",IF($C$5=C12,"★ CAPTAIN",""))
B13: 4 | D13: =IF(C13="","",IFERROR(VLOOKUP(C13,'CALCULATIONS'!$A$2:$C$22,3,FALSE),"")) | E13: =IF(C13="","",IF($C$5=C13,"★ CAPTAIN",""))
B14: 5 | D14: =IF(C14="","",IFERROR(VLOOKUP(C14,'CALCULATIONS'!$A$2:$C$22,3,FALSE),"")) | E14: =IF(C14="","",IF($C$5=C14,"★ CAPTAIN",""))
B16: TEAM SUMMARY
B17: Team Value | C17: =SUM(D10:D14)
B18: Budget Left | C18: =50-C17
B19: GW Score | C19: =IF($C$20="VALID TEAM",SUMIF('CALCULATIONS'!$A$2:$A$22,C10:C14,'CALCULATIONS'!$D$2:$D$22)+SUMIF('CALCULATIONS'!$A$2:$A$22,C5,'CALCULATIONS'!$D$2:$D$22),0)
B20: Team Status | C20: =IF(COUNTBLANK(C10:C14)>0,"LESS THAN 5 PLAYERS",IF(SUM(D10:D14)>50,"OVER BUDGET",IF(C5="","NO CAPTAIN",IF(COUNTIF(C10:C14,C5)=0,"CAPTAIN NOT IN SQUAD",IF(SUMPRODUCT(COUNTIF(C10:C14,C10:C14))>5,"DUPLICATE PLAYER","VALID TEAM")))))
B22: INPUT CELLS ARE GOLD. Only the captain cell (C5) and the 5 player cells (C10:C14) should be edited. Everything else is calculated automatically.
B26: EXAMPLE (do not edit — for reference only)
B27: Slot | C27: Player | D27: Price | E27: Captain?
B28: 1 | C28: Chinedu Chile | D28: £11.0m
B29: 2 | C29: Emily Warburton | D29: £11.0m | E29: ★ CAPTAIN
B30: 3 | C30: Joe Paige | D30: £10.5m
B31: 4 | C31: Edwin Mayers | D31: £9.0m
B32: 5 | C32: Alfie Foley | D32: £7.5m
B33: CAPTAIN | C33: Emily Warburton
B34: TEAM VALUE | C34: £49.0m BUDGET LEFT £1.0m
B35: STATUS | C35: ✓ VALID TEAM

Sheet Rory Bowman
B1: RORY BOWMAN'S TEAM
B2: ← Back to PICK YOUR TEAM
B4: PICK YOUR CAPTAIN (scores 2× points)
B6: Tip: pick your 5 players below first, then choose your captain.
B8: SQUAD
B9: Slot | C9: Player | D9: Price | E9: Captain?
B10: 1 | D10: =IF(C10="","",IFERROR(VLOOKUP(C10,'CALCULATIONS'!$A$2:$C$22,3,FALSE),"")) | E10: =IF(C10="","",IF($C$5=C10,"★ CAPTAIN",""))
B11: 2 | D11: =IF(C11="","",IFERROR(VLOOKUP(C11,'CALCULATIONS'!$A$2:$C$22,3,FALSE),"")) | E11: =IF(C11="","",IF($C$5=C11,"★ CAPTAIN",""))
B12: 3 | D12: =IF(C12="","",IFERROR(VLOOKUP(C12,'CALCULATIONS'!$A$2:$C$22,3,FALSE),"")) | E12: =IF(C12="","",IF($C$5=C12,"★ CAPTAIN",""))
B13: 4 | D13: =IF(C13="","",IFERROR(VLOOKUP(C13,'CALCULATIONS'!$A$2:$C$22,3,FALSE),"")) | E13: =IF(C13="","",IF($C$5=C13,"★ CAPTAIN",""))
B14: 5 | D14: =IF(C14="","",IFERROR(VLOOKUP(C14,'CALCULATIONS'!$A$2:$C$22,3,FALSE),"")) | E14: =IF(C14="","",IF($C$5=C14,"★ CAPTAIN",""))
B16: TEAM SUMMARY
B17: Team Value | C17: =SUM(D10:D14)
B18: Budget Left | C18: =50-C17
B19: GW Score | C19: =IF($C$20="VALID TEAM",SUMIF('CALCULATIONS'!$A$2:$A$22,C10:C14,'CALCULATIONS'!$D$2:$D$22)+SUMIF('CALCULATIONS'!$A$2:$A$22,C5,'CALCULATIONS'!$D$2:$D$22),0)
B20: Team Status | C20: =IF(COUNTBLANK(C10:C14)>0,"LESS THAN 5 PLAYERS",IF(SUM(D10:D14)>50,"OVER BUDGET",IF(C5="","NO CAPTAIN",IF(COUNTIF(C10:C14,C5)=0,"CAPTAIN NOT IN SQUAD",IF(SUMPRODUCT(COUNTIF(C10:C14,C10:C14))>5,"DUPLICATE PLAYER","VALID TEAM")))))
B22: INPUT CELLS ARE GOLD. Only the captain cell (C5) and the 5 player cells (C10:C14) should be edited. Everything else is calculated automatically.
B26: EXAMPLE (do not edit — for reference only)
B27: Slot | C27: Player | D27: Price | E27: Captain?
B28: 1 | C28: Chinedu Chile | D28: £11.0m
B29: 2 | C29: Emily Warburton | D29: £11.0m | E29: ★ CAPTAIN
B30: 3 | C30: Joe Paige | D30: £10.5m
B31: 4 | C31: Edwin Mayers | D31: £9.0m
B32: 5 | C32: Alfie Foley | D32: £7.5m
B33: CAPTAIN | C33: Emily Warburton
B34: TEAM VALUE | C34: £49.0m BUDGET LEFT £1.0m
B35: STATUS | C35: ✓ VALID TEAM

Sheet Sophie Barker
B1: SOPHIE BARKER'S TEAM
B2: ← Back to PICK YOUR TEAM
B4: PICK YOUR CAPTAIN (scores 2× points)
B6: Tip: pick your 5 players below first, then choose your captain.
B8: SQUAD
B9: Slot | C9: Player | D9: Price | E9: Captain?
B10: 1 | D10: =IF(C10="","",IFERROR(VLOOKUP(C10,'CALCULATIONS'!$A$2:$C$22,3,FALSE),"")) | E10: =IF(C10="","",IF($C$5=C10,"★ CAPTAIN",""))
B11: 2 | D11: =IF(C11="","",IFERROR(VLOOKUP(C11,'CALCULATIONS'!$A$2:$C$22,3,FALSE),"")) | E11: =IF(C11="","",IF($C$5=C11,"★ CAPTAIN",""))
B12: 3 | D12: =IF(C12="","",IFERROR(VLOOKUP(C12,'CALCULATIONS'!$A$2:$C$22,3,FALSE),"")) | E12: =IF(C12="","",IF($C$5=C12,"★ CAPTAIN",""))
B13: 4 | D13: =IF(C13="","",IFERROR(VLOOKUP(C13,'CALCULATIONS'!$A$2:$C$22,3,FALSE),"")) | E13: =IF(C13="","",IF($C$5=C13,"★ CAPTAIN",""))
B14: 5 | D14: =IF(C14="","",IFERROR(VLOOKUP(C14,'CALCULATIONS'!$A$2:$C$22,3,FALSE),"")) | E14: =IF(C14="","",IF($C$5=C14,"★ CAPTAIN",""))
B16: TEAM SUMMARY
B17: Team Value | C17: =SUM(D10:D14)
B18: Budget Left | C18: =50-C17
B19: GW Score | C19: =IF($C$20="VALID TEAM",SUMIF('CALCULATIONS'!$A$2:$A$22,C10:C14,'CALCULATIONS'!$D$2:$D$22)+SUMIF('CALCULATIONS'!$A$2:$A$22,C5,'CALCULATIONS'!$D$2:$D$22),0)
B20: Team Status | C20: =IF(COUNTBLANK(C10:C14)>0,"LESS THAN 5 PLAYERS",IF(SUM(D10:D14)>50,"OVER BUDGET",IF(C5="","NO CAPTAIN",IF(COUNTIF(C10:C14,C5)=0,"CAPTAIN NOT IN SQUAD",IF(SUMPRODUCT(COUNTIF(C10:C14,C10:C14))>5,"DUPLICATE PLAYER","VALID TEAM")))))
B22: INPUT CELLS ARE GOLD. Only the captain cell (C5) and the 5 player cells (C10:C14) should be edited. Everything else is calculated automatically.
B26: EXAMPLE (do not edit — for reference only)
B27: Slot | C27: Player | D27: Price | E27: Captain?
B28: 1 | C28: Chinedu Chile | D28: £11.0m
B29: 2 | C29: Emily Warburton | D29: £11.0m | E29: ★ CAPTAIN
B30: 3 | C30: Joe Paige | D30: £10.5m
B31: 4 | C31: Edwin Mayers | D31: £9.0m
B32: 5 | C32: Alfie Foley | D32: £7.5m
B33: CAPTAIN | C33: Emily Warburton
B34: TEAM VALUE | C34: £49.0m BUDGET LEFT £1.0m
B35: STATUS | C35: ✓ VALID TEAM

Sheet Xander Meijer
B1: XANDER MEIJER'S TEAM
B2: ← Back to PICK YOUR TEAM
B4: PICK YOUR CAPTAIN (scores 2× points)
B6: Tip: pick your 5 players below first, then choose your captain.
B8: SQUAD
B9: Slot | C9: Player | D9: Price | E9: Captain?
B10: 1 | D10: =IF(C10="","",IFERROR(VLOOKUP(C10,'CALCULATIONS'!$A$2:$C$22,3,FALSE),"")) | E10: =IF(C10="","",IF($C$5=C10,"★ CAPTAIN",""))
B11: 2 | D11: =IF(C11="","",IFERROR(VLOOKUP(C11,'CALCULATIONS'!$A$2:$C$22,3,FALSE),"")) | E11: =IF(C11="","",IF($C$5=C11,"★ CAPTAIN",""))
B12: 3 | D12: =IF(C12="","",IFERROR(VLOOKUP(C12,'CALCULATIONS'!$A$2:$C$22,3,FALSE),"")) | E12: =IF(C12="","",IF($C$5=C12,"★ CAPTAIN",""))
B13: 4 | D13: =IF(C13="","",IFERROR(VLOOKUP(C13,'CALCULATIONS'!$A$2:$C$22,3,FALSE),"")) | E13: =IF(C13="","",IF($C$5=C13,"★ CAPTAIN",""))
B14: 5 | D14: =IF(C14="","",IFERROR(VLOOKUP(C14,'CALCULATIONS'!$A$2:$C$22,3,FALSE),"")) | E14: =IF(C14="","",IF($C$5=C14,"★ CAPTAIN",""))
B16: TEAM SUMMARY
B17: Team Value | C17: =SUM(D10:D14)
B18: Budget Left | C18: =50-C17
B19: GW Score | C19: =IF($C$20="VALID TEAM",SUMIF('CALCULATIONS'!$A$2:$A$22,C10:C14,'CALCULATIONS'!$D$2:$D$22)+SUMIF('CALCULATIONS'!$A$2:$A$22,C5,'CALCULATIONS'!$D$2:$D$22),0)
B20: Team Status | C20: =IF(COUNTBLANK(C10:C14)>0,"LESS THAN 5 PLAYERS",IF(SUM(D10:D14)>50,"OVER BUDGET",IF(C5="","NO CAPTAIN",IF(COUNTIF(C10:C14,C5)=0,"CAPTAIN NOT IN SQUAD",IF(SUMPRODUCT(COUNTIF(C10:C14,C10:C14))>5,"DUPLICATE PLAYER","VALID TEAM")))))
B22: INPUT CELLS ARE GOLD. Only the captain cell (C5) and the 5 player cells (C10:C14) should be edited. Everything else is calculated automatically.
B26: EXAMPLE (do not edit — for reference only)
B27: Slot | C27: Player | D27: Price | E27: Captain?
B28: 1 | C28: Chinedu Chile | D28: £11.0m
B29: 2 | C29: Emily Warburton | D29: £11.0m | E29: ★ CAPTAIN
B30: 3 | C30: Joe Paige | D30: £10.5m
B31: 4 | C31: Edwin Mayers | D31: £9.0m
B32: 5 | C32: Alfie Foley | D32: £7.5m
B33: CAPTAIN | C33: Emily Warburton
B34: TEAM VALUE | C34: £49.0m BUDGET LEFT £1.0m
B35: STATUS | C35: ✓ VALID TEAM

Sheet CALCULATIONS
A1: Player | B1: Base Price | C1: Current Price | D1: Points | E1: Δ | K1: Manager | L1: P1 | M1: P2 | N1: P3 | O1: P4 | P1: P5 | Q1: Captain | R1: Team Value | S1: Budget Left | T1: GW Score | U1: Status
A2: Lia Li | B2: 13 | C2: =MIN(13,MAX(6,B2+E2)) | D2: =IFERROR(IF('TEST RESULTS'!C2="",0,IF('TEST RESULTS'!C2>=90,10,IF('TEST RESULTS'!C2>=80,8,IF('TEST RESULTS'!C2>=70,6,IF('TEST RESULTS'!C2>=60,5,IF('TEST RESULTS'!C2>=50,3,IF('TEST RESULTS'!C2>=40,2,1))))))),0) | E2: =IF(D2=10,2,IF(D2=8,1.5,IF(D2=6,1,IF(D2=5,0,IF(D2=3,-1,IF(D2=2,-1.5,IF(D2=1,-2,0))))))) | K2: Alexa Amesimeku | L2: ='Alexa Amesimeku'!C10 | M2: ='Alexa Amesimeku'!C11 | N2: ='Alexa Amesimeku'!C12 | O2: ='Alexa Amesimeku'!C13 | P2: ='Alexa Amesimeku'!C14 | Q2: ='Alexa Amesimeku'!C5 | R2: ='Alexa Amesimeku'!C17 | S2: ='Alexa Amesimeku'!C18 | T2: ='Alexa Amesimeku'!C19 | U2: ='Alexa Amesimeku'!C20
A3: Chinedu Chile | B3: 11 | C3: =MIN(13,MAX(6,B3+E3)) | D3: =IFERROR(IF('TEST RESULTS'!C3="",0,IF('TEST RESULTS'!C3>=90,10,IF('TEST RESULTS'!C3>=80,8,IF('TEST RESULTS'!C3>=70,6,IF('TEST RESULTS'!C3>=60,5,IF('TEST RESULTS'!C3>=50,3,IF('TEST RESULTS'!C3>=40,2,1))))))),0) | E3: =IF(D3=10,2,IF(D3=8,1.5,IF(D3=6,1,IF(D3=5,0,IF(D3=3,-1,IF(D3=2,-1.5,IF(D3=1,-2,0))))))) | K3: Alfie Foley | L3: ='Alfie Foley'!C10 | M3: ='Alfie Foley'!C11 | N3: ='Alfie Foley'!C12 | O3: ='Alfie Foley'!C13 | P3: ='Alfie Foley'!C14 | Q3: ='Alfie Foley'!C5 | R3: ='Alfie Foley'!C17 | S3: ='Alfie Foley'!C18 | T3: ='Alfie Foley'!C19 | U3: ='Alfie Foley'!C20
A4: Emily Warburton | B4: 11 | C4: =MIN(13,MAX(6,B4+E4)) | D4: =IFERROR(IF('TEST RESULTS'!C4="",0,IF('TEST RESULTS'!C4>=90,10,IF('TEST RESULTS'!C4>=80,8,IF('TEST RESULTS'!C4>=70,6,IF('TEST RESULTS'!C4>=60,5,IF('TEST RESULTS'!C4>=50,3,IF('TEST RESULTS'!C4>=40,2,1))))))),0) | E4: =IF(D4=10,2,IF(D4=8,1.5,IF(D4=6,1,IF(D4=5,0,IF(D4=3,-1,IF(D4=2,-1.5,IF(D4=1,-2,0))))))) | K4: Alyza Rai | L4: ='Alyza Rai'!C10 | M4: ='Alyza Rai'!C11 | N4: ='Alyza Rai'!C12 | O4: ='Alyza Rai'!C13 | P4: ='Alyza Rai'!C14 | Q4: ='Alyza Rai'!C5 | R4: ='Alyza Rai'!C17 | S4: ='Alyza Rai'!C18 | T4: ='Alyza Rai'!C19 | U4: ='Alyza Rai'!C20
A5: Sophie Barker | B5: 11 | C5: =MIN(13,MAX(6,B5+E5)) | D5: =IFERROR(IF('TEST RESULTS'!C5="",0,IF('TEST RESULTS'!C5>=90,10,IF('TEST RESULTS'!C5>=80,8,IF('TEST RESULTS'!C5>=70,6,IF('TEST RESULTS'!C5>=60,5,IF('TEST RESULTS'!C5>=50,3,IF('TEST RESULTS'!C5>=40,2,1))))))),0) | E5: =IF(D5=10,2,IF(D5=8,1.5,IF(D5=6,1,IF(D5=5,0,IF(D5=3,-1,IF(D5=2,-1.5,IF(D5=1,-2,0))))))) | K5: Ava Swinfen | L5: ='Ava Swinfen'!C10 | M5: ='Ava Swinfen'!C11 | N5: ='Ava Swinfen'!C12 | O5: ='Ava Swinfen'!C13 | P5: ='Ava Swinfen'!C14 | Q5: ='Ava Swinfen'!C5 | R5: ='Ava Swinfen'!C17 | S5: ='Ava Swinfen'!C18 | T5: ='Ava Swinfen'!C19 | U5: ='Ava Swinfen'!C20
A6: Alyza Rai | B6: 10.5 | C6: =MIN(13,MAX(6,B6+E6)) | D6: =IFERROR(IF('TEST RESULTS'!C6="",0,IF('TEST RESULTS'!C6>=90,10,IF('TEST RESULTS'!C6>=80,8,IF('TEST RESULTS'!C6>=70,6,IF('TEST RESULTS'!C6>=60,5,IF('TEST RESULTS'!C6>=50,3,IF('TEST RESULTS'!C6>=40,2,1))))))),0) | E6: =IF(D6=10,2,IF(D6=8,1.5,IF(D6=6,1,IF(D6=5,0,IF(D6=3,-1,IF(D6=2,-1.5,IF(D6=1,-2,0))))))) | K6: Azlan Husain | L6: ='Azlan Husain'!C10 | M6: ='Azlan Husain'!C11 | N6: ='Azlan Husain'!C12 | O6: ='Azlan Husain'!C13 | P6: ='Azlan Husain'!C14 | Q6: ='Azlan Husain'!C5 | R6: ='Azlan Husain'!C17 | S6: ='Azlan Husain'!C18 | T6: ='Azlan Husain'!C19 | U6: ='Azlan Husain'!C20
A7: David Wu | B7: 10.5 | C7: =MIN(13,MAX(6,B7+E7)) | D7: =IFERROR(IF('TEST RESULTS'!C7="",0,IF('TEST RESULTS'!C7>=90,10,IF('TEST RESULTS'!C7>=80,8,IF('TEST RESULTS'!C7>=70,6,IF('TEST RESULTS'!C7>=60,5,IF('TEST RESULTS'!C7>=50,3,IF('TEST RESULTS'!C7>=40,2,1))))))),0) | E7: =IF(D7=10,2,IF(D7=8,1.5,IF(D7=6,1,IF(D7=5,0,IF(D7=3,-1,IF(D7=2,-1.5,IF(D7=1,-2,0))))))) | K7: Chinedu Chile | L7: ='Chinedu Chile'!C10 | M7: ='Chinedu Chile'!C11 | N7: ='Chinedu Chile'!C12 | O7: ='Chinedu Chile'!C13 | P7: ='Chinedu Chile'!C14 | Q7: ='Chinedu Chile'!C5 | R7: ='Chinedu Chile'!C17 | S7: ='Chinedu Chile'!C18 | T7: ='Chinedu Chile'!C19 | U7: ='Chinedu Chile'!C20
A8: Joe Paige | B8: 10.5 | C8: =MIN(13,MAX(6,B8+E8)) | D8: =IFERROR(IF('TEST RESULTS'!C8="",0,IF('TEST RESULTS'!C8>=90,10,IF('TEST RESULTS'!C8>=80,8,IF('TEST RESULTS'!C8>=70,6,IF('TEST RESULTS'!C8>=60,5,IF('TEST RESULTS'!C8>=50,3,IF('TEST RESULTS'!C8>=40,2,1))))))),0) | E8: =IF(D8=10,2,IF(D8=8,1.5,IF(D8=6,1,IF(D8=5,0,IF(D8=3,-1,IF(D8=2,-1.5,IF(D8=1,-2,0))))))) | K8: Daniel Liu | L8: ='Daniel Liu'!C10 | M8: ='Daniel Liu'!C11 | N8: ='Daniel Liu'!C12 | O8: ='Daniel Liu'!C13 | P8: ='Daniel Liu'!C14 | Q8: ='Daniel Liu'!C5 | R8: ='Daniel Liu'!C17 | S8: ='Daniel Liu'!C18 | T8: ='Daniel Liu'!C19 | U8: ='Daniel Liu'!C20
A9: Azlan Husain | B9: 10 | C9: =MIN(13,MAX(6,B9+E9)) | D9: =IFERROR(IF('TEST RESULTS'!C9="",0,IF('TEST RESULTS'!C9>=90,10,IF('TEST RESULTS'!C9>=80,8,IF('TEST RESULTS'!C9>=70,6,IF('TEST RESULTS'!C9>=60,5,IF('TEST RESULTS'!C9>=50,3,IF('TEST RESULTS'!C9>=40,2,1))))))),0) | E9: =IF(D9=10,2,IF(D9=8,1.5,IF(D9=6,1,IF(D9=5,0,IF(D9=3,-1,IF(D9=2,-1.5,IF(D9=1,-2,0))))))) | K9: David Wu | L9: ='David Wu'!C10 | M9: ='David Wu'!C11 | N9: ='David Wu'!C12 | O9: ='David Wu'!C13 | P9: ='David Wu'!C14 | Q9: ='David Wu'!C5 | R9: ='David Wu'!C17 | S9: ='David Wu'!C18 | T9: ='David Wu'!C19 | U9: ='David Wu'!C20
A10: Nina De Saram | B10: 10 | C10: =MIN(13,MAX(6,B10+E10)) | D10: =IFERROR(IF('TEST RESULTS'!C10="",0,IF('TEST RESULTS'!C10>=90,10,IF('TEST RESULTS'!C10>=80,8,IF('TEST RESULTS'!C10>=70,6,IF('TEST RESULTS'!C10>=60,5,IF('TEST RESULTS'!C10>=50,3,IF('TEST RESULTS'!C10>=40,2,1))))))),0) | E10: =IF(D10=10,2,IF(D10=8,1.5,IF(D10=6,1,IF(D10=5,0,IF(D10=3,-1,IF(D10=2,-1.5,IF(D10=1,-2,0))))))) | K10: Edwin Mayers | L10: ='Edwin Mayers'!C10 | M10: ='Edwin Mayers'!C11 | N10: ='Edwin Mayers'!C12 | O10: ='Edwin Mayers'!C13 | P10: ='Edwin Mayers'!C14 | Q10: ='Edwin Mayers'!C5 | R10: ='Edwin Mayers'!C17 | S10: ='Edwin Mayers'!C18 | T10: ='Edwin Mayers'!C19 | U10: ='Edwin Mayers'!C20
A11: Alexa Amesimeku | B11: 9.5 | C11: =MIN(13,MAX(6,B11+E11)) | D11: =IFERROR(IF('TEST RESULTS'!C11="",0,IF('TEST RESULTS'!C11>=90,10,IF('TEST RESULTS'!C11>=80,8,IF('TEST RESULTS'!C11>=70,6,IF('TEST RESULTS'!C11>=60,5,IF('TEST RESULTS'!C11>=50,3,IF('TEST RESULTS'!C11>=40,2,1))))))),0) | E11: =IF(D11=10,2,IF(D11=8,1.5,IF(D11=6,1,IF(D11=5,0,IF(D11=3,-1,IF(D11=2,-1.5,IF(D11=1,-2,0))))))) | K11: Emily Warburton | L11: ='Emily Warburton'!C10 | M11: ='Emily Warburton'!C11 | N11: ='Emily Warburton'!C12 | O11: ='Emily Warburton'!C13 | P11: ='Emily Warburton'!C14 | Q11: ='Emily Warburton'!C5 | R11: ='Emily Warburton'!C17 | S11: ='Emily Warburton'!C18 | T11: ='Emily Warburton'!C19 | U11: ='Emily Warburton'!C20
A12: Daniel Liu | B12: 9.5 | C12: =MIN(13,MAX(6,B12+E12)) | D12: =IFERROR(IF('TEST RESULTS'!C12="",0,IF('TEST RESULTS'!C12>=90,10,IF('TEST RESULTS'!C12>=80,8,IF('TEST RESULTS'!C12>=70,6,IF('TEST RESULTS'!C12>=60,5,IF('TEST RESULTS'!C12>=50,3,IF('TEST RESULTS'!C12>=40,2,1))))))),0) | E12: =IF(D12=10,2,IF(D12=8,1.5,IF(D12=6,1,IF(D12=5,0,IF(D12=3,-1,IF(D12=2,-1.5,IF(D12=1,-2,0))))))) | K12: Esme Beston | L12: ='Esme Beston'!C10 | M12: ='Esme Beston'!C11 | N12: ='Esme Beston'!C12 | O12: ='Esme Beston'!C13 | P12: ='Esme Beston'!C14 | Q12: ='Esme Beston'!C5 | R12: ='Esme Beston'!C17 | S12: ='Esme Beston'!C18 | T12: ='Esme Beston'!C19 | U12: ='Esme Beston'!C20
A13: Rebecca Seymour | B13: 9.5 | C13: =MIN(13,MAX(6,B13+E13)) | D13: =IFERROR(IF('TEST RESULTS'!C13="",0,IF('TEST RESULTS'!C13>=90,10,IF('TEST RESULTS'!C13>=80,8,IF('TEST RESULTS'!C13>=70,6,IF('TEST RESULTS'!C13>=60,5,IF('TEST RESULTS'!C13>=50,3,IF('TEST RESULTS'!C13>=40,2,1))))))),0) | E13: =IF(D13=10,2,IF(D13=8,1.5,IF(D13=6,1,IF(D13=5,0,IF(D13=3,-1,IF(D13=2,-1.5,IF(D13=1,-2,0))))))) | K13: Iona Smith | L13: ='Iona Smith'!C10 | M13: ='Iona Smith'!C11 | N13: ='Iona Smith'!C12 | O13: ='Iona Smith'!C13 | P13: ='Iona Smith'!C14 | Q13: ='Iona Smith'!C5 | R13: ='Iona Smith'!C17 | S13: ='Iona Smith'!C18 | T13: ='Iona Smith'!C19 | U13: ='Iona Smith'!C20
A14: Edwin Mayers | B14: 9 | C14: =MIN(13,MAX(6,B14+E14)) | D14: =IFERROR(IF('TEST RESULTS'!C14="",0,IF('TEST RESULTS'!C14>=90,10,IF('TEST RESULTS'!C14>=80,8,IF('TEST RESULTS'!C14>=70,6,IF('TEST RESULTS'!C14>=60,5,IF('TEST RESULTS'!C14>=50,3,IF('TEST RESULTS'!C14>=40,2,1))))))),0) | E14: =IF(D14=10,2,IF(D14=8,1.5,IF(D14=6,1,IF(D14=5,0,IF(D14=3,-1,IF(D14=2,-1.5,IF(D14=1,-2,0))))))) | K14: Joe Paige | L14: ='Joe Paige'!C10 | M14: ='Joe Paige'!C11 | N14: ='Joe Paige'!C12 | O14: ='Joe Paige'!C13 | P14: ='Joe Paige'!C14 | Q14: ='Joe Paige'!C5 | R14: ='Joe Paige'!C17 | S14: ='Joe Paige'!C18 | T14: ='Joe Paige'!C19 | U14: ='Joe Paige'!C20
A15: Melody Zhaeentan | B15: 8.5 | C15: =MIN(13,MAX(6,B15+E15)) | D15: =IFERROR(IF('TEST RESULTS'!C15="",0,IF('TEST RESULTS'!C15>=90,10,IF('TEST RESULTS'!C15>=80,8,IF('TEST RESULTS'!C15>=70,6,IF('TEST RESULTS'!C15>=60,5,IF('TEST RESULTS'!C15>=50,3,IF('TEST RESULTS'!C15>=40,2,1))))))),0) | E15: =IF(D15=10,2,IF(D15=8,1.5,IF(D15=6,1,IF(D15=5,0,IF(D15=3,-1,IF(D15=2,-1.5,IF(D15=1,-2,0))))))) | K15: Lia Li | L15: ='Lia Li'!C10 | M15: ='Lia Li'!C11 | N15: ='Lia Li'!C12 | O15: ='Lia Li'!C13 | P15: ='Lia Li'!C14 | Q15: ='Lia Li'!C5 | R15: ='Lia Li'!C17 | S15: ='Lia Li'!C18 | T15: ='Lia Li'!C19 | U15: ='Lia Li'!C20
A16: Esme Beston | B16: 8 | C16: =MIN(13,MAX(6,B16+E16)) | D16: =IFERROR(IF('TEST RESULTS'!C16="",0,IF('TEST RESULTS'!C16>=90,10,IF('TEST RESULTS'!C16>=80,8,IF('TEST RESULTS'!C16>=70,6,IF('TEST RESULTS'!C16>=60,5,IF('TEST RESULTS'!C16>=50,3,IF('TEST RESULTS'!C16>=40,2,1))))))),0) | E16: =IF(D16=10,2,IF(D16=8,1.5,IF(D16=6,1,IF(D16=5,0,IF(D16=3,-1,IF(D16=2,-1.5,IF(D16=1,-2,0))))))) | K16: Melody Zhaeentan | L16: ='Melody Zhaeentan'!C10 | M16: ='Melody Zhaeentan'!C11 | N16: ='Melody Zhaeentan'!C12 | O16: ='Melody Zhaeentan'!C13 | P16: ='Melody Zhaeentan'!C14 | Q16: ='Melody Zhaeentan'!C5 | R16: ='Melody Zhaeentan'!C17 | S16: ='Melody Zhaeentan'!C18 | T16: ='Melody Zhaeentan'!C19 | U16: ='Melody Zhaeentan'!C20
